Workbook

Sheet Capa
A1: Análise de Pontos de Função — entrega coletiva
A3: Projeto | B3: Estoque Inteligente
A5: Integrantes | B5: Artur Ribeiro de Souza Cristhian Ruan de Rezende Lucas Andriani Theiss
A7: Versão | B7: Branch entrega-trabalho — conclusão da revisão de 25/10/2026
A9: Escopo | B9: Aplicação completa, contagem sem sobreposição dos três recortes individuais.
A11: Leitura | B11: Resumo → Catálogo → fichas por ID → Matrizes → NI e estimativas → Conferência.
A13: Resultado | B13: Fórmulas nativas editáveis; resultados e premissas nas abas seguintes.
A15: Ressalvas | B15: Notas NI são avaliação técnica com premissas acadêmicas explícitas. Capturas reais incluem dados de demonstração e simulador IoT identificado. Os três recortes individuais são documentos históricos preservados.

Sheet Resumo
A1: Resultado coletivo e reconciliação
A3: Tipo | B3: Quantidade | C3: PF | D3: Regra
A4: ALI | B4: =COUNTIF(Catálogo!$B$4:$B$58,A4) -> 9 | C4: =SUMIF(Catálogo!$B$4:$B$58,A4,Catálogo!$G$4:$G$58) -> 63 | D4: Uma função por ID, sem somar recortes.
A5: AIE | B5: =COUNTIF(Catálogo!$B$4:$B$58,A5) -> 2 | C5: =SUMIF(Catálogo!$B$4:$B$58,A5,Catálogo!$G$4:$G$58) -> 10 | D5: Uma função por ID, sem somar recortes.
A6: EE | B6: =COUNTIF(Catálogo!$B$4:$B$58,A6) -> 28 | C6: =SUMIF(Catálogo!$B$4:$B$58,A6,Catálogo!$G$4:$G$58) -> 135 | D6: Uma função por ID, sem somar recortes.
A7: SE | B7: =COUNTIF(Catálogo!$B$4:$B$58,A7) -> 8 | C7: =SUMIF(Catálogo!$B$4:$B$58,A7,Catálogo!$G$4:$G$58) -> 48 | D7: Uma função por ID, sem somar recortes.
A8: CE | B8: =COUNTIF(Catálogo!$B$4:$B$58,A8) -> 8 | C8: =SUMIF(Catálogo!$B$4:$B$58,A8,Catálogo!$G$4:$G$58) -> 27 | D8: Uma função por ID, sem somar recortes.
A10: PFB | B10: =SUM(C4:C8) -> 283
A11: NI | B11: ='NI e estimativas'!B19 -> 38
A12: FA | B12: ='NI e estimativas'!B22 -> 1.03
A13: PFA | B13: =B10*B12 -> 291.49
A15: Mudança funcional | B15: CE10 passa a SE10: indicador de estorno é derivado por EXISTS e exibido. Não é função nova; diferença de peso: 6 para 7 PF.
A17: Mudança no NI | B17: Desempenho 1→0; implantação 2→1; operação 2→1. Notas altas exigiam evidências não demonstradas. Premissas de volume e múltiplos locais continuam explícitas.
A19: Cobertura do enunciado | B19: Destaque de quatro CEs: CE04, CE05, CE08, CE12. SEs numéricas: SE02, SE04, SE06, SE07, SE08 e SE13. Todas as funções restantes permanecem no coletivo.
A21: Estimativa | B21: Desenvolvimento do sistema inteiro. Não é prazo restante da atividade. Ver premissas e fórmulas em NI e estimativas.

Sheet Catálogo
A1: Catálogo coletivo — uma linha por função
A3: ID | B3: Tipo | C3: Função | D3: TD | E3: AR / RL | F3: Complexidade | G3: PF | H3: Ficha
A4: A01 | B4: ALI | C4: Modelos de produto | D4: =A01!B60 -> 5 | E4: =A01!D60 -> 1 | F4: =A01!D64 -> Simples | G4: =A01!D65 -> 7 | H4: =HYPERLINK("#'A01'!A1","Abrir A01") -> Abrir A01
A5: A02 | B5: ALI | C5: Produtos | D5: =A02!B60 -> 11 | E5: =A02!D60 -> 1 | F5: =A02!D64 -> Simples | G5: =A02!D65 -> 7 | H5: =HYPERLINK("#'A02'!A1","Abrir A02") -> Abrir A02
A6: A03 | B6: ALI | C6: Posições | D6: =A03!B60 -> 11 | E6: =A03!D60 -> 1 | F6: =A03!D64 -> Simples | G6: =A03!D65 -> 7 | H6: =HYPERLINK("#'A03'!A1","Abrir A03") -> Abrir A03
A7: A04 | B7: ALI | C7: Estoque por posição / vínculos | D7: =A04!B60 -> 4 | E7: =A04!D60 -> 1 | F7: =A04!D64 -> Simples | G7: =A04!D65 -> 7 | H7: =HYPERLINK("#'A04'!A1","Abrir A04") -> Abrir A04
A8: A05 | B8: ALI | C8: Movimentações | D8: =A05!B60 -> 12 | E8: =A05!D60 -> 1 | F8: =A05!D64 -> Simples | G8: =A05!D65 -> 7 | H8: =HYPERLINK("#'A05'!A1","Abrir A05") -> Abrir A05
A9: A06 | B9: ALI | C9: Usuários | D9: =A06!B60 -> 6 | E9: =A06!D60 -> 1 | F9: =A06!D64 -> Simples | G9: =A06!D65 -> 7 | H9: =HYPERLINK("#'A06'!A1","Abrir A06") -> Abrir A06
A10: A07 | B10: ALI | C10: Permissões por perfil | D10: =A07!B60 -> 3 | E10: =A07!D60 -> 1 | F10: =A07!D64 -> Simples | G10: =A07!D65 -> 7 | H10: =HYPERLINK("#'A07'!A1","Abrir A07") -> Abrir A07
A11: A08 | B11: ALI | C11: Lojas e configuração | D11: =A08!B60 -> 12 | E11: =A08!D60 -> 1 | F11: =A08!D64 -> Simples | G11: =A08!D65 -> 7 | H11: =HYPERLINK("#'A08'!A1","Abrir A08") -> Abrir A08
A12: A09 | B12: ALI | C12: Auditoria consultável | D12: =A09!B60 -> 6 | E12: =A09!D60 -> 1 | F12: =A09!D64 -> Simples | G12: =A09!D65 -> 7 | H12: =HYPERLINK("#'A09'!A1","Abrir A09") -> Abrir A09
A13: X01 | B13: AIE | C13: Fornecedores externos | D13: =X01!B60 -> 5 | E13: =X01!D60 -> 1 | F13: =X01!D64 -> Simples | G13: =X01!D65 -> 5 | H13: =HYPERLINK("#'X01'!A1","Abrir X01") -> Abrir X01
A14: X02 | B14: AIE | C14: Ofertas externas | D14: =X02!B60 -> 9 | E14: =X02!D60 -> 1 | F14: =X02!D64 -> Simples | G14: =X02!D65 -> 5 | H14: =HYPERLINK("#'X02'!A1","Abrir X02") -> Abrir X02
A15: CE04 | B15: CE | C15: Consultar fornecedores externos | D15: =CE04!B60 -> 8 | E15: =CE04!D60 -> 1 | F15: =CE04!D64 -> Simples | G15: =CE04!D65 -> 3 | H15: =HYPERLINK("#'CE04'!A1","Abrir CE04") -> Abrir CE04
A16: CE05 | B16: CE | C16: Consultar modelos | D16: =CE05!B60 -> 6 | E16: =CE05!D60 -> 1 | F16: =CE05!D64 -> Simples | G16: =CE05!D65 -> 3 | H16: =HYPERLINK("#'CE05'!A1","Abrir CE05") -> Abrir CE05
A17: CE06 | B17: CE | C17: Consultar vínculos | D17: =CE06!B60 -> 10 | E17: =CE06!D60 -> 4 | F17: =CE06!D64 -> Complexa | G17: =CE06!D65 -> 6 | H17: =HYPERLINK("#'CE06'!A1","Abrir CE06") -> Abrir CE06
A18: CE07 | B18: CE | C18: Consultar equipe e permissões | D18: =CE07!B60 -> 6 | E18: =CE07!D60 -> 2 | F18: =CE07!D64 -> Simples | G18: =CE07!D65 -> 3 | H18: =HYPERLINK("#'CE07'!A1","Abrir CE07") -> Abrir CE07
A19: CE08 | B19: CE | C19: Consultar lojas | D19: =CE08!B60 -> 9 | E19: =CE08!D60 -> 1 | F19: =CE08!D64 -> Simples | G19: =CE08!D65 -> 3 | H19: =HYPERLINK("#'CE08'!A1","Abrir CE08") -> Abrir CE08
A20: CE09 | B20: CE | C20: Consultar configuração IoT | D20: =CE09!B60 -> 6 | E20: =CE09!D60 -> 1 | F20: =CE09!D64 -> Simples | G20: =CE09!D65 -> 3 | H20: =HYPERLINK("#'CE09'!A1","Abrir CE09") -> Abrir CE09
A21: CE11 | B21: CE | C21: Consultar auditoria | D21: =CE11!B60 -> 6 | E21: =CE11!D60 -> 2 | F21: =CE11!D64 -> Simples | G21: =CE11!D65 -> 3 | H21: =HYPERLINK("#'CE11'!A1","Abrir CE11") -> Abrir CE11
A22: CE12 | B22: CE | C22: Consultar ofertas externas | D22: =CE12!B60 -> 11 | E22: =CE12!D60 -> 1 | F22: =CE12!D64 -> Simples | G22: =CE12!D65 -> 3 | H22: =HYPERLINK("#'CE12'!A1","Abrir CE12") -> Abrir CE12
A23: EE01 | B23: EE | C23: Incluir produto, inclusive grade e saldo inicial | D23: =EE01!B60 -> 16 | E23: =EE01!D60 -> 6 | F23: =EE01!D64 -> Complexa | G23: =EE01!D65 -> 6 | H23: =HYPERLINK("#'EE01'!A1","Abrir EE01") -> Abrir EE01
A24: EE02 | B24: EE | C24: Alterar produto | D24: =EE02!B60 -> 13 | E24: =EE02!D60 -> 4 | F24: =EE02!D64 -> Complexa | G24: =EE02!D65 -> 6 | H24: =HYPERLINK("#'EE02'!A1","Abrir EE02") -> Abrir EE02
A25: EE03 | B25: EE | C25: Excluir produto logicamente | D25: =EE03!B60 -> 3 | E25: =EE03!D60 -> 3 | F25: =EE03!D64 -> Moderada | G25: =EE03!D65 -> 4 | H25: =HYPERLINK("#'EE03'!A1","Abrir EE03") -> Abrir EE03
A26: EE04 | B26: EE | C26: Incluir modelo | D26: =EE04!B60 -> 5 | E26: =EE04!D60 -> 2 | F26: =EE04!D64 -> Moderada | G26: =EE04!D65 -> 4 | H26: =HYPERLINK("#'EE04'!A1","Abrir EE04") -> Abrir EE04
A27: EE05 | B27: EE | C27: Alterar modelo | D27: =EE05!B60 -> 6 | E27: =EE05!D60 -> 2 | F27: =EE05!D64 -> Moderada | G27: =EE05!D65 -> 4 | H27: =HYPERLINK("#'EE05'!A1","Abrir EE05") -> Abrir EE05
A28: EE06 | B28: EE | C28: Excluir modelo | D28: =EE06!B60 -> 3 | E28: =EE06!D60 -> 3 | F28: =EE06!D64 -> Moderada | G28: =EE06!D65 -> 4 | H28: =HYPERLINK("#'EE06'!A1","Abrir EE06") -> Abrir EE06
A29: EE07 | B29: EE | C29: Incluir posição | D29: =EE07!B60 -> 10 | E29: =EE07!D60 -> 2 | F29: =EE07!D64 -> Moderada | G29: =EE07!D65 -> 4 | H29: =HYPERLINK("#'EE07'!A1","Abrir EE07") -> Abrir EE07
A30: EE08 | B30: EE | C30: Alterar posição | D30: =EE08!B60 -> 11 | E30: =EE08!D60 -> 3 | F30: =EE08!D64 -> Complexa | G30: =EE08!D65 -> 6 | H30: =HYPERLINK("#'EE08'!A1","Abrir EE08") -> Abrir EE08
A31: EE09 | B31: EE | C31: Excluir posição logicamente | D31: =EE09!B60 -> 3 | E31: =EE09!D60 -> 3 | F31: =EE09!D64 -> Moderada | G31: =EE09!D65 -> 4 | H31: =HYPERLINK("#'EE09'!A1","Abrir EE09") -> Abrir EE09
A32: EE10 | B32: EE | C32: Incluir vínculo | D32: =EE10!B60 -> 4 | E32: =EE10!D60 -> 4 | F32: =EE10!D64 -> Moderada | G32: =EE10!D65 -> 4 | H32: =HYPERLINK("#'EE10'!A1","Abrir EE10") -> Abrir EE10
A33: EE11 | B33: EE | C33: Alterar vínculo vazio | D33: =EE11!B60 -> 6 | E33: =EE11!D60 -> 4 | F33: =EE11!D64 -> Complexa | G33: =EE11!D65 -> 6 | H33: =HYPERLINK("#'EE11'!A1","Abrir EE11") -> Abrir EE11
A34: EE12 | B34: EE | C34: Excluir vínculo vazio | D34: =EE12!B60 -> 4 | E34: =EE12!D60 -> 4 | F34: =EE12!D64 -> Moderada | G34: =EE12!D65 -> 4 | H34: =HYPERLINK("#'EE12'!A1","Abrir EE12") -> Abrir EE12
A35: EE13 | B35: EE | C35: Incluir usuário | D35: =EE13!B60 -> 5 | E35: =EE13!D60 -> 3 | F35: =EE13!D64 -> Complexa | G35: =EE13!D65 -> 6 | H35: =HYPERLINK("#'EE13'!A1","Abrir EE13") -> Abrir EE13
A36: EE14 | B36: EE | C36: Alterar usuário | D36: =EE14!B60 -> 6 | E36: =EE14!D60 -> 3 | F36: =EE14!D64 -> Complexa | G36: =EE14!D65 -> 6 | H36: =HYPERLINK("#'EE14'!A1","Abrir EE14") -> Abrir EE14
A37: EE15 | B37: EE | C37: Excluir usuário logicamente | D37: =EE15!B60 -> 5 | E37: =EE15!D60 -> 3 | F37: =EE15!D64 -> Complexa | G37: =EE15!D65 -> 6 | H37: =HYPERLINK("#'EE15'!A1","Abrir EE15") -> Abrir EE15
A38: EE16 | B38: EE | C38: Incluir loja e administrador | D38: =EE16!B60 -> 10 | E38: =EE16!D60 -> 4 | F38: =EE16!D64 -> Complexa | G38: =EE16!D65 -> 6 | H38: =HYPERLINK("#'EE16'!A1","Abrir EE16") -> Abrir EE16
A39: EE17 | B39: EE | C39: Alterar loja e recursos | D39: =EE17!B60 -> 9 | E39: =EE17!D60 -> 3 | F39: =EE17!D64 -> Complexa | G39: =EE17!D65 -> 6 | H39: =HYPERLINK("#'EE17'!A1","Abrir EE17") -> Abrir EE17
A40: EE18 | B40: EE | C40: Excluir loja logicamente | D40: =EE18!B60 -> 3 | E40: =EE18!D60 -> 2 | F40: =EE18!D64 -> Simples | G40: =EE18!D65 -> 3 | H40: =HYPERLINK("#'EE18'!A1","Abrir EE18") -> Abrir EE18
A41: EE19 | B41: EE | C41: Alterar matriz de permissões | D41: =EE19!B60 -> 5 | E41: =EE19!D60 -> 2 | F41: =EE19!D64 -> Moderada | G41: =EE19!D65 -> 4 | H41: =HYPERLINK("#'EE19'!A1","Abrir EE19") -> Abrir EE19
...

Sheet Matrizes
A1: Matrizes e pesos da disciplina
A2: Convenção | B2: Índice 1 = simples; 2 = moderada; 3 = complexa. Matriz comum; limites por tipo abaixo.
A4: Faixa AR/RL × faixa TD | B4: TD baixo | C4: TD médio | D4: TD alto
A5: AR/RL baixo | B5: 1 | C5: 1 | D5: 2
A6: AR/RL médio | B6: 1 | C6: 2 | D6: 3
A7: AR/RL alto | B7: 2 | C7: 3 | D7: 3
B10: Simples | C10: Moderada | D10: Complexa
A12: Tipo | B12: Simples | C12: Moderada | D12: Complexa
A13: ALI | B13: 7 | C13: 10 | D13: 15
A14: AIE | B14: 5 | C14: 7 | D14: 10
A15: EE | B15: 3 | C15: 4 | D15: 6
A16: SE | B16: 4 | C16: 5 | D16: 7
A17: CE | B17: 3 | C17: 4 | D17: 6
A19: ALI/AIE | B19: TD 1–19 / 20–50 / 51+. RL 1 / 2–5 / 6+. Parte I, p. 19 e 28.
A20: EE / entrada CE | B20: TD 1–4 / 5–15 / 16+. AR 0–1 / 2 / 3+. Parte II EE, p. 9; Parte III, p. 10.
A21: SE / saída CE | B21: TD 1–5 / 6–19 / 20+. AR 0–1 / 2–3 / 4+. Parte II SE, p. 9; Parte III, p. 12.
A23: CE | B23: Escolher a maior complexidade das duas avaliações. Pesos 3/4/6, inclusive na saída da CE.
A25: Diferença do modelo | B25: O modelo original aplica matriz única ao total da CE. Corrigido aqui conforme Parte III, p. 10–13. Original preservado.
A27: FA | B27: Parte IV, p. 11: 0,65 + 0,01 × NI. A p. 15 usa 0,35 e limites incoerentes; adotada p. 11.

Sheet NI e estimativas
A1: NI e estimativas — premissas editáveis
A3: Característica | B3: Nota (0 a 5) | C3: Justificativa | D3: Evidência / natureza
A4: Comunicação de dados | B4: 5 | C4: Aplicação on-line com HTTP e MQTT; novo cliente HTTP de fornecedores. Mais de um protocolo. | D4: MqttGateway, controllers e FornecedorGateway — avaliação documental; não implica consenso da equipe.
A5: Processamento distribuído | B5: 3 | C5: Envia comandos para processamento no controlador IoT. Retorno de telemetria não demonstra transferência de processamento nas duas direções nem escolha dinâmica de CPU. | D5: IoTService.sinalizar — avaliação documental; não implica consenso da equipe.
A6: Desempenho | B6: 0 | C6: Timeout e paginação não comprovam requisitos de desempenho solicitados e revistos pelo usuário. Sem essa evidência, aplica-se nota 0 da tabela. | D6: application.properties, ProdutoRepository — avaliação documental; não implica consenso da equipe.
A7: Utilização de equipamento | B7: 2 | C7: Compose define limites de memória e pools; há considerações de recursos e segurança. Não exige CPU exclusiva. | D7: compose.yaml — avaliação documental; não implica consenso da equipe.
A8: Volume de transações | B8: 1 | C8: Premissa acadêmica: picos mensais de inventário. Volume real não medido; revisar se houver histórico operacional. | D8: Premissa de estimativa — premissa acadêmica, não fato medido.
A9: Entrada on-line | B9: 5 | C9: Mais de 30% dos processos de entrada são interativos: cadastros, movimentos e configurações. | D9: Controllers web — avaliação documental; não implica consenso da equipe.
A10: Eficiência do usuário final | B10: 4 | C10: Menus, mouse, paginação, navegação, ajuda contextual e poucas telas; redução de digitação por código de barras, voz e balança. Sem medição formal de eficiência. | D10: templates, speech.js, baixa rápida — avaliação documental; não implica consenso da equipe.
A11: Atualização on-line | B11: 4 | C11: Maioria dos ALIs atualizada on-line, com transações, bloqueios e idempotência contra perda/duplicação. Não se assume recuperação de volumes extremos. | D11: EstoqueService, repositories — avaliação documental; não implica consenso da equipe.
A12: Processamento complexo | B12: 2 | C12: Dois critérios: auditoria/segurança específica e lógica de negócio de estorno, saldo e permissões. Não se considera matemática extensiva nem reprocessamento batch complexo. | D12: Acesso, EstoqueService, AuditoriaRepository — avaliação documental; não implica consenso da equipe.
A13: Reutilização de código | B13: 4 | C13: Biblioteca de regras empacotável, documentada e com consumidor externo. Extensões exigem código; não se atribui customização geral por parâmetros. | D13: docs/reuso/README.md, scripts/empacotar-reuso.ps1 — avaliação documental; não implica consenso da equipe.
A14: Facilidade de implantação | B14: 1 | C14: Há procedimento de implantação; migrações Flyway criam/evoluem esquema, mas não comprovam requisitos e roteiros testados de conversão de dados legados. | D14: README, Flyway, Compose — avaliação documental; não implica consenso da equipe.
A15: Facilidade operacional | B15: 1 | C15: Relatórios minimizam papel. Scripts de inicialização, sem procedimento demonstrado de backup e recuperação, não comprovam o critério composto adicional. | D15: scripts/demo.ps1, relatórios — avaliação documental; não implica consenso da equipe.
... A17: Facilidade de mudanças | B17: 4 | C17: Consulta flexível sobre vários ALIs (2) e controles em tabelas alteráveis on-line com efeito imediato, como permissões/recursos (2). | D17: ProdutoRepository.pesquisar, PermissaoService, LojaService — avaliação documental; não implica consenso da equipe.
A19: NI | B19: =SUM(B4:B17) -> 38
A20: Constante FA | B20: 0.65
A21: Coeficiente NI | B21: 0.01
A22: FA | B22: =B20+B21*B19 -> 1.03
A23: PFB | B23: =Resumo!B10 -> 283
A24: PFA | B24: =B23*B22 -> 291.49
A27: Produtividade | B27: 10 | C27: horas-pessoa/PFA; premissa acadêmica
A28: Integrantes | B28: 3 | C28: pessoas com capacidade constante
A29: Jornada | B29: 8 | C29: horas/pessoa/dia útil; premissa
A30: Fração produtiva | B30: 0.75 | C30: 75% da jornada; premissa
A31: Valor-hora | B31: 25 | C31: R$/hora-pessoa; premissa
A32: Dias por semana | B32: 5 | C32: dias úteis/semana; premissa
A33: Reserva | B33: 0 | C33: fração do esforço base; sem contingência
A34: Custos adicionais | B34: 0 | C34: R$; infraestrutura e impostos não estimados
A36: Horas produtivas por pessoa | B36: =B29*B30 -> 6 | C36: h/pessoa/dia útil
A37: Esforço base | B37: =B24*B27 -> 2914.9 | C37: horas-pessoa
A38: Reserva em horas | B38: =B37*B33 -> 0 | C38: horas-pessoa
A39: Esforço total | B39: =SUM(B37:B38) -> 2914.9 | C39: horas-pessoa
A40: Capacidade diária | B40: =B28*B36 -> 18 | C40: horas-pessoa/dia útil
A41: Prazo fracionário | B41: =B39/B40 -> 161.93889 | C41: dias úteis
A42: Prazo arredondado | B42: =ROUNDUP(B41,0) -> 162 | C42: dias úteis inteiros
A43: Prazo em semanas | B43: =B42/B32 -> 32.4 | C43: semanas úteis
A44: Custo | B44: =B39*B31+B34 -> 72872.5 | C44: R$
A46: Esforço restante | B46: Não medido. Não aplicar PFA total como horas restantes para concluir o trabalho acadêmico.
A48: Consenso | B48: Notas são avaliação técnica revisada, com premissas identificadas. Reunião e aprovação coletiva não foram comprovadas.

Sheet Exemplos SE
A1: Exemplos numéricos conferíveis — dados didáticos
A2: Natureza | B2: Entradas fictícias para demonstrar as regras do código. Não são medições nem resultados extraídos das capturas.
A4: Função / cálculo | B4: Entrada 1 | C4: Entrada 2 | D4: Resultado por fórmula
A5: SE02: saldo × preço | B5: 5 | C5: 22 | D5: =ROUND(B5*C5,2) -> 110
A6: SE04: duas variações de entrada | B6: 3 | C6: 7 | D6: =SUM(B6:C6) -> 10
A7: SE06: saldo em duas posições | B7: 3 | C7: 7 | D7: =SUM(B7:C7) -> 10
A8: SE07: ocupado / capacidade | B8: 12 | C8: 10 | D8: =B8/C8 -> 1.2
A9: SE08: bruto − tara (kg) | B9: 1.44 | C9: 0.015 | D9: =B9-C9 -> 1.425
A10: SE08: líquido × preço/kg | B10: =D9 -> 1.425 | C10: 29.9 | D10: =ROUND(B10*C10,2) -> 42.61
A11: SE13: cotação − interno | B11: 89.9 | C11: 249.9 | D11: =ROUND(B11-C11,2) -> -160
A12: SE13: diferença / interno | B12: =D11 -> -160 | C12: =C11 -> 249.9 | D12: =IF(C12=0,"Não aplicável",B12/C12) -> -0.6402561
A13: SE10: reversores encontrados | B13: 1 | C13: 0 | D13: =IF(B13>C13,"Estornado","Sem estorno") -> Estornado
A16: SE02 | B16: Total da loja = soma dos valores por produto arredondados. Preço de venda, não custo histórico nem receita realizada.
A18: SE04 | B18: Duas operações e soma 3+7. Agrupa por produto e tipo. Não soma kg e unidades entre produtos. Datas em America/Sao_Paulo.
A20: SE07 | B20: O sistema compara ocupado > capacidade e apresenta alerta. A razão acima é explicação didática do medidor, não TD adicional contado.
A22: SE08 | B22: Captura real na loja granel: 1,440 kg bruto − 0,015 kg tara = 1,425 kg líquido; × R$ 29,90/kg = R$ 42,61. Simulador MQTT identificado, leitura com até 5 segundos; nenhum movimento registrado.
A24: SE09 | B24: Não atende sozinha ao requisito de valor numérico derivado: saída classificada por manutenção de auditoria. CSV e PDF contam uma função.
A26: SE10 | B26: EXISTS identifica reversor persistido. O status do movimento original é obtido por processamento, não um campo armazenado nele.
A28: Fusos distintos | B28: Fluxo gerencial usa Brasília; histórico/exportação usam UTC. Mesmos filtros de datas podem produzir conjuntos diferentes.

Sheet Critérios e fontes
A1: Critérios, fronteira e fontes
A3: Fronteira | B3: Dentro: aplicação Spring, regras, telas e dados persistidos. Fora: usuários, provedores independentes de fornecedores/ofertas e dispositivos IoT. MQTT transitório não é AIE.
A5: Grupos lógicos | B5: A01 modelos; A02 produtos; A03 posições; A04 vínculos/saldos; A05 movimentos; A06 usuários; A07 permissões; A08 lojas/configuração; A09 auditoria. Cada grupo tem intenção e manutenção próprias.
A7: AIEs | B7: X01 identidade e contato de fornecedores. X02 ofertas comerciais. Cada provedor mantém TSV por CLI independente. Clientes do estoque somente leem; HTTP sozinho não fundamenta AIE.
A9: Operações aplicáveis | B9: CRUD completo nos cadastros; produto/posição/usuário/loja têm exclusão lógica. Modelos sem uso e vínculos vazios têm exclusão física. Movimentos e auditoria não recebem edição/exclusão arbitrária.
A11: Unicidade | B11: IDs únicos no Catálogo. Canais de pesquisa, mapa/ocupação e formatos CSV/PDF não multiplicam funções. Os PFBs individuais não são somados.
A13: TD e controles | B13: Dados internos lidos para validação não são TD adicionais. Um conjunto de comandos e um campo de feedback por processo. Parte II EE p. 8 conta duas mensagens específicas: divergência de convenção explicitada; aceitação acadêmica deve ser confirmada.
A15: CE | B15: Entrada/saída separadas, repetição retirada da saída e MAX dos índices. AR de ambos os lados ficam explícitos. Sem etapa distinta de validação, os arquivos participam da seleção/recuperação da mesma consulta.
A17: Não contados | B17: CSRF, requestKey, fingerprint, versão de sessão, tentativas técnicas de login, healthcheck, tema, polling e paginação. Não são grupos/processos funcionais independentes nesta fronteira.
A19: Modelo visual | B19: docs/exemploEntregaPf.xlsx: fichas em quatro colunas, Arial, seções de contexto, campos, contagem e imagens. Abas ampliadas para catálogo coletivo e todas as 55 funções; não se conserva o recorte de outro sistema.
A21: Matrizes | B21: docs/pdfs/PF - Parte I.pdf p. 19/28; Parte II - EE.pdf p. 5/9; Parte II - SE.pdf p. 5/9; Parte III - CE.pdf p. 4/7/10–13.
A23: NI e planejamento | B23: docs/pdfs/Características Gerais do Software.pdf e PF - Parte IV - V2.pdf p. 9/11/14/15/18. Taxas de produtividade e dinheiro são hipóteses, não valores prescritos pelos slides.
A25: Código | B25: Referências curtas das fichas: Java em src/main/java/br/com/estoque; templates em src/main/resources/templates. Provedores em external/fornecedores e external/ofertas.
... A37: Fusos e limites | B37: Histórico/exportação: UTC e até 5.000 registros; fluxo gerencial: Brasília. Valores de ofertas são demonstrativos; não comprovam preço de mercado.

Sheet Conferência
A1: Atendimento e inconsistências da revisão
A3: ALI/AIE | B3: Atendido documentalmente: 9 ALIs e 2 AIEs, campos, RL, finalidade e código nas fichas.
A5: EE incluir/alterar/excluir | B5: 28 EEs identificadas; CRUD real de modelos executado. Exclusões lógicas/físicas e grupos sem CRUD arbitrário explicados.
A7: Ao menos cinco SEs | B7: Seis saídas numéricas demonstradas por exemplos e código. SE10 reclassificada; SE09 justificada por auditoria.
A9: Quatro CEs com entrada/saída | B9: CE04, CE05, CE08 e CE12 destacadas; oito CEs no coletivo. Protótipos de entrada/saída e TD deduplicados.
A11: Protótipos de todas as funções | B11: 55 fichas com 93 imagens reais incorporadas. Todas as EEs e CEs possuem entrada e saída; balança e LED mostram resposta real do simulador identificado, e SE09 inclui o PDF efetivamente exportado.
A13: Contagem completa | B13: Fórmulas em cada ficha alimentam catálogo e subtotais; cada ID uma vez.
A15: NI e justificativas | B15: 14 notas justificadas em NI e estimativas. Volume e múltiplos locais são premissas acadêmicas; a pontuação é avaliação técnica documental.
A17: FA e PFA | B17: Fórmulas ligadas ao PFB/NI. Divergência 0,35 versus 0,65 dos slides explicada.
A19: Esforço, prazo e custo | B19: Premissas editáveis, unidades e fórmulas; refere-se ao desenvolvimento integral. Esforço restante não medido.
A21: Preservação | B21: Modelo e três planilhas individuais preservados por verificação de SHA-256.
A23: Inconsistência CE06 | B23: Ficha anterior confundia campos internos do DTO com saída exibida. Removidos cinco campos não exibidos; adicionado código da posição.
A25: Inconsistência CE10 | B25: Status Estornado calculado por EXISTS não estava na ficha. Reclassificado como SE10, sem duplicação de função.
... A35: Pendência acadêmica | B35: Convenções de contagem e premissas estão explícitas. Não se declara consenso da equipe nem autoria individual não informada. Validação de compatibilidade realizada no LibreOffice; Microsoft Excel indisponível nesta máquina.

Sheet A01
A1: A01 — Modelos de produto
A2: Sistema e tipo | B2: Estoque Inteligente — ALI
A3: Intenção / finalidade | B3: Manter Modelos de produto como grupo lógico reconhecido pelo usuário.
A4: Fronteira e classificação | B4: Grupo persistente mantido pelo estoque; RL é tipo de registro, não quantidade de linhas.
A5: Rota / contexto | B5: /modelos
A6: Permissões | B6: Permissão cadastros para manutenção; consultar para leitura quando aplicável. Loja sempre validada.
A7: Evidência atual | B7: model/ModeloProduto.java; repository/ModeloProdutoRepository.java; service/ModeloProdutoService.java; templates/modelos.html
A8: Dados internos / regra | B8: Campos de negócio abaixo. Chaves técnicas, CSRF, versão de sessão e idempotência não são TD funcionais.
A10: Registro lógico | B10: Item de dado (TD) | C10: TD distinto | D10: RL distinto
A11: Registro de modelos de produto | B11: loja | C11: =IF(B11="",0,IF(COUNTIF($B$11:B11,B11)=1,1,0)) -> 1 | D11: =IF(A11="",0,IF(COUNTIF($A$11:A11,A11)=1,1,0)) -> 1
A12: Registro de modelos de produto | B12: código | C12: =IF(B12="",0,IF(COUNTIF($B$11:B12,B12)=1,1,0)) -> 1 | D12: =IF(A12="",0,IF(COUNTIF($A$11:A12,A12)=1,1,0)) -> 0
A13: Registro de modelos de produto | B13: nome | C13: =IF(B13="",0,IF(COUNTIF($B$11:B13,B13)=1,1,0)) -> 1 | D13: =IF(A13="",0,IF(COUNTIF($A$11:A13,A13)=1,1,0)) -> 0
A14: Registro de modelos de produto | B14: marca | C14: =IF(B14="",0,IF(COUNTIF($B$11:B14,B14)=1,1,0)) -> 1 | D14: =IF(A14="",0,IF(COUNTIF($A$11:A14,A14)=1,1,0)) -> 0
A15: Registro de modelos de produto | B15: categoria | C15: =IF(B15="",0,IF(COUNTIF($B$11:B15,B15)=1,1,0)) -> 1 | D15: =IF(A15="",0,IF(COUNTIF($A$11:A15,A15)=1,1,0)) -> 0
C16: =IF(B16="",0,IF(COUNTIF($B$11:B16,B16)=1,1,0)) -> 0 | D16: =IF(A16="",0,IF(COUNTIF($A$11:A16,A16)=1,1,0)) -> 0
C17: =IF(B17="",0,IF(COUNTIF($B$11:B17,B17)=1,1,0)) -> 0 | D17: =IF(A17="",0,IF(COUNTIF($A$11:A17,A17)=1,1,0)) -> 0
C18: =IF(B18="",0,IF(COUNTIF($B$11:B18,B18)=1,1,0)) -> 0 | D18: =IF(A18="",0,IF(COUNTIF($A$11:A18,A18)=1,1,0)) -> 0
C19: =IF(B19="",0,IF(COUNTIF($B$11:B19,B19)=1,1,0)) -> 0 | D19: =IF(A19="",0,IF(COUNTIF($A$11:A19,A19)=1,1,0)) -> 0
C20: =IF(B20="",0,IF(COUNTIF($B$11:B20,B20)=1,1,0)) -> 0 | D20: =IF(A20="",0,IF(COUNTIF($A$11:A20,A20)=1,1,0)) -> 0
C21: =IF(B21="",0,IF(COUNTIF($B$11:B21,B21)=1,1,0)) -> 0 | D21: =IF(A21="",0,IF(COUNTIF($A$11:A21,A21)=1,1,0)) -> 0
C22: =IF(B22="",0,IF(COUNTIF($B$11:B22,B22)=1,1,0)) -> 0 | D22: =IF(A22="",0,IF(COUNTIF($A$11:A22,A22)=1,1,0)) -> 0
C23: =IF(B23="",0,IF(COUNTIF($B$11:B23,B23)=1,1,0)) -> 0 | D23: =IF(A23="",0,IF(COUNTIF($A$11:A23,A23)=1,1,0)) -> 0
C24: =IF(B24="",0,IF(COUNTIF($B$11:B24,B24)=1,1,0)) -> 0 | D24: =IF(A24="",0,IF(COUNTIF($A$11:A24,A24)=1,1,0)) -> 0
C25: =IF(B25="",0,IF(COUNTIF($B$11:B25,B25)=1,1,0)) -> 0 | D25: =IF(A25="",0,IF(COUNTIF($A$11:A25,A25)=1,1,0)) -> 0
C26: =IF(B26="",0,IF(COUNTIF($B$11:B26,B26)=1,1,0)) -> 0 | D26: =IF(A26="",0,IF(COUNTIF($A$11:A26,A26)=1,1,0)) -> 0
C27: =IF(B27="",0,IF(COUNTIF($B$11:B27,B27)=1,1,0)) -> 0 | D27: =IF(A27="",0,IF(COUNTIF($A$11:A27,A27)=1,1,0)) -> 0
... C42: =IF(B42="",0,IF(COUNTIF($B$11:B42,B42)=1,1,0)) -> 0 | D42: =IF(A42="",0,IF(COUNTIF($A$11:A42,A42)=1,1,0)) -> 0
A44: Manutenção do grupo lógico
A45: ALI / AIE | B45: Finalidade da referência | C45: AR entrada CE | D45: AR saída CE
A46: Manutenção | B46: Inclusão, alteração e exclusão conforme as EEs de manutenção; consultar catálogo.
A57: Regra AR / RL | B57: Somar RL distintos, não linhas armazenadas. Campos repetidos contam uma vez.
A59: Contagem calculada — entradas editáveis acima
A60: TD total distinto | B60: =SUM(C11:C42) -> 5 | C60: RL distintos | D60: =SUM(D11:D42) -> 1
A61: TD entrada CE | B61: =0 -> 0 | C61: TD saída sem repetição | D61: =0 -> 0
A62: AR entrada CE | B62: =0 -> 0 | C62: AR saída CE | D62: =0 -> 0
A63: Índice entrada CE | B63: =0 -> 0 | C63: Índice saída CE | D63: =0 -> 0
A64: Índice adotado | B64: =INDEX(Matrizes!$B$5:$D$7,IF(D60<=1,1,IF(D60<=5,2,3)),IF(B60<=19,1,IF(B60<=50,2,3))) -> 1 | C64: Complexidade | D64: =INDEX(Matrizes!$B$10:$D$10,1,B64) -> Simples
A65: Peso apropriado ao tipo | B65: =INDEX(Matrizes!$B$13:$D$17,MATCH("ALI",Matrizes!$A$13:$A$17,0),B64) -> 7 | C65: PF desta função | D65: =B65 -> 7
A67: Justificativa da contagem | B67: Peso por TD/RL da Parte I. Cada grupo entra uma única vez no coletivo.
A69: Fluxo da função — leitura do protótipo real
...

Sheet A02
A1: A02 — Produtos
A2: Sistema e tipo | B2: Estoque Inteligente — ALI
A3: Intenção / finalidade | B3: Manter Produtos como grupo lógico reconhecido pelo usuário.
A4: Fronteira e classificação | B4: Grupo persistente mantido pelo estoque; RL é tipo de registro, não quantidade de linhas.
A5: Rota / contexto | B5: /produtos
A6: Permissões | B6: Permissão cadastros para manutenção; consultar para leitura quando aplicável. Loja sempre validada.
A7: Evidência atual | B7: model/Produto.java; repository/ProdutoRepository.java; service/ProdutoService.java; templates/produtos.html
A8: Dados internos / regra | B8: Campos de negócio abaixo. Chaves técnicas, CSRF, versão de sessão e idempotência não são TD funcionais.
A10: Registro lógico | B10: Item de dado (TD) | C10: TD distinto | D10: RL distinto
A11: Registro de produtos | B11: loja | C11: =IF(B11="",0,IF(COUNTIF($B$11:B11,B11)=1,1,0)) -> 1 | D11: =IF(A11="",0,IF(COUNTIF($A$11:A11,A11)=1,1,0)) -> 1
A12: Registro de produtos | B12: código | C12: =IF(B12="",0,IF(COUNTIF($B$11:B12,B12)=1,1,0)) -> 1 | D12: =IF(A12="",0,IF(COUNTIF($A$11:A12,A12)=1,1,0)) -> 0
A13: Registro de produtos | B13: modelo | C13: =IF(B13="",0,IF(COUNTIF($B$11:B13,B13)=1,1,0)) -> 1 | D13: =IF(A13="",0,IF(COUNTIF($A$11:A13,A13)=1,1,0)) -> 0
A14: Registro de produtos | B14: SKU | C14: =IF(B14="",0,IF(COUNTIF($B$11:B14,B14)=1,1,0)) -> 1 | D14: =IF(A14="",0,IF(COUNTIF($A$11:A14,A14)=1,1,0)) -> 0
A15: Registro de produtos | B15: código de barras | C15: =IF(B15="",0,IF(COUNTIF($B$11:B15,B15)=1,1,0)) -> 1 | D15: =IF(A15="",0,IF(COUNTIF($A$11:A15,A15)=1,1,0)) -> 0
A16: Registro de produtos | B16: cor | C16: =IF(B16="",0,IF(COUNTIF($B$11:B16,B16)=1,1,0)) -> 1 | D16: =IF(A16="",0,IF(COUNTIF($A$11:A16,A16)=1,1,0)) -> 0
A17: Registro de produtos | B17: tamanho | C17: =IF(B17="",0,IF(COUNTIF($B$11:B17,B17)=1,1,0)) -> 1 | D17: =IF(A17="",0,IF(COUNTIF($A$11:A17,A17)=1,1,0)) -> 0
A18: Registro de produtos | B18: unidade | C18: =IF(B18="",0,IF(COUNTIF($B$11:B18,B18)=1,1,0)) -> 1 | D18: =IF(A18="",0,IF(COUNTIF($A$11:A18,A18)=1,1,0)) -> 0
A19: Registro de produtos | B19: preço | C19: =IF(B19="",0,IF(COUNTIF($B$11:B19,B19)=1,1,0)) -> 1 | D19: =IF(A19="",0,IF(COUNTIF($A$11:A19,A19)=1,1,0)) -> 0
A20: Registro de produtos | B20: características | C20: =IF(B20="",0,IF(COUNTIF($B$11:B20,B20)=1,1,0)) -> 1 | D20: =IF(A20="",0,IF(COUNTIF($A$11:A20,A20)=1,1,0)) -> 0
A21: Registro de produtos | B21: ativo | C21: =IF(B21="",0,IF(COUNTIF($B$11:B21,B21)=1,1,0)) -> 1 | D21: =IF(A21="",0,IF(COUNTIF($A$11:A21,A21)=1,1,0)) -> 0
C22: =IF(B22="",0,IF(COUNTIF($B$11:B22,B22)=1,1,0)) -> 0 | D22: =IF(A22="",0,IF(COUNTIF($A$11:A22,A22)=1,1,0)) -> 0
C23: =IF(B23="",0,IF(COUNTIF($B$11:B23,B23)=1,1,0)) -> 0 | D23: =IF(A23="",0,IF(COUNTIF($A$11:A23,A23)=1,1,0)) -> 0
C24: =IF(B24="",0,IF(COUNTIF($B$11:B24,B24)=1,1,0)) -> 0 | D24: =IF(A24="",0,IF(COUNTIF($A$11:A24,A24)=1,1,0)) -> 0
C25: =IF(B25="",0,IF(COUNTIF($B$11:B25,B25)=1,1,0)) -> 0 | D25: =IF(A25="",0,IF(COUNTIF($A$11:A25,A25)=1,1,0)) -> 0
C26: =IF(B26="",0,IF(COUNTIF($B$11:B26,B26)=1,1,0)) -> 0 | D26: =IF(A26="",0,IF(COUNTIF($A$11:A26,A26)=1,1,0)) -> 0
C27: =IF(B27="",0,IF(COUNTIF($B$11:B27,B27)=1,1,0)) -> 0 | D27: =IF(A27="",0,IF(COUNTIF($A$11:A27,A27)=1,1,0)) -> 0
C28: =IF(B28="",0,IF(COUNTIF($B$11:B28,B28)=1,1,0)) -> 0 | D28: =IF(A28="",0,IF(COUNTIF($A$11:A28,A28)=1,1,0)) -> 0
C29: =IF(B29="",0,IF(COUNTIF($B$11:B29,B29)=1,1,0)) -> 0 | D29: =IF(A29="",0,IF(COUNTIF($A$11:A29,A29)=1,1,0)) -> 0
C30: =IF(B30="",0,IF(COUNTIF($B$11:B30,B30)=1,1,0)) -> 0 | D30: =IF(A30="",0,IF(COUNTIF($A$11:A30,A30)=1,1,0)) -> 0
C31: =IF(B31="",0,IF(COUNTIF($B$11:B31,B31)=1,1,0)) -> 0 | D31: =IF(A31="",0,IF(COUNTIF($A$11:A31,A31)=1,1,0)) -> 0
C32: =IF(B32="",0,IF(COUNTIF($B$11:B32,B32)=1,1,0)) -> 0 | D32: =IF(A32="",0,IF(COUNTIF($A$11:A32,A32)=1,1,0)) -> 0
C33: =IF(B33="",0,IF(COUNTIF($B$11:B33,B33)=1,1,0)) -> 0 | D33: =IF(A33="",0,IF(COUNTIF($A$11:A33,A33)=1,1,0)) -> 0
... C42: =IF(B42="",0,IF(COUNTIF($B$11:B42,B42)=1,1,0)) -> 0 | D42: =IF(A42="",0,IF(COUNTIF($A$11:A42,A42)=1,1,0)) -> 0
A44: Manutenção do grupo lógico
A45: ALI / AIE | B45: Finalidade da referência | C45: AR entrada CE | D45: AR saída CE
A46: Manutenção | B46: Inclusão, alteração e exclusão conforme as EEs de manutenção; consultar catálogo.
A57: Regra AR / RL | B57: Somar RL distintos, não linhas armazenadas. Campos repetidos contam uma vez.
A59: Contagem calculada — entradas editáveis acima
A60: TD total distinto | B60: =SUM(C11:C42) -> 11 | C60: RL distintos | D60: =SUM(D11:D42) -> 1
A61: TD entrada CE | B61: =0 -> 0 | C61: TD saída sem repetição | D61: =0 -> 0
...

Sheet A03
A1: A03 — Posições
A2: Sistema e tipo | B2: Estoque Inteligente — ALI
A3: Intenção / finalidade | B3: Manter Posições como grupo lógico reconhecido pelo usuário.
A4: Fronteira e classificação | B4: Grupo persistente mantido pelo estoque; RL é tipo de registro, não quantidade de linhas.
A5: Rota / contexto | B5: /posicoes
A6: Permissões | B6: Permissão cadastros para manutenção; consultar para leitura quando aplicável. Loja sempre validada.
A7: Evidência atual | B7: model/Posicao.java; repository/PosicaoRepository.java; service/PosicaoService.java; templates/posicoes.html
A8: Dados internos / regra | B8: Campos de negócio abaixo. Chaves técnicas, CSRF, versão de sessão e idempotência não são TD funcionais.
A10: Registro lógico | B10: Item de dado (TD) | C10: TD distinto | D10: RL distinto
A11: Registro de posições | B11: loja | C11: =IF(B11="",0,IF(COUNTIF($B$11:B11,B11)=1,1,0)) -> 1 | D11: =IF(A11="",0,IF(COUNTIF($A$11:A11,A11)=1,1,0)) -> 1
A12: Registro de posições | B12: identificador | C12: =IF(B12="",0,IF(COUNTIF($B$11:B12,B12)=1,1,0)) -> 1 | D12: =IF(A12="",0,IF(COUNTIF($A$11:A12,A12)=1,1,0)) -> 0
A13: Registro de posições | B13: código | C13: =IF(B13="",0,IF(COUNTIF($B$11:B13,B13)=1,1,0)) -> 1 | D13: =IF(A13="",0,IF(COUNTIF($A$11:A13,A13)=1,1,0)) -> 0
A14: Registro de posições | B14: setor | C14: =IF(B14="",0,IF(COUNTIF($B$11:B14,B14)=1,1,0)) -> 1 | D14: =IF(A14="",0,IF(COUNTIF($A$11:A14,A14)=1,1,0)) -> 0
A15: Registro de posições | B15: linha | C15: =IF(B15="",0,IF(COUNTIF($B$11:B15,B15)=1,1,0)) -> 1 | D15: =IF(A15="",0,IF(COUNTIF($A$11:A15,A15)=1,1,0)) -> 0
A16: Registro de posições | B16: coluna | C16: =IF(B16="",0,IF(COUNTIF($B$11:B16,B16)=1,1,0)) -> 1 | D16: =IF(A16="",0,IF(COUNTIF($A$11:A16,A16)=1,1,0)) -> 0
A17: Registro de posições | B17: capacidade | C17: =IF(B17="",0,IF(COUNTIF($B$11:B17,B17)=1,1,0)) -> 1 | D17: =IF(A17="",0,IF(COUNTIF($A$11:A17,A17)=1,1,0)) -> 0
A18: Registro de posições | B18: unidade | C18: =IF(B18="",0,IF(COUNTIF($B$11:B18,B18)=1,1,0)) -> 1 | D18: =IF(A18="",0,IF(COUNTIF($A$11:A18,A18)=1,1,0)) -> 0
A19: Registro de posições | B19: dispositivo | C19: =IF(B19="",0,IF(COUNTIF($B$11:B19,B19)=1,1,0)) -> 1 | D19: =IF(A19="",0,IF(COUNTIF($A$11:A19,A19)=1,1,0)) -> 0
A20: Registro de posições | B20: pino | C20: =IF(B20="",0,IF(COUNTIF($B$11:B20,B20)=1,1,0)) -> 1 | D20: =IF(A20="",0,IF(COUNTIF($A$11:A20,A20)=1,1,0)) -> 0
A21: Registro de posições | B21: ativo | C21: =IF(B21="",0,IF(COUNTIF($B$11:B21,B21)=1,1,0)) -> 1 | D21: =IF(A21="",0,IF(COUNTIF($A$11:A21,A21)=1,1,0)) -> 0
C22: =IF(B22="",0,IF(COUNTIF($B$11:B22,B22)=1,1,0)) -> 0 | D22: =IF(A22="",0,IF(COUNTIF($A$11:A22,A22)=1,1,0)) -> 0
C23: =IF(B23="",0,IF(COUNTIF($B$11:B23,B23)=1,1,0)) -> 0 | D23: =IF(A23="",0,IF(COUNTIF($A$11:A23,A23)=1,1,0)) -> 0
C24: =IF(B24="",0,IF(COUNTIF($B$11:B24,B24)=1,1,0)) -> 0 | D24: =IF(A24="",0,IF(COUNTIF($A$11:A24,A24)=1,1,0)) -> 0
C25: =IF(B25="",0,IF(COUNTIF($B$11:B25,B25)=1,1,0)) -> 0 | D25: =IF(A25="",0,IF(COUNTIF($A$11:A25,A25)=1,1,0)) -> 0
C26: =IF(B26="",0,IF(COUNTIF($B$11:B26,B26)=1,1,0)) -> 0 | D26: =IF(A26="",0,IF(COUNTIF($A$11:A26,A26)=1,1,0)) -> 0
C27: =IF(B27="",0,IF(COUNTIF($B$11:B27,B27)=1,1,0)) -> 0 | D27: =IF(A27="",0,IF(COUNTIF($A$11:A27,A27)=1,1,0)) -> 0
C28: =IF(B28="",0,IF(COUNTIF($B$11:B28,B28)=1,1,0)) -> 0 | D28: =IF(A28="",0,IF(COUNTIF($A$11:A28,A28)=1,1,0)) -> 0
C29: =IF(B29="",0,IF(COUNTIF($B$11:B29,B29)=1,1,0)) -> 0 | D29: =IF(A29="",0,IF(COUNTIF($A$11:A29,A29)=1,1,0)) -> 0
C30: =IF(B30="",0,IF(COUNTIF($B$11:B30,B30)=1,1,0)) -> 0 | D30: =IF(A30="",0,IF(COUNTIF($A$11:A30,A30)=1,1,0)) -> 0
C31: =IF(B31="",0,IF(COUNTIF($B$11:B31,B31)=1,1,0)) -> 0 | D31: =IF(A31="",0,IF(COUNTIF($A$11:A31,A31)=1,1,0)) -> 0
C32: =IF(B32="",0,IF(COUNTIF($B$11:B32,B32)=1,1,0)) -> 0 | D32: =IF(A32="",0,IF(COUNTIF($A$11:A32,A32)=1,1,0)) -> 0
C33: =IF(B33="",0,IF(COUNTIF($B$11:B33,B33)=1,1,0)) -> 0 | D33: =IF(A33="",0,IF(COUNTIF($A$11:A33,A33)=1,1,0)) -> 0
... C42: =IF(B42="",0,IF(COUNTIF($B$11:B42,B42)=1,1,0)) -> 0 | D42: =IF(A42="",0,IF(COUNTIF($A$11:A42,A42)=1,1,0)) -> 0
A44: Manutenção do grupo lógico
A45: ALI / AIE | B45: Finalidade da referência | C45: AR entrada CE | D45: AR saída CE
A46: Manutenção | B46: Inclusão, alteração e exclusão conforme as EEs de manutenção; consultar catálogo.
A57: Regra AR / RL | B57: Somar RL distintos, não linhas armazenadas. Campos repetidos contam uma vez.
A59: Contagem calculada — entradas editáveis acima
A60: TD total distinto | B60: =SUM(C11:C42) -> 11 | C60: RL distintos | D60: =SUM(D11:D42) -> 1
A61: TD entrada CE | B61: =0 -> 0 | C61: TD saída sem repetição | D61: =0 -> 0
...

Sheet A04
A1: A04 — Estoque por posição / vínculos
A2: Sistema e tipo | B2: Estoque Inteligente — ALI
A3: Intenção / finalidade | B3: Manter Estoque por posição / vínculos como grupo lógico reconhecido pelo usuário.
A4: Fronteira e classificação | B4: Grupo persistente mantido pelo estoque; RL é tipo de registro, não quantidade de linhas.
A5: Rota / contexto | B5: /vinculos
A6: Permissões | B6: Permissão cadastros para manutenção; consultar para leitura quando aplicável. Loja sempre validada.
A7: Evidência atual | B7: model/Ocupacao.java; repository/OcupacaoRepository.java; service/VinculoService.java; templates/vinculos.html
A8: Dados internos / regra | B8: Campos de negócio abaixo. Chaves técnicas, CSRF, versão de sessão e idempotência não são TD funcionais.
A10: Registro lógico | B10: Item de dado (TD) | C10: TD distinto | D10: RL distinto
A11: Registro de estoque por posição / vínculos | B11: loja | C11: =IF(B11="",0,IF(COUNTIF($B$11:B11,B11)=1,1,0)) -> 1 | D11: =IF(A11="",0,IF(COUNTIF($A$11:A11,A11)=1,1,0)) -> 1
A12: Registro de estoque por posição / vínculos | B12: produto | C12: =IF(B12="",0,IF(COUNTIF($B$11:B12,B12)=1,1,0)) -> 1 | D12: =IF(A12="",0,IF(COUNTIF($A$11:A12,A12)=1,1,0)) -> 0
A13: Registro de estoque por posição / vínculos | B13: posição | C13: =IF(B13="",0,IF(COUNTIF($B$11:B13,B13)=1,1,0)) -> 1 | D13: =IF(A13="",0,IF(COUNTIF($A$11:A13,A13)=1,1,0)) -> 0
A14: Registro de estoque por posição / vínculos | B14: quantidade | C14: =IF(B14="",0,IF(COUNTIF($B$11:B14,B14)=1,1,0)) -> 1 | D14: =IF(A14="",0,IF(COUNTIF($A$11:A14,A14)=1,1,0)) -> 0
C15: =IF(B15="",0,IF(COUNTIF($B$11:B15,B15)=1,1,0)) -> 0 | D15: =IF(A15="",0,IF(COUNTIF($A$11:A15,A15)=1,1,0)) -> 0
C16: =IF(B16="",0,IF(COUNTIF($B$11:B16,B16)=1,1,0)) -> 0 | D16: =IF(A16="",0,IF(COUNTIF($A$11:A16,A16)=1,1,0)) -> 0
C17: =IF(B17="",0,IF(COUNTIF($B$11:B17,B17)=1,1,0)) -> 0 | D17: =IF(A17="",0,IF(COUNTIF($A$11:A17,A17)=1,1,0)) -> 0
C18: =IF(B18="",0,IF(COUNTIF($B$11:B18,B18)=1,1,0)) -> 0 | D18: =IF(A18="",0,IF(COUNTIF($A$11:A18,A18)=1,1,0)) -> 0
C19: =IF(B19="",0,IF(COUNTIF($B$11:B19,B19)=1,1,0)) -> 0 | D19: =IF(A19="",0,IF(COUNTIF($A$11:A19,A19)=1,1,0)) -> 0
C20: =IF(B20="",0,IF(COUNTIF($B$11:B20,B20)=1,1,0)) -> 0 | D20: =IF(A20="",0,IF(COUNTIF($A$11:A20,A20)=1,1,0)) -> 0
C21: =IF(B21="",0,IF(COUNTIF($B$11:B21,B21)=1,1,0)) -> 0 | D21: =IF(A21="",0,IF(COUNTIF($A$11:A21,A21)=1,1,0)) -> 0
C22: =IF(B22="",0,IF(COUNTIF($B$11:B22,B22)=1,1,0)) -> 0 | D22: =IF(A22="",0,IF(COUNTIF($A$11:A22,A22)=1,1,0)) -> 0
C23: =IF(B23="",0,IF(COUNTIF($B$11:B23,B23)=1,1,0)) -> 0 | D23: =IF(A23="",0,IF(COUNTIF($A$11:A23,A23)=1,1,0)) -> 0
C24: =IF(B24="",0,IF(COUNTIF($B$11:B24,B24)=1,1,0)) -> 0 | D24: =IF(A24="",0,IF(COUNTIF($A$11:A24,A24)=1,1,0)) -> 0
C25: =IF(B25="",0,IF(COUNTIF($B$11:B25,B25)=1,1,0)) -> 0 | D25: =IF(A25="",0,IF(COUNTIF($A$11:A25,A25)=1,1,0)) -> 0
C26: =IF(B26="",0,IF(COUNTIF($B$11:B26,B26)=1,1,0)) -> 0 | D26: =IF(A26="",0,IF(COUNTIF($A$11:A26,A26)=1,1,0)) -> 0
... C42: =IF(B42="",0,IF(COUNTIF($B$11:B42,B42)=1,1,0)) -> 0 | D42: =IF(A42="",0,IF(COUNTIF($A$11:A42,A42)=1,1,0)) -> 0
A44: Manutenção do grupo lógico
A45: ALI / AIE | B45: Finalidade da referência | C45: AR entrada CE | D45: AR saída CE
A46: Manutenção | B46: Inclusão, alteração e exclusão conforme as EEs de manutenção; consultar catálogo.
A57: Regra AR / RL | B57: Somar RL distintos, não linhas armazenadas. Campos repetidos contam uma vez.
A59: Contagem calculada — entradas editáveis acima
A60: TD total distinto | B60: =SUM(C11:C42) -> 4 | C60: RL distintos | D60: =SUM(D11:D42) -> 1
A61: TD entrada CE | B61: =0 -> 0 | C61: TD saída sem repetição | D61: =0 -> 0
A62: AR entrada CE | B62: =0 -> 0 | C62: AR saída CE | D62: =0 -> 0
A63: Índice entrada CE | B63: =0 -> 0 | C63: Índice saída CE | D63: =0 -> 0
A64: Índice adotado | B64: =INDEX(Matrizes!$B$5:$D$7,IF(D60<=1,1,IF(D60<=5,2,3)),IF(B60<=19,1,IF(B60<=50,2,3))) -> 1 | C64: Complexidade | D64: =INDEX(Matrizes!$B$10:$D$10,1,B64) -> Simples
A65: Peso apropriado ao tipo | B65: =INDEX(Matrizes!$B$13:$D$17,MATCH("ALI",Matrizes!$A$13:$A$17,0),B64) -> 7 | C65: PF desta função | D65: =B65 -> 7
A67: Justificativa da contagem | B67: Peso por TD/RL da Parte I. Cada grupo entra uma única vez no coletivo.
A69: Fluxo da função — leitura do protótipo real
A70: Entrada / contexto | B70: loja; produto; posição; quantidade
...

Sheet A05
A1: A05 — Movimentações
A2: Sistema e tipo | B2: Estoque Inteligente — ALI
A3: Intenção / finalidade | B3: Manter Movimentações como grupo lógico reconhecido pelo usuário.
A4: Fronteira e classificação | B4: Grupo persistente mantido pelo estoque; RL é tipo de registro, não quantidade de linhas.
A5: Rota / contexto | B5: /historico
A6: Permissões | B6: Permissão historico e isolamento pela loja autenticada.
A7: Evidência atual | B7: model/Movimentacao.java; repository/MovimentacaoRepository.java; service/EstoqueService.java; templates/historico.html
A8: Dados internos / regra | B8: Campos de negócio abaixo. Chaves técnicas, CSRF, versão de sessão e idempotência não são TD funcionais.
A10: Registro lógico | B10: Item de dado (TD) | C10: TD distinto | D10: RL distinto
A11: Registro de movimentações | B11: loja | C11: =IF(B11="",0,IF(COUNTIF($B$11:B11,B11)=1,1,0)) -> 1 | D11: =IF(A11="",0,IF(COUNTIF($A$11:A11,A11)=1,1,0)) -> 1
A12: Registro de movimentações | B12: número | C12: =IF(B12="",0,IF(COUNTIF($B$11:B12,B12)=1,1,0)) -> 1 | D12: =IF(A12="",0,IF(COUNTIF($A$11:A12,A12)=1,1,0)) -> 0
A13: Registro de movimentações | B13: produto | C13: =IF(B13="",0,IF(COUNTIF($B$11:B13,B13)=1,1,0)) -> 1 | D13: =IF(A13="",0,IF(COUNTIF($A$11:A13,A13)=1,1,0)) -> 0
A14: Registro de movimentações | B14: posição | C14: =IF(B14="",0,IF(COUNTIF($B$11:B14,B14)=1,1,0)) -> 1 | D14: =IF(A14="",0,IF(COUNTIF($A$11:A14,A14)=1,1,0)) -> 0
A15: Registro de movimentações | B15: responsável | C15: =IF(B15="",0,IF(COUNTIF($B$11:B15,B15)=1,1,0)) -> 1 | D15: =IF(A15="",0,IF(COUNTIF($A$11:A15,A15)=1,1,0)) -> 0
A16: Registro de movimentações | B16: tipo | C16: =IF(B16="",0,IF(COUNTIF($B$11:B16,B16)=1,1,0)) -> 1 | D16: =IF(A16="",0,IF(COUNTIF($A$11:A16,A16)=1,1,0)) -> 0
A17: Registro de movimentações | B17: variação | C17: =IF(B17="",0,IF(COUNTIF($B$11:B17,B17)=1,1,0)) -> 1 | D17: =IF(A17="",0,IF(COUNTIF($A$11:A17,A17)=1,1,0)) -> 0
A18: Registro de movimentações | B18: saldo anterior | C18: =IF(B18="",0,IF(COUNTIF($B$11:B18,B18)=1,1,0)) -> 1 | D18: =IF(A18="",0,IF(COUNTIF($A$11:A18,A18)=1,1,0)) -> 0
A19: Registro de movimentações | B19: saldo posterior | C19: =IF(B19="",0,IF(COUNTIF($B$11:B19,B19)=1,1,0)) -> 1 | D19: =IF(A19="",0,IF(COUNTIF($A$11:A19,A19)=1,1,0)) -> 0
A20: Registro de movimentações | B20: motivo | C20: =IF(B20="",0,IF(COUNTIF($B$11:B20,B20)=1,1,0)) -> 1 | D20: =IF(A20="",0,IF(COUNTIF($A$11:A20,A20)=1,1,0)) -> 0
A21: Registro de movimentações | B21: data | C21: =IF(B21="",0,IF(COUNTIF($B$11:B21,B21)=1,1,0)) -> 1 | D21: =IF(A21="",0,IF(COUNTIF($A$11:A21,A21)=1,1,0)) -> 0
A22: Registro de movimentações | B22: movimento original | C22: =IF(B22="",0,IF(COUNTIF($B$11:B22,B22)=1,1,0)) -> 1 | D22: =IF(A22="",0,IF(COUNTIF($A$11:A22,A22)=1,1,0)) -> 0
C23: =IF(B23="",0,IF(COUNTIF($B$11:B23,B23)=1,1,0)) -> 0 | D23: =IF(A23="",0,IF(COUNTIF($A$11:A23,A23)=1,1,0)) -> 0
C24: =IF(B24="",0,IF(COUNTIF($B$11:B24,B24)=1,1,0)) -> 0 | D24: =IF(A24="",0,IF(COUNTIF($A$11:A24,A24)=1,1,0)) -> 0
C25: =IF(B25="",0,IF(COUNTIF($B$11:B25,B25)=1,1,0)) -> 0 | D25: =IF(A25="",0,IF(COUNTIF($A$11:A25,A25)=1,1,0)) -> 0
C26: =IF(B26="",0,IF(COUNTIF($B$11:B26,B26)=1,1,0)) -> 0 | D26: =IF(A26="",0,IF(COUNTIF($A$11:A26,A26)=1,1,0)) -> 0
C27: =IF(B27="",0,IF(COUNTIF($B$11:B27,B27)=1,1,0)) -> 0 | D27: =IF(A27="",0,IF(COUNTIF($A$11:A27,A27)=1,1,0)) -> 0
C28: =IF(B28="",0,IF(COUNTIF($B$11:B28,B28)=1,1,0)) -> 0 | D28: =IF(A28="",0,IF(COUNTIF($A$11:A28,A28)=1,1,0)) -> 0
C29: =IF(B29="",0,IF(COUNTIF($B$11:B29,B29)=1,1,0)) -> 0 | D29: =IF(A29="",0,IF(COUNTIF($A$11:A29,A29)=1,1,0)) -> 0
C30: =IF(B30="",0,IF(COUNTIF($B$11:B30,B30)=1,1,0)) -> 0 | D30: =IF(A30="",0,IF(COUNTIF($A$11:A30,A30)=1,1,0)) -> 0
C31: =IF(B31="",0,IF(COUNTIF($B$11:B31,B31)=1,1,0)) -> 0 | D31: =IF(A31="",0,IF(COUNTIF($A$11:A31,A31)=1,1,0)) -> 0
C32: =IF(B32="",0,IF(COUNTIF($B$11:B32,B32)=1,1,0)) -> 0 | D32: =IF(A32="",0,IF(COUNTIF($A$11:A32,A32)=1,1,0)) -> 0
C33: =IF(B33="",0,IF(COUNTIF($B$11:B33,B33)=1,1,0)) -> 0 | D33: =IF(A33="",0,IF(COUNTIF($A$11:A33,A33)=1,1,0)) -> 0
C34: =IF(B34="",0,IF(COUNTIF($B$11:B34,B34)=1,1,0)) -> 0 | D34: =IF(A34="",0,IF(COUNTIF($A$11:A34,A34)=1,1,0)) -> 0
... C42: =IF(B42="",0,IF(COUNTIF($B$11:B42,B42)=1,1,0)) -> 0 | D42: =IF(A42="",0,IF(COUNTIF($A$11:A42,A42)=1,1,0)) -> 0
A44: Manutenção do grupo lógico
A45: ALI / AIE | B45: Finalidade da referência | C45: AR entrada CE | D45: AR saída CE
A46: Manutenção | B46: Registro imutável por movimentos; correção por estorno, sem CRUD arbitrário.
A57: Regra AR / RL | B57: Somar RL distintos, não linhas armazenadas. Campos repetidos contam uma vez.
A59: Contagem calculada — entradas editáveis acima
A60: TD total distinto | B60: =SUM(C11:C42) -> 12 | C60: RL distintos | D60: =SUM(D11:D42) -> 1
...

Sheet A06
A1: A06 — Usuários
A2: Sistema e tipo | B2: Estoque Inteligente — ALI
A3: Intenção / finalidade | B3: Manter Usuários como grupo lógico reconhecido pelo usuário.
A4: Fronteira e classificação | B4: Grupo persistente mantido pelo estoque; RL é tipo de registro, não quantidade de linhas.
A5: Rota / contexto | B5: /usuarios
A6: Permissões | B6: Permissão usuarios; proteção do último administrador e impedimento de autoexclusão.
A7: Evidência atual | B7: model/Usuario.java; repository/UsuarioRepository.java; service/UsuarioService.java; templates/usuarios.html
A8: Dados internos / regra | B8: Campos de negócio abaixo. Chaves técnicas, CSRF, versão de sessão e idempotência não são TD funcionais.
A10: Registro lógico | B10: Item de dado (TD) | C10: TD distinto | D10: RL distinto
A11: Registro de usuários | B11: loja | C11: =IF(B11="",0,IF(COUNTIF($B$11:B11,B11)=1,1,0)) -> 1 | D11: =IF(A11="",0,IF(COUNTIF($A$11:A11,A11)=1,1,0)) -> 1
A12: Registro de usuários | B12: código | C12: =IF(B12="",0,IF(COUNTIF($B$11:B12,B12)=1,1,0)) -> 1 | D12: =IF(A12="",0,IF(COUNTIF($A$11:A12,A12)=1,1,0)) -> 0
A13: Registro de usuários | B13: nome de usuário | C13: =IF(B13="",0,IF(COUNTIF($B$11:B13,B13)=1,1,0)) -> 1 | D13: =IF(A13="",0,IF(COUNTIF($A$11:A13,A13)=1,1,0)) -> 0
A14: Registro de usuários | B14: senha | C14: =IF(B14="",0,IF(COUNTIF($B$11:B14,B14)=1,1,0)) -> 1 | D14: =IF(A14="",0,IF(COUNTIF($A$11:A14,A14)=1,1,0)) -> 0
A15: Registro de usuários | B15: perfil | C15: =IF(B15="",0,IF(COUNTIF($B$11:B15,B15)=1,1,0)) -> 1 | D15: =IF(A15="",0,IF(COUNTIF($A$11:A15,A15)=1,1,0)) -> 0
A16: Registro de usuários | B16: ativo | C16: =IF(B16="",0,IF(COUNTIF($B$11:B16,B16)=1,1,0)) -> 1 | D16: =IF(A16="",0,IF(COUNTIF($A$11:A16,A16)=1,1,0)) -> 0
C17: =IF(B17="",0,IF(COUNTIF($B$11:B17,B17)=1,1,0)) -> 0 | D17: =IF(A17="",0,IF(COUNTIF($A$11:A17,A17)=1,1,0)) -> 0
C18: =IF(B18="",0,IF(COUNTIF($B$11:B18,B18)=1,1,0)) -> 0 | D18: =IF(A18="",0,IF(COUNTIF($A$11:A18,A18)=1,1,0)) -> 0
C19: =IF(B19="",0,IF(COUNTIF($B$11:B19,B19)=1,1,0)) -> 0 | D19: =IF(A19="",0,IF(COUNTIF($A$11:A19,A19)=1,1,0)) -> 0
C20: =IF(B20="",0,IF(COUNTIF($B$11:B20,B20)=1,1,0)) -> 0 | D20: =IF(A20="",0,IF(COUNTIF($A$11:A20,A20)=1,1,0)) -> 0
C21: =IF(B21="",0,IF(COUNTIF($B$11:B21,B21)=1,1,0)) -> 0 | D21: =IF(A21="",0,IF(COUNTIF($A$11:A21,A21)=1,1,0)) -> 0
C22: =IF(B22="",0,IF(COUNTIF($B$11:B22,B22)=1,1,0)) -> 0 | D22: =IF(A22="",0,IF(COUNTIF($A$11:A22,A22)=1,1,0)) -> 0
C23: =IF(B23="",0,IF(COUNTIF($B$11:B23,B23)=1,1,0)) -> 0 | D23: =IF(A23="",0,IF(COUNTIF($A$11:A23,A23)=1,1,0)) -> 0
C24: =IF(B24="",0,IF(COUNTIF($B$11:B24,B24)=1,1,0)) -> 0 | D24: =IF(A24="",0,IF(COUNTIF($A$11:A24,A24)=1,1,0)) -> 0
C25: =IF(B25="",0,IF(COUNTIF($B$11:B25,B25)=1,1,0)) -> 0 | D25: =IF(A25="",0,IF(COUNTIF($A$11:A25,A25)=1,1,0)) -> 0
C26: =IF(B26="",0,IF(COUNTIF($B$11:B26,B26)=1,1,0)) -> 0 | D26: =IF(A26="",0,IF(COUNTIF($A$11:A26,A26)=1,1,0)) -> 0
C27: =IF(B27="",0,IF(COUNTIF($B$11:B27,B27)=1,1,0)) -> 0 | D27: =IF(A27="",0,IF(COUNTIF($A$11:A27,A27)=1,1,0)) -> 0
C28: =IF(B28="",0,IF(COUNTIF($B$11:B28,B28)=1,1,0)) -> 0 | D28: =IF(A28="",0,IF(COUNTIF($A$11:A28,A28)=1,1,0)) -> 0
... C42: =IF(B42="",0,IF(COUNTIF($B$11:B42,B42)=1,1,0)) -> 0 | D42: =IF(A42="",0,IF(COUNTIF($A$11:A42,A42)=1,1,0)) -> 0
A44: Manutenção do grupo lógico
A45: ALI / AIE | B45: Finalidade da referência | C45: AR entrada CE | D45: AR saída CE
A46: Manutenção | B46: Inclusão, alteração e exclusão conforme as EEs de manutenção; consultar catálogo.
A57: Regra AR / RL | B57: Somar RL distintos, não linhas armazenadas. Campos repetidos contam uma vez.
A59: Contagem calculada — entradas editáveis acima
A60: TD total distinto | B60: =SUM(C11:C42) -> 6 | C60: RL distintos | D60: =SUM(D11:D42) -> 1
A61: TD entrada CE | B61: =0 -> 0 | C61: TD saída sem repetição | D61: =0 -> 0
A62: AR entrada CE | B62: =0 -> 0 | C62: AR saída CE | D62: =0 -> 0
A63: Índice entrada CE | B63: =0 -> 0 | C63: Índice saída CE | D63: =0 -> 0
A64: Índice adotado | B64: =INDEX(Matrizes!$B$5:$D$7,IF(D60<=1,1,IF(D60<=5,2,3)),IF(B60<=19,1,IF(B60<=50,2,3))) -> 1 | C64: Complexidade | D64: =INDEX(Matrizes!$B$10:$D$10,1,B64) -> Simples
A65: Peso apropriado ao tipo | B65: =INDEX(Matrizes!$B$13:$D$17,MATCH("ALI",Matrizes!$A$13:$A$17,0),B64) -> 7 | C65: PF desta função | D65: =B65 -> 7
A67: Justificativa da contagem | B67: Peso por TD/RL da Parte I. Cada grupo entra uma única vez no coletivo.
...

Sheet A07
A1: A07 — Permissões por perfil
A2: Sistema e tipo | B2: Estoque Inteligente — ALI
A3: Intenção / finalidade | B3: Manter Permissões por perfil como grupo lógico reconhecido pelo usuário.
A4: Fronteira e classificação | B4: Grupo persistente mantido pelo estoque; RL é tipo de registro, não quantidade de linhas.
A5: Rota / contexto | B5: /usuarios
A6: Permissões | B6: Administrador ou global, permissão rbac; consulta da matriz exige usuarios e exibição exige rbac.
A7: Evidência atual | B7: model/PermissaoPerfil.java; repository/PermissaoRepository.java; service/PermissaoService.java; templates/usuarios.html
A8: Dados internos / regra | B8: Campos de negócio abaixo. Chaves técnicas, CSRF, versão de sessão e idempotência não são TD funcionais.
A10: Registro lógico | B10: Item de dado (TD) | C10: TD distinto | D10: RL distinto
A11: Registro de permissões por perfil | B11: loja | C11: =IF(B11="",0,IF(COUNTIF($B$11:B11,B11)=1,1,0)) -> 1 | D11: =IF(A11="",0,IF(COUNTIF($A$11:A11,A11)=1,1,0)) -> 1
A12: Registro de permissões por perfil | B12: perfil | C12: =IF(B12="",0,IF(COUNTIF($B$11:B12,B12)=1,1,0)) -> 1 | D12: =IF(A12="",0,IF(COUNTIF($A$11:A12,A12)=1,1,0)) -> 0
A13: Registro de permissões por perfil | B13: permissão | C13: =IF(B13="",0,IF(COUNTIF($B$11:B13,B13)=1,1,0)) -> 1 | D13: =IF(A13="",0,IF(COUNTIF($A$11:A13,A13)=1,1,0)) -> 0
C14: =IF(B14="",0,IF(COUNTIF($B$11:B14,B14)=1,1,0)) -> 0 | D14: =IF(A14="",0,IF(COUNTIF($A$11:A14,A14)=1,1,0)) -> 0
C15: =IF(B15="",0,IF(COUNTIF($B$11:B15,B15)=1,1,0)) -> 0 | D15: =IF(A15="",0,IF(COUNTIF($A$11:A15,A15)=1,1,0)) -> 0
C16: =IF(B16="",0,IF(COUNTIF($B$11:B16,B16)=1,1,0)) -> 0 | D16: =IF(A16="",0,IF(COUNTIF($A$11:A16,A16)=1,1,0)) -> 0
C17: =IF(B17="",0,IF(COUNTIF($B$11:B17,B17)=1,1,0)) -> 0 | D17: =IF(A17="",0,IF(COUNTIF($A$11:A17,A17)=1,1,0)) -> 0
C18: =IF(B18="",0,IF(COUNTIF($B$11:B18,B18)=1,1,0)) -> 0 | D18: =IF(A18="",0,IF(COUNTIF($A$11:A18,A18)=1,1,0)) -> 0
C19: =IF(B19="",0,IF(COUNTIF($B$11:B19,B19)=1,1,0)) -> 0 | D19: =IF(A19="",0,IF(COUNTIF($A$11:A19,A19)=1,1,0)) -> 0
C20: =IF(B20="",0,IF(COUNTIF($B$11:B20,B20)=1,1,0)) -> 0 | D20: =IF(A20="",0,IF(COUNTIF($A$11:A20,A20)=1,1,0)) -> 0
C21: =IF(B21="",0,IF(COUNTIF($B$11:B21,B21)=1,1,0)) -> 0 | D21: =IF(A21="",0,IF(COUNTIF($A$11:A21,A21)=1,1,0)) -> 0
C22: =IF(B22="",0,IF(COUNTIF($B$11:B22,B22)=1,1,0)) -> 0 | D22: =IF(A22="",0,IF(COUNTIF($A$11:A22,A22)=1,1,0)) -> 0
C23: =IF(B23="",0,IF(COUNTIF($B$11:B23,B23)=1,1,0)) -> 0 | D23: =IF(A23="",0,IF(COUNTIF($A$11:A23,A23)=1,1,0)) -> 0
C24: =IF(B24="",0,IF(COUNTIF($B$11:B24,B24)=1,1,0)) -> 0 | D24: =IF(A24="",0,IF(COUNTIF($A$11:A24,A24)=1,1,0)) -> 0
C25: =IF(B25="",0,IF(COUNTIF($B$11:B25,B25)=1,1,0)) -> 0 | D25: =IF(A25="",0,IF(COUNTIF($A$11:A25,A25)=1,1,0)) -> 0
... C42: =IF(B42="",0,IF(COUNTIF($B$11:B42,B42)=1,1,0)) -> 0 | D42: =IF(A42="",0,IF(COUNTIF($A$11:A42,A42)=1,1,0)) -> 0
A44: Manutenção do grupo lógico
A45: ALI / AIE | B45: Finalidade da referência | C45: AR entrada CE | D45: AR saída CE
A46: Manutenção | B46: Inicialização junto da loja; matriz alterada por EE19. Não existe cadastro independente de novos perfis.
A57: Regra AR / RL | B57: Somar RL distintos, não linhas armazenadas. Campos repetidos contam uma vez.
A59: Contagem calculada — entradas editáveis acima
A60: TD total distinto | B60: =SUM(C11:C42) -> 3 | C60: RL distintos | D60: =SUM(D11:D42) -> 1
A61: TD entrada CE | B61: =0 -> 0 | C61: TD saída sem repetição | D61: =0 -> 0
A62: AR entrada CE | B62: =0 -> 0 | C62: AR saída CE | D62: =0 -> 0
A63: Índice entrada CE | B63: =0 -> 0 | C63: Índice saída CE | D63: =0 -> 0
A64: Índice adotado | B64: =INDEX(Matrizes!$B$5:$D$7,IF(D60<=1,1,IF(D60<=5,2,3)),IF(B60<=19,1,IF(B60<=50,2,3))) -> 1 | C64: Complexidade | D64: =INDEX(Matrizes!$B$10:$D$10,1,B64) -> Simples
A65: Peso apropriado ao tipo | B65: =INDEX(Matrizes!$B$13:$D$17,MATCH("ALI",Matrizes!$A$13:$A$17,0),B64) -> 7 | C65: PF desta função | D65: =B65 -> 7
A67: Justificativa da contagem | B67: Peso por TD/RL da Parte I. Cada grupo entra uma única vez no coletivo.
A69: Fluxo da função — leitura do protótipo real
A70: Entrada / contexto | B70: loja; perfil; permissão
A71: Acionamento | B71: Salvar / alterar / excluir quando permitido pelo grupo.
...

Sheet A08
A1: A08 — Lojas e configuração
A2: Sistema e tipo | B2: Estoque Inteligente — ALI
A3: Intenção / finalidade | B3: Manter Lojas e configuração como grupo lógico reconhecido pelo usuário.
A4: Fronteira e classificação | B4: Grupo persistente mantido pelo estoque; RL é tipo de registro, não quantidade de linhas.
A5: Rota / contexto | B5: /global e /iot/configuracao
A6: Permissões | B6: Superadministrador global; configuração IoT exige permissão iot e recurso iot.
A7: Evidência atual | B7: model/Loja.java; repository/LojaRepository.java; service/LojaService.java; service/ConfiguracaoIoTService.java; templates/global.html e iot.html
A8: Dados internos / regra | B8: Campos de negócio abaixo. Chaves técnicas, CSRF, versão de sessão e idempotência não são TD funcionais.
A10: Registro lógico | B10: Item de dado (TD) | C10: TD distinto | D10: RL distinto
A11: Registro de lojas e configuração | B11: código | C11: =IF(B11="",0,IF(COUNTIF($B$11:B11,B11)=1,1,0)) -> 1 | D11: =IF(A11="",0,IF(COUNTIF($A$11:A11,A11)=1,1,0)) -> 1
A12: Registro de lojas e configuração | B12: identificador público | C12: =IF(B12="",0,IF(COUNTIF($B$11:B12,B12)=1,1,0)) -> 1 | D12: =IF(A12="",0,IF(COUNTIF($A$11:A12,A12)=1,1,0)) -> 0
A13: Registro de lojas e configuração | B13: nome | C13: =IF(B13="",0,IF(COUNTIF($B$11:B13,B13)=1,1,0)) -> 1 | D13: =IF(A13="",0,IF(COUNTIF($A$11:A13,A13)=1,1,0)) -> 0
A14: Registro de lojas e configuração | B14: IoT | C14: =IF(B14="",0,IF(COUNTIF($B$11:B14,B14)=1,1,0)) -> 1 | D14: =IF(A14="",0,IF(COUNTIF($A$11:A14,A14)=1,1,0)) -> 0
A15: Registro de lojas e configuração | B15: relatórios | C15: =IF(B15="",0,IF(COUNTIF($B$11:B15,B15)=1,1,0)) -> 1 | D15: =IF(A15="",0,IF(COUNTIF($A$11:A15,A15)=1,1,0)) -> 0
A16: Registro de lojas e configuração | B16: ocupação | C16: =IF(B16="",0,IF(COUNTIF($B$11:B16,B16)=1,1,0)) -> 1 | D16: =IF(A16="",0,IF(COUNTIF($A$11:A16,A16)=1,1,0)) -> 0
A17: Registro de lojas e configuração | B17: fracionados | C17: =IF(B17="",0,IF(COUNTIF($B$11:B17,B17)=1,1,0)) -> 1 | D17: =IF(A17="",0,IF(COUNTIF($A$11:A17,A17)=1,1,0)) -> 0
A18: Registro de lojas e configuração | B18: host MQTT | C18: =IF(B18="",0,IF(COUNTIF($B$11:B18,B18)=1,1,0)) -> 1 | D18: =IF(A18="",0,IF(COUNTIF($A$11:A18,A18)=1,1,0)) -> 0
A19: Registro de lojas e configuração | B19: porta MQTT | C19: =IF(B19="",0,IF(COUNTIF($B$11:B19,B19)=1,1,0)) -> 1 | D19: =IF(A19="",0,IF(COUNTIF($A$11:A19,A19)=1,1,0)) -> 0
A20: Registro de lojas e configuração | B20: QoS | C20: =IF(B20="",0,IF(COUNTIF($B$11:B20,B20)=1,1,0)) -> 1 | D20: =IF(A20="",0,IF(COUNTIF($A$11:A20,A20)=1,1,0)) -> 0
A21: Registro de lojas e configuração | B21: tempo LED | C21: =IF(B21="",0,IF(COUNTIF($B$11:B21,B21)=1,1,0)) -> 1 | D21: =IF(A21="",0,IF(COUNTIF($A$11:A21,A21)=1,1,0)) -> 0
A22: Registro de lojas e configuração | B22: ativo | C22: =IF(B22="",0,IF(COUNTIF($B$11:B22,B22)=1,1,0)) -> 1 | D22: =IF(A22="",0,IF(COUNTIF($A$11:A22,A22)=1,1,0)) -> 0
C23: =IF(B23="",0,IF(COUNTIF($B$11:B23,B23)=1,1,0)) -> 0 | D23: =IF(A23="",0,IF(COUNTIF($A$11:A23,A23)=1,1,0)) -> 0
C24: =IF(B24="",0,IF(COUNTIF($B$11:B24,B24)=1,1,0)) -> 0 | D24: =IF(A24="",0,IF(COUNTIF($A$11:A24,A24)=1,1,0)) -> 0
C25: =IF(B25="",0,IF(COUNTIF($B$11:B25,B25)=1,1,0)) -> 0 | D25: =IF(A25="",0,IF(COUNTIF($A$11:A25,A25)=1,1,0)) -> 0
C26: =IF(B26="",0,IF(COUNTIF($B$11:B26,B26)=1,1,0)) -> 0 | D26: =IF(A26="",0,IF(COUNTIF($A$11:A26,A26)=1,1,0)) -> 0
C27: =IF(B27="",0,IF(COUNTIF($B$11:B27,B27)=1,1,0)) -> 0 | D27: =IF(A27="",0,IF(COUNTIF($A$11:A27,A27)=1,1,0)) -> 0
C28: =IF(B28="",0,IF(COUNTIF($B$11:B28,B28)=1,1,0)) -> 0 | D28: =IF(A28="",0,IF(COUNTIF($A$11:A28,A28)=1,1,0)) -> 0
C29: =IF(B29="",0,IF(COUNTIF($B$11:B29,B29)=1,1,0)) -> 0 | D29: =IF(A29="",0,IF(COUNTIF($A$11:A29,A29)=1,1,0)) -> 0
C30: =IF(B30="",0,IF(COUNTIF($B$11:B30,B30)=1,1,0)) -> 0 | D30: =IF(A30="",0,IF(COUNTIF($A$11:A30,A30)=1,1,0)) -> 0
C31: =IF(B31="",0,IF(COUNTIF($B$11:B31,B31)=1,1,0)) -> 0 | D31: =IF(A31="",0,IF(COUNTIF($A$11:A31,A31)=1,1,0)) -> 0
C32: =IF(B32="",0,IF(COUNTIF($B$11:B32,B32)=1,1,0)) -> 0 | D32: =IF(A32="",0,IF(COUNTIF($A$11:A32,A32)=1,1,0)) -> 0
C33: =IF(B33="",0,IF(COUNTIF($B$11:B33,B33)=1,1,0)) -> 0 | D33: =IF(A33="",0,IF(COUNTIF($A$11:A33,A33)=1,1,0)) -> 0
C34: =IF(B34="",0,IF(COUNTIF($B$11:B34,B34)=1,1,0)) -> 0 | D34: =IF(A34="",0,IF(COUNTIF($A$11:A34,A34)=1,1,0)) -> 0
... C42: =IF(B42="",0,IF(COUNTIF($B$11:B42,B42)=1,1,0)) -> 0 | D42: =IF(A42="",0,IF(COUNTIF($A$11:A42,A42)=1,1,0)) -> 0
A44: Manutenção do grupo lógico
A45: ALI / AIE | B45: Finalidade da referência | C45: AR entrada CE | D45: AR saída CE
A46: Manutenção | B46: Criar, alterar e desativar loja; configuração IoT é parte deste grupo.
A57: Regra AR / RL | B57: Somar RL distintos, não linhas armazenadas. Campos repetidos contam uma vez.
A59: Contagem calculada — entradas editáveis acima
