Workbook

Sheet Capa
A2: ESTOQUE INTELIGENTE
A5: Disciplina | B5: Medição de Software — Análise de Pontos de Função
A8: Integrante | B8: Arthur Ribeiro
A11: Recorte | B11: Catalogo e produtos
A14: Conteúdo | B14: 2 ALIs, 2 AIEs, 2 EEs identificadas, 2 SEs derivadas e 2 CEs; protótipos, dados/arquivos, NI/PFB/FA/PFA, esforço, prazo e custo.
A17: Organização | B17: Documento único em abas. Ordem: contribuição, dados, transações, critérios e estimativas. Todos os protótipos estão incorporados neste arquivo.
A20: Data | B20: 24/10/2026
A23: Autoria a confirmar | B23: O nome e o recorte foram informados pelo grupo. O integrante deve confirmar a descrição de sua contribuição real na identificação das EEs antes de entregar.

Sheet Contribuição
A1: Medição de Software — Arthur Ribeiro
A2: Responsabilidade | B2: Catalogo e produtos. Responsável informado pelo grupo. Contribuição efetivamente realizada na identificação das EEs: confirmar com o integrante antes da entrega; não há atribuição retroativa de autoria.
A4: Item | B4: Função / grupo lógico | C4: Tipo | D4: PF
A5: A01 | B5: Modelos de produto | C5: ALI | D5: ='A01 ALI'!B18 -> 7
A6: A02 | B6: Produtos | C6: ALI | D6: ='A02 ALI'!B24 -> 7
A7: X01 | B7: Fornecedores externos | C7: AIE | D7: ='X01 AIE'!B18 -> 5
A8: X02 | B8: Ofertas externas | C8: AIE | D8: ='X02 AIE'!B22 -> 5
A9: EE04 | B9: Incluir modelo | C9: EE | D9: ='Entradas externas'!B23 -> 4
A10: EE01 | B10: Incluir produto, inclusive grade e saldo inicial | C10: EE | D10: ='Entradas externas'!B91 -> 6
A11: SE06 | B11: Pesquisar estoque e localizar produto | C11: SE | D11: ='SE06 SE'!B38 -> 7
A12: SE02 | B12: Valor potencial do estoque | C12: SE | D12: ='SE02 SE'!B26 -> 5
A13: CE04 | B13: Consultar fornecedores externos | C13: CE | D13: ='CE04 Consulta'!B29 -> 3
A14: CE12 | B14: Consultar ofertas externas | C14: CE | D14: ='CE12 Consulta'!B32 -> 3
A15: PFB individual | D15: =IF(COUNT(D5:D14)=ROWS(D5:D14),SUM(D5:D14),"Dados pendentes") -> 52
A18: NI | B18: ='NI e estimativas'!B3 -> 41
A19: FA | B19: ='NI e estimativas'!B4 -> 1.06
A20: PFA | B20: ='NI e estimativas'!B5 -> 55.12
A21: Esforço (h) | B21: ='NI e estimativas'!B42 -> 551.2
A22: Prazo (dias úteis) | B22: ='NI e estimativas'!B45 -> 92
A23: Custo (R$) | B23: ='NI e estimativas'!B49 -> 13780
A25: Escopo | B25: Recorte acadêmico individual. Arquivos adicionais referenciados entram no AR das transações, mas não são contados novamente como funções de dados atribuídas. Não somar os três recortes como tamanho único do sistema.

Sheet A01 ALI
A1: A01 — Modelos de produto
A2: Sistema | B2: Estoque Inteligente · fronteira da aplicação web
A3: Tipo | B3: ALI — Arquivo Lógico Interno
A4: Justificativa | B4: Dados de negócio mantidos por operações do estoque.
A5: Origem / requisito | B5: models · /modelos
A6: Registros lógicos | B6: Um tipo de registro de negócio, não a quantidade de linhas cadastradas. Identificadores de negócio e contexto da loja seguem a contagem documentada; chaves técnicas de sessão não entram.
A8: Registro lógico | B8: Item de dado referenciado | C8: Tipo | D8: Exemplo / observação
A9: Registro de modelos de produto | B9: loja | C9: Texto / identificação | D9: Loja autenticada (contexto)
A10: Registro de modelos de produto | B10: código | C10: Texto / identificação | D10: 1 (identificação)
A11: Registro de modelos de produto | B11: nome | C11: Texto / identificação | D11: Modelo Aurora
A12: Registro de modelos de produto | B12: marca | C12: Texto / identificação | D12: Aurora
A13: Registro de modelos de produto | B13: categoria | C13: Texto / identificação | D13: Calçados
A15: Contagem | B15: Registros lógicos (RL) | C15: =ROUND(SUMPRODUCT((A9:A13<>"")/COUNTIF(A9:A13,A9:A13&"")),0) -> 1
A16: Contagem | B16: Itens de dados (TD/DER) | C16: =COUNTA(B9:B13) -> 5
A17: Complexidade | B17: =IF(OR(NOT(ISNUMBER(C15)),NOT(ISNUMBER(C16)),C15<=0,C16<=0),"Dados pendentes",IF(C16<=19,IF(C15<=5,"Simples","Moderado"),IF(C16<=50,IF(C15=1,"Simples",IF(C15<=5,"Moderado","Complexo")),IF(C15=1,"Moderado","Complexo")))) -> Simples
A18: Tamanho (PF) | B18: =IF(B17="Simples",7,IF(B17="Moderado",10,IF(B17="Complexo",15,"Dados pendentes"))) -> 7
A20: Protótipo | B20: /modelos · campos de loja/identificação podem ser contexto ou somente leitura; senha não é exibida em consultas. Em vínculo, quantidade começa em zero e muda por movimentação.

Sheet A02 ALI
A1: A02 — Produtos
A2: Sistema | B2: Estoque Inteligente · fronteira da aplicação web
A3: Tipo | B3: ALI — Arquivo Lógico Interno
A4: Justificativa | B4: Dados de negócio mantidos por operações do estoque.
A5: Origem / requisito | B5: products · /produtos
A6: Registros lógicos | B6: Um tipo de registro de negócio, não a quantidade de linhas cadastradas. Identificadores de negócio e contexto da loja seguem a contagem documentada; chaves técnicas de sessão não entram.
A8: Registro lógico | B8: Item de dado referenciado | C8: Tipo | D8: Exemplo / observação
A9: Registro de produtos | B9: loja | C9: Texto / identificação | D9: Loja autenticada (contexto)
A10: Registro de produtos | B10: código | C10: Texto / identificação | D10: 1 (identificação)
A11: Registro de produtos | B11: modelo | C11: Texto / identificação | D11: Modelo Aurora
A12: Registro de produtos | B12: SKU | C12: Texto / identificação | D12: CALCADOS-2
A13: Registro de produtos | B13: código de barras | C13: Texto / identificação | D13: 789000000001
A14: Registro de produtos | B14: cor | C14: Texto / identificação | D14: Preto
A15: Registro de produtos | B15: tamanho | C15: Texto / identificação | D15: 39
A16: Registro de produtos | B16: unidade | C16: Texto / identificação | D16: un
A17: Registro de produtos | B17: preço | C17: Decimal | D17: 249,90
A18: Registro de produtos | B18: características | C18: Texto / identificação | D18: Material: tecido
A19: Registro de produtos | B19: ativo | C19: Boolean | D19: Sim
A21: Contagem | B21: Registros lógicos (RL) | C21: =ROUND(SUMPRODUCT((A9:A19<>"")/COUNTIF(A9:A19,A9:A19&"")),0) -> 1
A22: Contagem | B22: Itens de dados (TD/DER) | C22: =COUNTA(B9:B19) -> 11
A23: Complexidade | B23: =IF(OR(NOT(ISNUMBER(C21)),NOT(ISNUMBER(C22)),C21<=0,C22<=0),"Dados pendentes",IF(C22<=19,IF(C21<=5,"Simples","Moderado"),IF(C22<=50,IF(C21=1,"Simples",IF(C21<=5,"Moderado","Complexo")),IF(C21=1,"Moderado","Complexo")))) -> Simples
A24: Tamanho (PF) | B24: =IF(B23="Simples",7,IF(B23="Moderado",10,IF(B23="Complexo",15,"Dados pendentes"))) -> 7
A26: Protótipo | B26: /produtos · campos de loja/identificação podem ser contexto ou somente leitura; senha não é exibida em consultas. Em vínculo, quantidade começa em zero e muda por movimentação.

Sheet X01 AIE
A1: X01 — Fornecedores externos
A2: Sistema | B2: Estoque Inteligente · fronteira da aplicação web
A3: Tipo | B3: AIE — Arquivo de Interface Externa
A4: Justificativa | B4: Dados mantidos por aplicação externa independente; o estoque apenas consulta. X01 identifica fornecedores; X02 registra ofertas comerciais.
A5: Origem / requisito | B5: external/fornecedores · /fornecedores
A6: Registros lógicos | B6: Um tipo de registro de negócio, não a quantidade de linhas cadastradas. Identificadores de negócio e contexto da loja seguem a contagem documentada; chaves técnicas de sessão não entram.
A8: Registro lógico | B8: Item de dado referenciado | C8: Tipo | D8: Exemplo / observação
A9: Registro de fornecedores externos | B9: código | C9: Texto / identificação | D9: 1 (identificação)
A10: Registro de fornecedores externos | B10: nome | C10: Texto / identificação | D10: Modelo Aurora
A11: Registro de fornecedores externos | B11: documento | C11: Texto / identificação | D11: DEMO-001
A12: Registro de fornecedores externos | B12: e-mail | C12: Texto / identificação | D12: contato@example.org
A13: Registro de fornecedores externos | B13: telefone | C13: Texto / identificação | D13: 41-0000-0001
A15: Contagem | B15: Registros lógicos (RL) | C15: =ROUND(SUMPRODUCT((A9:A13<>"")/COUNTIF(A9:A13,A9:A13&"")),0) -> 1
A16: Contagem | B16: Itens de dados (TD/DER) | C16: =COUNTA(B9:B13) -> 5
A17: Complexidade | B17: =IF(OR(NOT(ISNUMBER(C15)),NOT(ISNUMBER(C16)),C15<=0,C16<=0),"Dados pendentes",IF(C16<=19,IF(C15<=5,"Simples","Moderado"),IF(C16<=50,IF(C15=1,"Simples",IF(C15<=5,"Moderado","Complexo")),IF(C15=1,"Moderado","Complexo")))) -> Simples
A18: Tamanho (PF) | B18: =IF(B17="Simples",5,IF(B17="Moderado",7,IF(B17="Complexo",10,"Dados pendentes"))) -> 5
A20: Protótipo | B20: /fornecedores · campos de loja/identificação podem ser contexto ou somente leitura; senha não é exibida em consultas. Em vínculo, quantidade começa em zero e muda por movimentação.

Sheet X02 AIE
A1: X02 — Ofertas externas
A2: Sistema | B2: Estoque Inteligente · fronteira da aplicação web
A3: Tipo | B3: AIE — Arquivo de Interface Externa
A4: Justificativa | B4: Dados mantidos por aplicação externa independente; o estoque apenas consulta. X01 identifica fornecedores; X02 registra ofertas comerciais.
A5: Origem / requisito | B5: external/ofertas · /ofertas
A6: Registros lógicos | B6: Um tipo de registro de negócio, não a quantidade de linhas cadastradas. Identificadores de negócio e contexto da loja seguem a contagem documentada; chaves técnicas de sessão não entram.
A8: Registro lógico | B8: Item de dado referenciado | C8: Tipo | D8: Exemplo / observação
A9: Oferta comercial externa | B9: GTIN | C9: Texto / identificação | D9: 789000000001
A10: Oferta comercial externa | B10: código do fornecedor | C10: Texto / identificação | D10: F001
A11: Oferta comercial externa | B11: SKU externo | C11: Texto / identificação | D11: EXT-001
A12: Oferta comercial externa | B12: descrição | C12: Texto / identificação | D12: Produto demonstrativo 1
A13: Oferta comercial externa | B13: marca | C13: Texto / identificação | D13: Aurora
A14: Oferta comercial externa | B14: unidade | C14: Texto / identificação | D14: un
A15: Oferta comercial externa | B15: preço cotado | C15: Decimal | D15: 89,90
A16: Oferta comercial externa | B16: disponibilidade | C16: Decimal | D16: 20
A17: Oferta comercial externa | B17: data de atualização | C17: Texto / identificação | D17: 2026-10-24
A19: Contagem | B19: Registros lógicos (RL) | C19: =ROUND(SUMPRODUCT((A9:A17<>"")/COUNTIF(A9:A17,A9:A17&"")),0) -> 1
A20: Contagem | B20: Itens de dados (TD/DER) | C20: =COUNTA(B9:B17) -> 9
A21: Complexidade | B21: =IF(OR(NOT(ISNUMBER(C19)),NOT(ISNUMBER(C20)),C19<=0,C20<=0),"Dados pendentes",IF(C20<=19,IF(C19<=5,"Simples","Moderado"),IF(C20<=50,IF(C19=1,"Simples",IF(C19<=5,"Moderado","Complexo")),IF(C19=1,"Moderado","Complexo")))) -> Simples
A22: Tamanho (PF) | B22: =IF(B21="Simples",5,IF(B21="Moderado",7,IF(B21="Complexo",10,"Dados pendentes"))) -> 5
A24: Protótipo | B24: /ofertas · campos de loja/identificação podem ser contexto ou somente leitura; senha não é exibida em consultas. Em vínculo, quantidade começa em zero e muda por movimentação.

Sheet Entradas externas
A1: EE04 — Incluir modelo
A2: Tipo e finalidade | B2: EE · Incluir modelo
A3: Evidência | B3: ModeloProdutoService.salvar · /modelos
A4: Arquivos e itens | B4: A01: loja, nome, marca e categoria; identificação do modelo gerada no cadastro. A09: loja, responsável, ação modelo.salvar, detalhe com a identificação do modelo e data gerada. Esses dados de auditoria são mantidos internamente e não são campos extras recebidos pela interface.
A5: Classificação / regra | B5: Entrada mantém ALIs e registra auditoria; validação antes de persistir.
A6: Contagem | B6: Um conjunto de comandos e um campo de feedback. Textos alternativos de sucesso/erro não são campos independentes. Dados repetidos contam uma vez. Sessão, CSRF e chave técnica de idempotência excluídos.
A7: Fluxo e exceções | B7: Sem resultados: mensagem de ausência. Erros de entrada são informados; consultas não alteram dados.
A9: Arquivo / origem | B9: Dado que cruza a fronteira | C9: Uso no processo | D9: DER contado
A10: A01, A09 | B10: nome | C10: Entrada | D10: 1
A11: A01, A09 | B11: marca | C11: Entrada | D11: 1
A12: A01, A09 | B12: categoria | C12: Entrada | D12: 1
A13: Interface | B13: mensagem de resultado | C13: Saída | D13: 1
A14: Interface | B14: acionamento | C14: Controle | D14: 1
A16: Arquivos referenciados | B16: Grupo lógico | C16: Uso
A17: A01 | B17: Modelos de produto | C17: Ver itens referenciados acima
A18: A09 | B18: Auditoria consultável | C18: Ver itens referenciados acima
A20: Contagem | B20: Arquivos referenciados | C20: =COUNTA(A17:A18) -> 2
A21: Contagem | B21: Itens distintos (TD/DER) | C21: =IF(COUNT(D10:D14)<>ROWS(D10:D14),"Dados pendentes",IF(COUNTIF(D10:D14,0)+COUNTIF(D10:D14,1)<>ROWS(D10:D14),"Revisar DER",SUM(D10:D14))) -> 5
A22: Complexidade | B22: =IF(OR(NOT(ISNUMBER(C20)),NOT(ISNUMBER(C21)),C20<=0,C21<=0),"Dados pendentes",IF(C21<=4,IF(C20<=2,"Simples","Moderado"),IF(C21<=15,IF(C20<=1,"Simples",IF(C20=2,"Moderado","Complexo")),IF(C20<=1,"Moderado","Complexo")))) -> Moderado
A23: Tamanho (PF) | B23: =IF(B22="Simples",3,IF(B22="Moderado",4,IF(B22="Complexo",6,"Dados pendentes"))) -> 4
A25: Protótipo | B25: Baixa fidelidade baseada na interface implementada. Exemplos ilustrativos; dados de demonstração não comprovam autoria. /modelos
A54: EE01 — Incluir produto, inclusive grade e saldo inicial
A55: Tipo e finalidade | B55: EE · Incluir produto, inclusive grade e saldo inicial
A56: Evidência | B56: ProdutoService.salvar · /produtos
A57: Arquivos e itens | B57: A01: nome, marca e categoria do modelo. A02: modelo, SKU, código de barras, cor, tamanho, unidade, preço, características e ativo. A03: posição e unidade, na entrada inicial. A04: produto, posição e quantidade inicial. A05: produto, posição, responsável, tipo, variação, saldos anterior/posterior, motivo e data, quando há saldo inicial. A09: loja, responsável, ação, detalhe e data (gerada). Identificações dos registros são geradas pelo banco; leituras/manutenções internas não são TD adicionais da interface.
A58: Classificação / regra | B58: Entrada mantém ALIs e registra auditoria; validação antes de persistir.
A59: Contagem | B59: Um conjunto de comandos e um campo de feedback. Textos alternativos de sucesso/erro não são campos independentes. Dados repetidos contam uma vez. Sessão, CSRF e chave técnica de idempotência excluídos.
A60: Fluxo e exceções | B60: Sem resultados: mensagem de ausência. Erros de entrada são informados; consultas não alteram dados.
A62: Arquivo / origem | B62: Dado que cruza a fronteira | C62: Uso no processo | D62: DER contado
A63: A01, A02, A03, A04, A05, A09 | B63: nome | C63: Entrada | D63: 1
A64: A01, A02, A03, A04, A05, A09 | B64: marca | C64: Entrada | D64: 1
A65: A01, A02, A03, A04, A05, A09 | B65: categoria | C65: Entrada | D65: 1
A66: A01, A02, A03, A04, A05, A09 | B66: SKU | C66: Entrada | D66: 1
A67: A01, A02, A03, A04, A05, A09 | B67: código de barras | C67: Entrada | D67: 1
A68: A01, A02, A03, A04, A05, A09 | B68: cor | C68: Entrada | D68: 1
A69: A01, A02, A03, A04, A05, A09 | B69: tamanho | C69: Entrada | D69: 1
A70: A01, A02, A03, A04, A05, A09 | B70: unidade | C70: Entrada | D70: 1
A71: A01, A02, A03, A04, A05, A09 | B71: preço | C71: Entrada | D71: 1
A72: A01, A02, A03, A04, A05, A09 | B72: características | C72: Entrada | D72: 1
A73: A01, A02, A03, A04, A05, A09 | B73: estrutura | C73: Entrada | D73: 1
...

Sheet SE06 SE
A1: SE06 — Pesquisar estoque e localizar produto
A2: Tipo e finalidade | B2: SE · Pesquisar estoque e localizar produto
A3: Evidência | B3: ProdutoService.pesquisar/buscar; DashboardController; BuscaAssistidaController · / (pesquisa)
A4: Arquivos e itens | B4: A01: nome, marca, categoria; A02: SKU, código de barras, cor, tamanho, unidade, preço, características e ativo; A03: código e setor; A04: produto, posição e quantidade. Loja delimita os registros. Saldo total é soma das quantidades.
A5: Classificação / regra | B5: Soma das posições para obter saldo. Dashboard, busca digitada/voz e lista de produtos reutilizam a mesma intenção; não contar canais novamente.
A6: Contagem | B6: Um conjunto de comandos e um campo de feedback. Textos alternativos de sucesso/erro não são campos independentes. Dados repetidos contam uma vez. Sessão, CSRF e chave técnica de idempotência excluídos.
A7: Fluxo e exceções | B7: Sem resultados: mensagem de ausência. Erros de entrada são informados; consultas não alteram dados.
A9: Arquivo / origem | B9: Dado que cruza a fronteira | C9: Uso no processo | D9: DER contado
A10: A01, A02, A03, A04 | B10: busca | C10: Entrada | D10: 1
A11: A01, A02, A03, A04 | B11: produto selecionado | C11: Entrada | D11: 1
A12: A01, A02, A03, A04 | B12: SKU | C12: Saída | D12: 1
A13: A01, A02, A03, A04 | B13: código de barras | C13: Saída | D13: 1
A14: A01, A02, A03, A04 | B14: nome | C14: Saída | D14: 1
A15: A01, A02, A03, A04 | B15: marca | C15: Saída | D15: 1
A16: A01, A02, A03, A04 | B16: categoria | C16: Saída | D16: 1
A17: A01, A02, A03, A04 | B17: cor | C17: Saída | D17: 1
A18: A01, A02, A03, A04 | B18: tamanho | C18: Saída | D18: 1
A19: A01, A02, A03, A04 | B19: unidade | C19: Saída | D19: 1
A20: A01, A02, A03, A04 | B20: preço | C20: Saída | D20: 1
A21: A01, A02, A03, A04 | B21: características | C21: Saída | D21: 1
... A27: Interface | B27: mensagem de resultado | C27: Controle | D27: 1
A29: Arquivos referenciados | B29: Grupo lógico | C29: Uso
A30: A01 | B30: Modelos de produto | C30: Ver itens referenciados acima
A31: A02 | B31: Produtos | C31: Ver itens referenciados acima
A32: A03 | B32: Posições | C32: Ver itens referenciados acima
A33: A04 | B33: Estoque por posição / vínculos | C33: Ver itens referenciados acima
A35: Contagem | B35: Arquivos referenciados | C35: =COUNTA(A30:A33) -> 4
A36: Contagem | B36: Itens distintos (TD/DER) | C36: =IF(COUNT(D10:D27)<>ROWS(D10:D27),"Dados pendentes",IF(COUNTIF(D10:D27,0)+COUNTIF(D10:D27,1)<>ROWS(D10:D27),"Revisar DER",SUM(D10:D27))) -> 18
A37: Complexidade | B37: =IF(OR(NOT(ISNUMBER(C35)),NOT(ISNUMBER(C36)),C35<=0,C36<=0),"Dados pendentes",IF(C36<=5,IF(C35<=3,"Simples","Moderado"),IF(C36<=19,IF(C35<=1,"Simples",IF(C35<=3,"Moderado","Complexo")),IF(C35<=1,"Moderado","Complexo")))) -> Complexo
A38: Tamanho (PF) | B38: =IF(B37="Simples",4,IF(B37="Moderado",5,IF(B37="Complexo",7,"Dados pendentes"))) -> 7
A40: Protótipo | B40: Baixa fidelidade baseada na interface implementada. Exemplos ilustrativos; dados de demonstração não comprovam autoria. / (pesquisa)

Sheet SE02 SE
A1: SE02 — Valor potencial do estoque
A2: Tipo e finalidade | B2: SE · Valor potencial do estoque
A3: Evidência | B3: AnaliseService.relatorio(valor) · /relatorios?tipo=valor
A4: Arquivos e itens | B4: A02: SKU, unidade, preço, ativo e loja; A04: produto e quantidade. Saldo é soma por produto; valor = saldo × preço; total = soma dos valores arredondados em centavos.
A5: Classificação / regra | B5: Saldo × preço atual, arredondado em centavos por produto; total = soma dos valores. Não é custo nem receita realizada.
A6: Contagem | B6: Um conjunto de comandos e um campo de feedback. Textos alternativos de sucesso/erro não são campos independentes. Dados repetidos contam uma vez. Sessão, CSRF e chave técnica de idempotência excluídos.
A7: Fluxo e exceções | B7: Sem resultados: mensagem de ausência. Erros de entrada são informados; consultas não alteram dados.
A9: Arquivo / origem | B9: Dado que cruza a fronteira | C9: Uso no processo | D9: DER contado
A10: A02, A04 | B10: SKU | C10: Saída | D10: 1
A11: A02, A04 | B11: unidade | C11: Saída | D11: 1
A12: A02, A04 | B12: saldo | C12: Saída | D12: 1
A13: A02, A04 | B13: preço | C13: Saída | D13: 1
A14: A02, A04 | B14: valor por produto | C14: Saída | D14: 1
A15: A02, A04 | B15: total da loja | C15: Saída | D15: 1
A16: Interface | B16: acionamento | C16: Controle | D16: 1
A17: Interface | B17: mensagem de resultado | C17: Controle | D17: 1
A19: Arquivos referenciados | B19: Grupo lógico | C19: Uso
A20: A02 | B20: Produtos | C20: Ver itens referenciados acima
A21: A04 | B21: Estoque por posição / vínculos | C21: Ver itens referenciados acima
A23: Contagem | B23: Arquivos referenciados | C23: =COUNTA(A20:A21) -> 2
A24: Contagem | B24: Itens distintos (TD/DER) | C24: =IF(COUNT(D10:D17)<>ROWS(D10:D17),"Dados pendentes",IF(COUNTIF(D10:D17,0)+COUNTIF(D10:D17,1)<>ROWS(D10:D17),"Revisar DER",SUM(D10:D17))) -> 8
A25: Complexidade | B25: =IF(OR(NOT(ISNUMBER(C23)),NOT(ISNUMBER(C24)),C23<=0,C24<=0),"Dados pendentes",IF(C24<=5,IF(C23<=3,"Simples","Moderado"),IF(C24<=19,IF(C23<=1,"Simples",IF(C23<=3,"Moderado","Complexo")),IF(C23<=1,"Moderado","Complexo")))) -> Moderado
A26: Tamanho (PF) | B26: =IF(B25="Simples",4,IF(B25="Moderado",5,IF(B25="Complexo",7,"Dados pendentes"))) -> 5
A28: Protótipo | B28: Baixa fidelidade baseada na interface implementada. Exemplos ilustrativos; dados de demonstração não comprovam autoria. /relatorios?tipo=valor

Sheet CE04 Consulta
A1: CE04 — Consultar fornecedores externos
A2: Tipo e finalidade | B2: CE · Consultar fornecedores externos
A3: Evidência | B3: GET /fornecedores?q=; AnaliseService.consultar; FornecedorGateway · /fornecedores
A4: Arquivos e itens | B4: X01
A5: Classificação / regra | B5: Entrada e saída são um único processo: recupera dados, sem derivação e sem manutenção de arquivos.
A6: Contagem | B6: Um conjunto de comandos e um campo de feedback. Textos alternativos de sucesso/erro não são campos independentes. Dados repetidos contam uma vez. Sessão, CSRF e chave técnica de idempotência excluídos.
A7: Fluxo e exceções | B7: Sem resultados: mensagem de ausência. Erros de entrada são informados; consultas não alteram dados.
A9: Arquivo / origem | B9: Dado que cruza a fronteira | C9: Uso no processo | D9: DER contado
A10: X01 | B10: filtro código, nome ou documento | C10: Entrada | D10: 1
A11: X01 | B11: código | C11: Saída | D11: 1
A12: X01 | B12: nome | C12: Saída | D12: 1
A13: X01 | B13: documento | C13: Saída | D13: 1
A14: X01 | B14: e-mail | C14: Saída | D14: 1
A15: X01 | B15: telefone | C15: Saída | D15: 1
A16: Interface | B16: acionamento | C16: Controle | D16: 1
A17: Interface | B17: mensagem de resultado | C17: Controle | D17: 1
A19: Arquivos referenciados | B19: Grupo lógico | C19: Uso
A20: X01 | B20: Fornecedores externos | C20: Ver itens referenciados acima
A22: Contagem | B22: Arquivos referenciados | C22: =COUNTA(A20:A20) -> 1
A23: Contagem | B23: Itens distintos (TD/DER) | C23: =IF(COUNT(D10:D17)<>ROWS(D10:D17),"Dados pendentes",IF(COUNTIF(D10:D17,0)+COUNTIF(D10:D17,1)<>ROWS(D10:D17),"Revisar DER",SUM(D10:D17))) -> 8
A24: TD da entrada | C24: =COUNTIF(C10:C17,"Entrada")+COUNTIF(C10:C17,"Entrada e saída")+COUNTIF(C10:C17,"Controle") -> 3
A25: TD da saída sem repetição | C25: =COUNTIF(C10:C17,"Saída") -> 5
A26: Complexidade entrada | B26: =IF(OR(NOT(ISNUMBER(C22)),NOT(ISNUMBER(C24)),C22<=0,C24<=0),"Dados pendentes",IF(C24<=4,IF(C22<=2,"Simples","Moderado"),IF(C24<=15,IF(C22<=1,"Simples",IF(C22=2,"Moderado","Complexo")),IF(C22<=1,"Moderado","Complexo")))) -> Simples
A27: Complexidade saída | B27: =IF(OR(NOT(ISNUMBER(C22)),NOT(ISNUMBER(C25)),C22<=0,C25<=0),"Dados pendentes",IF(C25<=5,IF(C22<=3,"Simples","Moderado"),IF(C25<=19,IF(C22<=1,"Simples",IF(C22<=3,"Moderado","Complexo")),IF(C22<=1,"Moderado","Complexo")))) -> Simples
A28: Maior complexidade | B28: =IF(OR(B26="Complexo",B27="Complexo"),"Complexo",IF(OR(B26="Moderado",B27="Moderado"),"Moderado",IF(AND(B26="Simples",B27="Simples"),"Simples","Dados pendentes"))) -> Simples
A29: Tamanho (PF) | B29: =IF(B28="Simples",3,IF(B28="Moderado",4,IF(B28="Complexo",6,"Dados pendentes"))) -> 3
A31: Protótipo | B31: Baixa fidelidade baseada na interface implementada. Exemplos ilustrativos; dados de demonstração não comprovam autoria. /fornecedores

Sheet CE12 Consulta
A1: CE12 — Consultar ofertas externas
A2: Tipo e finalidade | B2: CE · Consultar ofertas externas
A3: Evidência | B3: GET /ofertas; OfertaService.consultar; OfertaGateway; external/ofertas/Provedor.java · /ofertas
A4: Arquivos e itens | B4: X02: nove campos da oferta. Filtros exatos opcionais combinados por GTIN e código do fornecedor. Não mantém arquivos nem deriva dados.
A5: Classificação / regra | B5: Entrada e saída são um único processo: recupera dados, sem derivação e sem manutenção de arquivos.
A6: Contagem | B6: Um conjunto de comandos e um campo de feedback. Textos alternativos de sucesso/erro não são campos independentes. Dados repetidos contam uma vez. Sessão, CSRF e chave técnica de idempotência excluídos.
A7: Fluxo e exceções | B7: Sem resultados: mensagem de ausência. Erros de entrada são informados; consultas não alteram dados.
A9: Arquivo / origem | B9: Dado que cruza a fronteira | C9: Uso no processo | D9: DER contado
A10: X02 | B10: GTIN | C10: Entrada e saída | D10: 1
A11: X02 | B11: código do fornecedor | C11: Entrada e saída | D11: 1
A12: X02 | B12: SKU externo | C12: Saída | D12: 1
A13: X02 | B13: descrição | C13: Saída | D13: 1
A14: X02 | B14: marca | C14: Saída | D14: 1
A15: X02 | B15: unidade | C15: Saída | D15: 1
A16: X02 | B16: preço cotado | C16: Saída | D16: 1
A17: X02 | B17: disponibilidade | C17: Saída | D17: 1
A18: X02 | B18: data de atualização | C18: Saída | D18: 1
A19: Interface | B19: acionamento | C19: Controle | D19: 1
A20: Interface | B20: mensagem de resultado | C20: Controle | D20: 1
A22: Arquivos referenciados | B22: Grupo lógico | C22: Uso
A23: X02 | B23: Ofertas externas | C23: Ver itens referenciados acima
A25: Contagem | B25: Arquivos referenciados | C25: =COUNTA(A23:A23) -> 1
A26: Contagem | B26: Itens distintos (TD/DER) | C26: =IF(COUNT(D10:D20)<>ROWS(D10:D20),"Dados pendentes",IF(COUNTIF(D10:D20,0)+COUNTIF(D10:D20,1)<>ROWS(D10:D20),"Revisar DER",SUM(D10:D20))) -> 11
A27: TD da entrada | C27: =COUNTIF(C10:C20,"Entrada")+COUNTIF(C10:C20,"Entrada e saída")+COUNTIF(C10:C20,"Controle") -> 4
A28: TD da saída sem repetição | C28: =COUNTIF(C10:C20,"Saída") -> 7
A29: Complexidade entrada | B29: =IF(OR(NOT(ISNUMBER(C25)),NOT(ISNUMBER(C27)),C25<=0,C27<=0),"Dados pendentes",IF(C27<=4,IF(C25<=2,"Simples","Moderado"),IF(C27<=15,IF(C25<=1,"Simples",IF(C25=2,"Moderado","Complexo")),IF(C25<=1,"Moderado","Complexo")))) -> Simples
A30: Complexidade saída | B30: =IF(OR(NOT(ISNUMBER(C25)),NOT(ISNUMBER(C28)),C25<=0,C28<=0),"Dados pendentes",IF(C28<=5,IF(C25<=3,"Simples","Moderado"),IF(C28<=19,IF(C25<=1,"Simples",IF(C25<=3,"Moderado","Complexo")),IF(C25<=1,"Moderado","Complexo")))) -> Simples
A31: Maior complexidade | B31: =IF(OR(B29="Complexo",B30="Complexo"),"Complexo",IF(OR(B29="Moderado",B30="Moderado"),"Moderado",IF(AND(B29="Simples",B30="Simples"),"Simples","Dados pendentes"))) -> Simples
A32: Tamanho (PF) | B32: =IF(B31="Simples",3,IF(B31="Moderado",4,IF(B31="Complexo",6,"Dados pendentes"))) -> 3
A34: Protótipo | B34: Baixa fidelidade baseada na interface implementada. Exemplos ilustrativos; dados de demonstração não comprovam autoria. /ofertas

Sheet Critérios e fontes
A1: Critérios de classificação e estimativa didática
A2: Fronteira | B2: Material do professor Tiago Navarro em docs/pdfs: Parte I (ALI/AIE), Parte II (EE/SE), Parte III (CE), Parte IV (ajuste/estimativas) e Características Gerais do Software.
A3: Convenção de contagem | B3: CE corrigida conforme autorização: avaliar entrada e saída separadamente e escolher a maior complexidade (Parte III, p. 10–12). Matriz abaixo é a da saída; entrada usa a matriz EE.
A4: SE e CE | B4: Os dados recebidos e apresentados são listados por processo. Um mesmo dado de consulta e resultado é contado uma vez. As regras internas de filtro não são entradas adicionais. SE produz dado derivado; CE apenas recupera dados armazenados, sem atualização ou cálculo novo.
A6: ALI - faixas de DER nas colunas
A7: RL / arquivos | B7: 1 a 19 | C7: 20 a 50 | D7: 51 ou mais
A8: 1 RL | B8: Simples | C8: Simples | D8: Moderado
A9: 2 a 5 RL | B9: Simples | C9: Moderado | D9: Complexo
A10: 6 ou mais RL | B10: Moderado | C10: Complexo | D10: Complexo
A11: Pesos em PF | B11: 7 | C11: 10 | D11: 15
A14: AIE - faixas de DER nas colunas
A15: RL / arquivos | B15: 1 a 19 | C15: 20 a 50 | D15: 51 ou mais
A16: 1 RL | B16: Simples | C16: Simples | D16: Moderado
A17: 2 a 5 RL | B17: Simples | C17: Moderado | D17: Complexo
A18: 6 ou mais RL | B18: Moderado | C18: Complexo | D18: Complexo
A19: Pesos em PF | B19: 5 | C19: 7 | D19: 10
A22: EE - faixas de DER nas colunas
A23: RL / arquivos | B23: 1 a 4 | C23: 5 a 15 | D23: 16 ou mais
A24: 0 ou 1 arquivo | B24: Simples | C24: Simples | D24: Moderado
A25: 2 arquivos | B25: Simples | C25: Moderado | D25: Complexo
A26: 3 ou mais arquivos | B26: Moderado | C26: Complexo | D26: Complexo
A27: Pesos em PF | B27: 3 | C27: 4 | D27: 6
A30: SE - faixas de DER nas colunas
A31: RL / arquivos | B31: 1 a 5 | C31: 6 a 19 | D31: 20 ou mais
A32: 0 ou 1 arquivo | B32: Simples | C32: Simples | D32: Moderado
A33: 2 a 3 arquivos | B33: Simples | C33: Moderado | D33: Complexo
A34: 4 ou mais arquivos | B34: Moderado | C34: Complexo | D34: Complexo
A35: Pesos em PF | B35: 4 | C35: 5 | D35: 7
A38: CE - faixas de DER nas colunas
A39: RL / arquivos | B39: 1 a 5 | C39: 6 a 19 | D39: 20 ou mais
A40: 0 ou 1 arquivo | B40: Simples | C40: Simples | D40: Moderado
A41: 2 a 3 arquivos | B41: Simples | C41: Moderado | D41: Complexo
A42: 4 ou mais arquivos | B42: Moderado | C42: Complexo | D42: Complexo
A43: Pesos em PF | B43: 3 | C43: 4 | D43: 6
A45: Ressalva dos slides | B45: Parte IV p. 11: FA = 0,65 + 0,01 × NI, adotado aqui e no modelo. P. 15 traz 0,35 e limites inconsistentes; registra-se a divergência sem alterar a fórmula validada da p. 11.
A46: Estimativas | B46: 10 h/PFA, 1 pessoa, 8 h/dia × 75%, R$25/h, reserva 0 e custos adicionais 0. São premissas didáticas; os slides não fixam essas taxas. Fórmulas do modelo preservadas, com referências ajustadas ao número de dados/funções.
A47: Evidência | B47: Branch entrega-trabalho; 90 testes Java passaram com PostgreSQL/MQTT. Protótipos são ilustrações das funções implementadas, não capturas de produção. Material antigo de reuso não comprova autoria individual.

Sheet NI e estimativas
A2: PFB (PF) | B2: ='Contribuição'!D15 -> 52 | C2: PFB individual: Contribuição!D15. Recorte, não tamanho do sistema.
A3: NI total (0 a 70) | B3: =IF(COUNT(B9:B22)<>ROWS(B9:B22),"Notas pendentes",IF(SUM(COUNTIF(B9:B22,0),COUNTIF(B9:B22,1),COUNTIF(B9:B22,2),COUNTIF(B9:B22,3),COUNTIF(B9:B22,4),COUNTIF(B9:B22,5))<>ROWS(B9:B22),"Notas inválidas",SUM(B9:B22))) -> 41 | C3: Soma das 14 notas de B9:B22; cada nota inteira de 0 a 5.
A4: Fator de ajuste (FA) | B4: =IF(ISNUMBER(B3),0.65+0.01*B3,"Revisar NI") -> 1.06 | C4: FA = 0,65 + 0,01 × NI total. Intervalo possível: 0,65 a 1,35.
A5: PFA (PF ajustados) | B5: =IF(AND(ISNUMBER(B2),ISNUMBER(B4)),B2*B4,"Revisar dados") -> 55.12 | C5: PFA = PFB × FA. O ajuste pode reduzir ou aumentar o tamanho: NI abaixo de 35 produz FA menor que 1.
A7: Características gerais da aplicação: notas propostas e justificativas
A8: Característica | B8: NI (0 a 5) | C8: Justificativa da nota | D8: Enquadramento e referência
A9: Comunicação de dados | B9: 5 | C9: Aplicação on-line com HTTP e MQTT; novo cliente HTTP de fornecedores. Mais de um protocolo. | D9: MqttGateway, controllers e FornecedorGateway
A10: Processamento distribuído | B10: 3 | C10: Envia comandos para processamento no controlador IoT. Retorno de telemetria não demonstra transferência de processamento nas duas direções nem escolha dinâmica de CPU. | D10: IoTService.sinalizar
A11: Desempenho | B11: 1 | C11: Há limites de conexão, paginação e timeouts, mas não foi fornecido SLA crítico nem evidência de análise de desempenho rigorosa. | D11: application.properties, ProdutoRepository
A12: Utilização de equipamento | B12: 2 | C12: Compose define limites de memória e pools; há considerações de recursos e segurança. Não exige CPU exclusiva. | D12: compose.yaml
A13: Volume de transações | B13: 1 | C13: Premissa acadêmica: picos mensais de inventário. Volume real não medido; revisar se houver histórico operacional. | D13: Premissa de estimativa
A14: Entrada on-line | B14: 5 | C14: Mais de 30% dos processos de entrada são interativos: cadastros, movimentos e configurações. | D14: Transações interativas deste recorte e aplicação. Critério de entrada on-line do material da disciplina.
A15: Eficiência do usuário final | B15: 4 | C15: Menus, mouse, paginação, navegação, ajuda contextual e poucas telas; redução de digitação por código de barras, voz e balança. Sem medição formal de eficiência. | D15: templates, speech.js, baixa rápida
A16: Atualização on-line | B16: 4 | C16: Maioria dos ALIs atualizada on-line, com transações, bloqueios e idempotência contra perda/duplicação. Não se assume recuperação de volumes extremos. | D16: EstoqueService, repositories
A17: Processamento complexo | B17: 2 | C17: Dois critérios: auditoria/segurança específica e lógica de negócio de estorno, saldo e permissões. Não se considera matemática extensiva nem reprocessamento batch complexo. | D17: Acesso, EstoqueService, AuditoriaRepository
A18: Reutilização de código | B18: 4 | C18: Biblioteca de regras empacotável, documentada e com consumidor externo. Extensões exigem código; não se atribui customização geral por parâmetros. | D18: docs/reuso/README.md, scripts/empacotar-reuso.ps1
A19: Facilidade de implantação | B19: 2 | C19: Roteiros de execução e migrações preparados. Não há evidência de conversão automatizada de dados legados para justificar 4/5. | D19: README, Flyway, Compose
A20: Facilidade operacional | B20: 2 | C20: Inicialização por scripts com intervenção (1); consultas e relatórios minimizam papel (1). Não se presume backup/recuperação automática. | D20: scripts/demo.ps1, relatórios
... A22: Facilidade de mudanças | B22: 4 | C22: Consulta flexível sobre vários ALIs (2) e controles em tabelas alteráveis on-line com efeito imediato, como permissões/recursos (2). | D22: ProdutoRepository.pesquisar, PermissaoService, LojaService
A26: Premissas editáveis para a estimativa individual
A27: Premissa | B27: Valor | C27: Explicação e alcance | D27: Unidade / origem
A28: Índice de esforço | B28: 10 | C28: Horas por PFA para análise, prototipação, implementação, testes e documentação. Não há histórico medido em PF; substituir a hipótese quando houver dados. Não é o índice de 20 h/UCP dos documentos de casos de uso. | D28: h/PFA. Hipótese didática; não é coeficiente do IFPUG.
A29: Pessoas equivalentes | B29: 1 | C29: Uma pessoa equivalente dedicada ao recorte de Arthur Ribeiro. | D29: pessoa. Premissa de capacidade individual.
A30: Jornada por dia | B30: 8 | C30: Jornada de referência antes de descontar reuniões, pausas e outras atividades. A produtividade efetiva é calculada pela alocação da linha seguinte. | D30: h/dia por pessoa. Hipótese de planejamento.
A31: Alocação produtiva | B31: 0.75 | C31: 8 horas de jornada × 75% = 6 horas produtivas por dia, conforme plano. | D31: proporção de 0 a 1. Hipótese de disponibilidade.
A32: Dias úteis por semana | B32: 5 | C32: Usado para converter o prazo em dias úteis em semanas. Não define data inicial, calendário de feriados ou compromisso de entrega. | D32: dias/semana. Hipótese de calendário.
A33: Valor da hora | B33: 25 | C33: Valor orçamentário adotado para cada hora do esforço incluído. Não é pesquisa de mercado, salário comprovado nem custo efetivamente incorrido. | D33: R$/h. Premissa didática editável.
A34: Reserva de esforço | B34: 0 | C34: Reserva de planejamento igual a zero para reproduzir as premissas do plano individual; não altera a fórmula do modelo. | D34: proporção de 0 a 1. Reserva de planejamento.
A35: Custos adicionais | B35: 0 | C35: Campo para hospedagem, licenças, equipamentos e encargos adicionais documentados. O valor inicial zero indica que nenhum desses desembolsos foi orçado; itens não informados ficam fora da estimativa. | D35: R$. Valor inicial zero; não representa cotação.
A37: Estimativas para desenvolver as funções individuais especificadas
A38: Resultado | B38: Valor calculado | C38: Fórmula de planejamento e interpretação | D38: Unidade
A39: Horas produtivas por pessoa/dia | B39: =IF(AND(ISNUMBER(B30),B30>0,ISNUMBER(B31),B31>0,B31<=1),B30*B31,"Revisar jornada") -> 6 | C39: Jornada × alocação produtiva. | D39: h/pessoa/dia
A40: Esforço base | B40: =IF(AND(ISNUMBER(B5),ISNUMBER(B28),B28>0),B5*B28,"Revisar dados") -> 551.2 | C40: PFA × índice de esforço. Mede trabalho total, sem reserva. | D40: h
A41: Reserva em horas | B41: =IF(AND(ISNUMBER(B40),ISNUMBER(B34),B34>=0,B34<=1),B40*B34,"Revisar reserva") -> 0 | C41: Esforço base × percentual de reserva. Reserva zero é permitida. | D41: h
A42: Esforço total com reserva | B42: =IF(AND(ISNUMBER(B40),ISNUMBER(B41)),SUM(B40:B41),"Revisar dados") -> 551.2 | C42: Esforço base + reserva; base usada no prazo e no custo total. | D42: h
A43: Capacidade diária da equipe | B43: =IF(AND(ISNUMBER(B29),B29>0,ISNUMBER(B39)),B29*B39,"Revisar equipe") -> 6 | C43: Pessoas equivalentes × horas produtivas por pessoa/dia. | D43: h/dia
A44: Prazo calculado | B44: =IF(AND(ISNUMBER(B42),ISNUMBER(B43)),B42/B43,"Revisar dados") -> 91.866667 | C44: Esforço total ÷ capacidade diária. Valor fracionário antes do arredondamento. | D44: dias úteis
A45: Prazo planejado | B45: =IF(ISNUMBER(B44),ROUNDUP(ROUND(B44,10),0),"Revisar dados") -> 92 | C45: Prazo calculado arredondado para o próximo dia útil inteiro. Arredondamento técnico prévio a 10 casas evita um dia extra causado apenas pela representação decimal. | D45: dias úteis
A46: Prazo em semanas | B46: =IF(AND(ISNUMBER(B45),ISNUMBER(B32),B32>0,B32<=7),B45/B32,"Revisar calendário") -> 18.4 | C46: Prazo planejado ÷ dias úteis por semana. Não é duração em dias corridos. | D46: semanas
A47: Custo base de mão de obra | B47: =IF(AND(ISNUMBER(B40),ISNUMBER(B33),B33>=0),B40*B33,"Revisar valor/hora") -> 13780 | C47: Esforço base × valor da hora. | D47: R$
...
