Workbook

Sheet Contribuição
A1: Medição de Software - Gustavo Yuri Ferreira Imoto
A2: Contribuição registrada | B2: Distribuição preservada dos documentos individuais anteriores. A responsabilidade pelas SEs já constava em saidas-externas.pdf; as demais funções foram organizadas por afinidade nos documentos individuais, sem atribuição retroativa de autoria.
A4: Item | B4: Função / grupo lógico | C4: Tipo | D4: PF estimados
A5: ALI-04 | B5: Perfil do pet | C5: ALI | D5: ='ALI-04 Perfil pet'!B30 -> 7
A6: ALI-05 | B6: Favoritos | C6: ALI | D6: ='ALI-05 Favoritos'!B18 -> 7
A7: AIE-03 | B7: Catálogo de raças | C7: AIE | D7: ='AIE-03 Raças'!B19 -> 5
A8: AIE-06 | B8: Histórico de vacinação | C8: AIE | D8: ='AIE-06 Vacinação'!B19 -> 5
A9: EE-07 | B9: Cadastrar perfil do pet | C9: EE | D9: ='EE - Gustavo'!B39 -> 6
A10: EE-08 | B10: Alterar perfil do pet | C10: EE | D10: ='EE - Gustavo'!B81 -> 6
A11: EE-09 | B11: Excluir perfil do pet | C11: EE | D11: ='EE - Gustavo'!B106 -> 4
A12: EE-10 | B12: Registrar interesse pelo pet | C12: EE | D12: ='EE - Gustavo'!B135 -> 6
A13: SE-05 | B13: Indicadores de adoção da ONG | C13: SE | D13: ='SE-05 Saída'!B32 -> 7
A14: SE-06 | B14: Pets mais favoritados | C14: SE | D14: ='SE-06 Saída'!B26 -> 5
A15: CE-05 | B15: Consultar acervo de pets | C15: CE | D15: ='CE-05 Consulta'!B26 -> 3
A16: CE-06 | B16: Consultar favoritos | C16: CE | D16: ='CE-06 Consulta'!B25 -> 4
A17: Total individual estimado | D17: =IF(COUNT(D5:D16)=ROWS(D5:D16),SUM(D5:D16),"Dados pendentes") -> 65
A19: Cálculos de ajuste e estimativa individual
A20: NI total | B20: ='NI e estimativas'!B3 -> 25 | C20: Soma das 14 notas justificadas em NI e estimativas.
A21: Fator de ajuste (FA) | B21: ='NI e estimativas'!B4 -> 0.9 | C21: FA = 0,65 + 0,01 × NI.
A22: PFA individual | B22: ='NI e estimativas'!B5 -> 58.5 | C22: PFB individual × FA.
A23: Esforço com reserva (h) | B23: ='NI e estimativas'!B42 -> 702 | C23: Inclui a reserva de esforço de planejamento.
A24: Prazo planejado (dias úteis) | B24: ='NI e estimativas'!B45 -> 117 | C24: Prazo calculado pela capacidade diária definida nas premissas.
A25: Custo com reserva (R$) | B25: ='NI e estimativas'!B49 -> 35100 | C25: Valor da hora e custos adicionais são premissas editáveis.

Sheet ALI-04 Perfil pet
A1: ALI-04 - Perfil do pet
A2: Sistema | B2: MatchEngine Adote Bem
A3: Tipo | B3: ALI - Arquivo Lógico Interno
A4: Justificativa | B4: A ONG mantém o cadastro e as mídias do animal pelo MatchEngine. Dados e mídias são subgrupos dependentes do mesmo pet e formam um ALI, não dois arquivos.
A5: Requisito relacionado | B5: Manter Perfil do pet
A6: Caso de uso relacionado | B6: Manutenção e consultas do grupo ALI-04; rastreabilidade descritiva, IDs de requisito e caso de uso não informados na fonte.
A8: Registro lógico | B8: Item de dado referenciado | C8: Tipo | D8: Observação / exemplo
A9: Dados do pet | B9: Nome | C9: String | D9: Exemplo fictício: Luna
A10: Dados do pet | B10: Idade | C10: String | D10: Exemplo fictício: 3 anos
A11: Dados do pet | B11: Raça | C11: String | D11: Exemplo fictício: Sem raça definida
A12: Dados do pet | B12: Onde reside | C12: String | D12: Exemplo fictício: Blumenau / SC
A13: Dados do pet | B13: Temperamento | C13: String | D13: Exemplo fictício: Calmo
A14: Dados do pet | B14: Hobby | C14: String | D14: Exemplo fictício: Caminhar
A15: Dados do pet | B15: Sexo | C15: String | D15: Exemplo fictício: Fêmea
A16: Dados do pet | B16: Porte | C16: String | D16: Exemplo fictício: Médio
A17: Dados do pet | B17: Energia | C17: String | D17: Exemplo fictício: Moderada
A18: Dados do pet | B18: Necessidade de atividade | C18: Decimal | D18: Exemplo fictício: 40 min/dia
A19: Dados do pet | B19: Castração | C19: Boolean | D19: Exemplo fictício: Sim
... A25: Dados do pet | B25: Faixa etária | C25: String | D25: Exemplo fictício: Adulto
A27: Contagem para PF | B27: Registros lógicos (RL) | C27: =ROUND(SUMPRODUCT((A9:A25<>"")/COUNTIF(A9:A25,A9:A25&"")),0) -> 2
A28: Contagem para PF | B28: Itens de dados (DER) | C28: =COUNTA(B9:B25) -> 17
A29: Complexidade | B29: =IF(OR(NOT(ISNUMBER(C27)),NOT(ISNUMBER(C28)),C27<=0,C28<=0),"Dados pendentes",IF(C28<=19,IF(C27<=5,"Simples","Moderado"),IF(C28<=50,IF(C27=1,"Simples",IF(C27<=5,"Moderado","Complexo")),IF(C27=1,"Moderado","Complexo")))) -> Simples
A30: Tamanho estimado (PF) | B30: =IF(B29="Simples",7,IF(B29="Moderado",10,IF(B29="Complexo",15,"Dados pendentes"))) -> 7
A32: Origem e complemento | B32: Grupo com dois registros lógicos e campos originais preservado. Espécie, faixa etária, situação, vínculo ONG responsável e detalhamento biológico foram explicitados para matching e indicadores. Onde reside continua sendo a localização, não o vínculo institucional. O item composto Informações biológicas foi desdobrado em cinco itens independentes: Sexo, Porte, Energia, Necessidade de atividade e Castração. O rótulo guarda-chuva não é contado adicionalmente. A decomposição explicita os campos já descritos na especificação; a localização é apresentada separada do vínculo com a ONG. Nesta atualização de 22/10/2026, a imagem foi substituída por captura real da execução local do Laço, com cobertura parcial identificada na legenda. A identificação, os dados e a classificação continuam referentes ao MatchEngine especificado; a captura não comprova implementação integral da função.
A33: Relação com a tela | B33: Na especificação, o ALI-04 reúne os dados e registros lógicos catalogados. A captura real mostra a ficha do animal ou seu CRUD no Laço, com cobertura parcial dos campos. Criar, editar e excluir usam o repositório em memória do cliente; os dados não persistem ao recarregar a página. Campos ausentes continuam propostos na especificação.

Sheet ALI-05 Favoritos
A1: ALI-05 - Favoritos
A2: Sistema | B2: MatchEngine Adote Bem
A3: Tipo | B3: ALI - Arquivo Lógico Interno
A4: Justificativa | B4: A escolha salva é um registro de negócio mantido pelo MatchEngine, com data e observação, independente da apresentação do ranking.
A5: Requisito relacionado | B5: Manter Favoritos
A6: Caso de uso relacionado | B6: Manutenção e consultas do grupo ALI-05; rastreabilidade descritiva, IDs de requisito e caso de uso não informados na fonte.
A8: Registro lógico | B8: Item de dado referenciado | C8: Tipo | D8: Observação / exemplo
A9: Favorito | B9: Adotante | C9: String | D9: Exemplo fictício: ana@example.com
A10: Favorito | B10: Animal favorito | C10: String | D10: Exemplo fictício: Luna
A11: Favorito | B11: Instituição | C11: String | D11: Exemplo fictício: Projeto Patinhas
A12: Favorito | B12: Data em que foi salvo | C12: Date | D12: Exemplo fictício: 14/10/2026
A13: Favorito | B13: Observação | C13: Text | D13: Exemplo fictício: Interesse em conhecer a Luna
A15: Contagem para PF | B15: Registros lógicos (RL) | C15: =ROUND(SUMPRODUCT((A9:A13<>"")/COUNTIF(A9:A13,A9:A13&"")),0) -> 1
A16: Contagem para PF | B16: Itens de dados (DER) | C16: =COUNTA(B9:B13) -> 5
A17: Complexidade | B17: =IF(OR(NOT(ISNUMBER(C15)),NOT(ISNUMBER(C16)),C15<=0,C16<=0),"Dados pendentes",IF(C16<=19,IF(C15<=5,"Simples","Moderado"),IF(C16<=50,IF(C15=1,"Simples",IF(C15<=5,"Moderado","Complexo")),IF(C15=1,"Moderado","Complexo")))) -> Simples
A18: Tamanho estimado (PF) | B18: =IF(B17="Simples",7,IF(B17="Moderado",10,IF(B17="Complexo",15,"Dados pendentes"))) -> 7
A20: Origem e complemento | B20: Grupo e campos existentes. Regra de unicidade adotante-animal explicitada na complementação documental anterior. Nesta atualização de 22/10/2026, a imagem foi substituída por captura real da execução local do Laço, com cobertura parcial identificada na legenda. A identificação, os dados e a classificação continuam referentes ao MatchEngine especificado; a captura não comprova implementação integral da função.
A21: Relação com a tela | B21: Na especificação, o ALI-05 reúne favoritos com os dados catalogados. A captura real mostra animais curtidos e matches mantidos no estado da sessão do Laço. Não há persistência do arquivo completo nem os campos de data e observação do favorito especificado; a evidência é parcial.

Sheet AIE-03 Raças
A1: AIE-03 - Catálogo de raças
A2: Sistema | B2: MatchEngine Adote Bem
A3: Tipo | B3: AIE - Arquivo de Interface Externa
A4: Justificativa | B4: Os dados de referência sobre raças pertencem a um catálogo administrado por outra aplicação. O MatchEngine apenas os consulta para orientar o preenchimento, sem manter o catálogo.
A5: Requisito relacionado | B5: Consultar Catálogo de raças em fonte externa proposta
A6: Caso de uso relacionado | B6: Consulta à referência AIE-03; rastreabilidade descritiva, IDs de requisito e caso de uso não informados na fonte.
A7: Sistema externo | B7: Aplicação externa de referência de raças; integração proposta.
A9: Registro lógico | B9: Item de dado referenciado | C9: Tipo | D9: Observação / exemplo
A10: Raça | B10: Espécie | C10: String | D10: Exemplo fictício: Cão
A11: Raça | B11: Raça selecionada | C11: String | D11: Exemplo fictício: Labrador
A12: Raça | B12: Porte típico | C12: String | D12: Exemplo fictício: Grande
A13: Raça | B13: Nível de energia | C13: String | D13: Exemplo fictício: Alto
A14: Raça | B14: Necessidade de atividade | C14: Decimal | D14: Exemplo fictício: 60 min/dia
A16: Contagem para PF | B16: Registros lógicos (RL) | C16: =ROUND(SUMPRODUCT((A10:A14<>"")/COUNTIF(A10:A14,A10:A14&"")),0) -> 1
A17: Contagem para PF | B17: Itens de dados (DER) | C17: =COUNTA(B10:B14) -> 5
A18: Complexidade | B18: =IF(OR(NOT(ISNUMBER(C16)),NOT(ISNUMBER(C17)),C16<=0,C17<=0),"Dados pendentes",IF(C17<=19,IF(C16<=5,"Simples","Moderado"),IF(C17<=50,IF(C16=1,"Simples",IF(C16<=5,"Moderado","Complexo")),IF(C16=1,"Moderado","Complexo")))) -> Simples
A19: Tamanho estimado (PF) | B19: =IF(B18="Simples",5,IF(B18="Moderado",7,IF(B18="Complexo",10,"Dados pendentes"))) -> 5
A21: Origem e complemento | B21: Grupo e campos existentes; integração permanece proposta. Nesta atualização de 22/10/2026, a imagem foi substituída por captura real da execução local do Laço, com cobertura parcial identificada na legenda. A identificação, os dados e a classificação continuam referentes ao MatchEngine especificado; a captura não comprova implementação integral da função.
A22: Relação com a tela | B22: O AIE-03 é um catálogo externo proposto na especificação. No Laço executado, a raça é informada como texto livre no formulário do animal; não existe consulta ao catálogo nem integração externa de raças. A captura real não comprova leitura dos registros do AIE-03.

Sheet AIE-06 Vacinação
A1: AIE-06 - Histórico de vacinação
A2: Sistema | B2: MatchEngine Adote Bem
A3: Tipo | B3: AIE - Arquivo de Interface Externa
A4: Justificativa | B4: O histórico é mantido no sistema da clínica parceira, fora da fronteira adotada. O MatchEngine apenas consulta esse histórico; este AIE não é o prontuário local do módulo veterinário Laço.
A5: Requisito relacionado | B5: Consultar Histórico de vacinação em fonte externa proposta
A6: Caso de uso relacionado | B6: Consulta à referência AIE-06; rastreabilidade descritiva, IDs de requisito e caso de uso não informados na fonte.
A7: Sistema externo | B7: Sistema externo da clínica parceira; integração proposta.
A9: Registro lógico | B9: Item de dado referenciado | C9: Tipo | D9: Observação / exemplo
A10: Registro de vacinação | B10: Animal | C10: String | D10: Exemplo fictício: Luna
A11: Registro de vacinação | B11: Vacina | C11: String | D11: Exemplo fictício: Antirrábica
A12: Registro de vacinação | B12: Última dose | C12: Date | D12: Exemplo fictício: 01/09/2026
A13: Registro de vacinação | B13: Próxima dose | C13: Date | D13: Exemplo fictício: 01/09/2027
A14: Registro de vacinação | B14: Clínica responsável | C14: String | D14: Exemplo fictício: Clínica Parceira Exemplo
A16: Contagem para PF | B16: Registros lógicos (RL) | C16: =ROUND(SUMPRODUCT((A10:A14<>"")/COUNTIF(A10:A14,A10:A14&"")),0) -> 1
A17: Contagem para PF | B17: Itens de dados (DER) | C17: =COUNTA(B10:B14) -> 5
A18: Complexidade | B18: =IF(OR(NOT(ISNUMBER(C16)),NOT(ISNUMBER(C17)),C16<=0,C17<=0),"Dados pendentes",IF(C17<=19,IF(C16<=5,"Simples","Moderado"),IF(C17<=50,IF(C16=1,"Simples",IF(C16<=5,"Moderado","Complexo")),IF(C16=1,"Moderado","Complexo")))) -> Simples
A19: Tamanho estimado (PF) | B19: =IF(B18="Simples",5,IF(B18="Moderado",7,IF(B18="Complexo",10,"Dados pendentes"))) -> 5
A21: Origem e complemento | B21: Grupo e campos existentes. A próxima dose é recuperada da fonte, não calculada nesta consulta. Nesta atualização de 22/10/2026, a imagem foi substituída por captura real da execução local do Laço, com cobertura parcial identificada na legenda. A identificação, os dados e a classificação continuam referentes ao MatchEngine especificado; a captura não comprova implementação integral da função.
A22: Relação com a tela | B22: O AIE-06 é um histórico externo proposto na especificação. A captura real mostra vacinação no prontuário clínico demonstrativo do Laço, com dados locais do animal. Não existe integração com um histórico externo nem recuperação da próxima dose da fonte especificada. A contagem do AIE permanece referente ao escopo documental.

Sheet EE - Gustavo
A1: EE-07 - Cadastrar perfil do pet
A2: Tipo e finalidade | B2: EE - A ONG informa os dados do novo pet: nome, idade, espécie, raça, onde reside, temperamento, hobby, sexo, porte, energia, necessidade de atividade em minutos por dia, castração, mídia principal, outras mídias, faixa etária, situação do pet e ONG responsável. O vínculo institucional vem do contexto da ONG autorizada. A situação inicial é Disponível.
A3: Origem e complemento | B3: Processo preservado da identificação preliminar de EEs. Nesta adaptação, os dados mantidos e os dados distintos que atravessam a fronteira são explicitados, incluindo o detalhamento biológico. Nesta atualização de 22/10/2026, a imagem foi substituída por captura real da execução local do Laço, com cobertura parcial identificada na legenda. A identificação, os dados e a classificação continuam referentes ao MatchEngine especificado; a captura não comprova implementação integral da função.
A4: Arquivos e itens | B4: Mantém os dados informados nos registros Dados do pet e Mídias do pet do ALI-04 Perfil do pet. Lê Nome da ONG no ALI-03 Perfil da ONG para validar a associação institucional. O AIE-03 Catálogo de raças pode fornecer Espécie, Raça selecionada, Porte típico, Nível de energia e Necessidade de atividade como referência, por integração proposta; o processo não altera essa base externa. ONG responsável e Onde reside são informações distintas.
A5: Resultado e classificação | B5: Valida os dados e inclui um pet associado à instituição. É EE porque informações entram pela fronteira para manter um ALI; consultar o catálogo não mantém a fonte externa.
A6: Campos complementados | B6: Espécie, Faixa etária, Situação do pet, ONG responsável e o detalhamento de Sexo, Porte, Energia, Necessidade de atividade e Castração são complementos identificados no catálogo consolidado. A identificação usada para selecionar um pet na alteração é uma referência da operação, não um novo atributo proposto para o ALI-04. Cada dado de negócio é listado uma vez; comandos e mensagens ficam separados.
A7: Arquivos referenciados | B7: ALI-04 Perfil do pet; ALI-03 Perfil da ONG; AIE-03 Catálogo de raças
A9: Arquivo / origem | B9: Dado que cruza a fronteira | C9: Uso no processo | D9: DER contado
A10: ALI-04 | B10: Nome | C10: Entrada / retorno | D10: 1
A11: ALI-04 | B11: Idade | C11: Entrada / retorno | D11: 1
A12: ALI-04 / AIE-03 | B12: Espécie | C12: Entrada / retorno | D12: 1
A13: ALI-04 | B13: Raça | C13: Entrada / retorno | D13: 1
A14: ALI-04 | B14: Onde reside | C14: Entrada / retorno | D14: 1
A15: ALI-04 | B15: Temperamento | C15: Entrada / retorno | D15: 1
A16: ALI-04 | B16: Hobby | C16: Entrada / retorno | D16: 1
A17: ALI-04 | B17: Sexo | C17: Entrada / retorno | D17: 1
A18: ALI-04 | B18: Porte | C18: Entrada / retorno | D18: 1
A19: ALI-04 | B19: Energia | C19: Entrada / retorno | D19: 1
A20: ALI-04 / AIE-03 | B20: Necessidade de atividade | C20: Entrada / retorno | D20: 1
A21: ALI-04 | B21: Castração | C21: Entrada / retorno | D21: 1
... A29: Interface / processamento | B29: Revise os campos obrigatórios ou os valores inválidos. | C29: Consistência / resposta | D29: 1
A31: Arquivos referenciados | B31: Nome do grupo lógico | C31: Uso
A32: ALI-04 | B32: Perfil do pet | C32: Ver finalidade e dados descritos
A33: ALI-03 | B33: Perfil da ONG | C33: Ver finalidade e dados descritos
A34: AIE-03 | B34: Catálogo de raças | C34: Ver finalidade e dados descritos
A36: Contagem para PF | B36: Arquivos referenciados | C36: =COUNTA(A32:A34) -> 3
A37: Contagem para PF | B37: Itens de dados (DER) | C37: =IF(COUNT(D10:D29)<>ROWS(D10:D29),"Dados pendentes",IF(COUNTIF(D10:D29,0)+COUNTIF(D10:D29,1)<>ROWS(D10:D29),"Revisar DER",SUM(D10:D29))) -> 20
A38: Complexidade | B38: =IF(OR(NOT(ISNUMBER(C36)),NOT(ISNUMBER(C37)),C36<=0,C37<=0),"Dados pendentes",IF(C37<=4,IF(C36<=2,"Simples","Moderado"),IF(C37<=15,IF(C36<=1,"Simples",IF(C36=2,"Moderado","Complexo")),IF(C36<=1,"Moderado","Complexo")))) -> Complexo
A39: Tamanho estimado (PF) | B39: =IF(B38="Simples",3,IF(B38="Moderado",4,IF(B38="Complexo",6,"Dados pendentes"))) -> 6
A42: EE-08 - Alterar perfil do pet
A43: Tipo e finalidade | B43: EE - A ONG seleciona um pet existente e informa os novos valores: nome, idade, espécie, raça, onde reside, temperamento, hobby, sexo, porte, energia, necessidade de atividade em minutos por dia, castração, mídia principal, outras mídias, faixa etária, situação do pet e ONG responsável. O vínculo institucional vem do contexto da ONG autorizada. A situação assume Disponível, Em processo ou Adotado.
A44: Origem e complemento | B44: Processo preservado da identificação preliminar de EEs. Nesta adaptação, os dados mantidos e os dados distintos que atravessam a fronteira são explicitados, incluindo o detalhamento biológico. Nesta atualização de 22/10/2026, a imagem foi substituída por captura real da execução local do Laço, com cobertura parcial identificada na legenda. A identificação, os dados e a classificação continuam referentes ao MatchEngine especificado; a captura não comprova implementação integral da função.
A45: Arquivos e itens | B45: Mantém os dados informados nos registros Dados do pet e Mídias do pet do ALI-04 Perfil do pet. Lê Nome da ONG no ALI-03 Perfil da ONG para validar a associação institucional. O AIE-03 Catálogo de raças pode fornecer Espécie, Raça selecionada, Porte típico, Nível de energia e Necessidade de atividade como referência, por integração proposta; o processo não altera essa base externa. ONG responsável e Onde reside são informações distintas.
A46: Resultado e classificação | B46: Valida e grava as alterações do pet selecionado. É EE de alteração: mantém cadastro existente, com finalidade distinta da inclusão. A confirmação visual integra o processo e não constitui uma SE independente.
A47: Campos complementados | B47: Espécie, Faixa etária, Situação do pet, ONG responsável e o detalhamento de Sexo, Porte, Energia, Necessidade de atividade e Castração são complementos identificados no catálogo consolidado. A identificação usada para selecionar um pet na alteração é uma referência da operação, não um novo atributo proposto para o ALI-04. Cada dado de negócio é listado uma vez; comandos e mensagens ficam separados.
A48: Arquivos referenciados | B48: ALI-04 Perfil do pet; ALI-03 Perfil da ONG; AIE-03 Catálogo de raças
A50: Arquivo / origem | B50: Dado que cruza a fronteira | C50: Uso no processo | D50: DER contado
A51: ALI-04 / ALI-03 / AIE-03 | B51: Identificação do pet selecionado | C51: Entrada / retorno | D51: 1
A52: ALI-04 | B52: Nome | C52: Entrada / retorno | D52: 1
A53: ALI-04 | B53: Idade | C53: Entrada / retorno | D53: 1
...

Sheet SE-05 Saída
A1: SE-05 - Indicadores de adoção da ONG
A2: Tipo e finalidade | B2: SE - A ONG informa instituição e período para acompanhar o estoque atual de animais e o fluxo de adoção no intervalo. A saída apresenta nome da ONG, período, pets disponíveis, matches positivos, solicitações enviadas, adoções concluídas e conversão.
A3: Origem e complemento | B3: SE preservada do material anterior de saídas externas, com atribuição a Gustavo Yuri. Fórmulas, vínculos, recortes temporais, tratamento de vazios e ilustração foram explicitados nesta adaptação. Nesta atualização de 22/10/2026, a imagem foi substituída por captura real da execução local do Laço, com cobertura parcial identificada na legenda. A identificação, os dados e a classificação continuam referentes ao MatchEngine especificado; a captura não comprova implementação integral da função.
A4: ALIs e itens referenciados | B4: Lê Nome da ONG no ALI-03 Perfil da ONG; Nome, ONG responsável e Situação do pet no ALI-04 Perfil do pet; Animal, Status e Data do match no ALI-06 Matches; ONG vinculada, Situação da solicitação, Data/hora de envio e Data/hora de conclusão no ALI-08 Solicitação de adoção. Para vincular cada match à ONG, resolve Animal para o pet e sua ONG responsável no ALI-04. Onde reside descreve a localização e não substitui esse vínculo.
A5: Dados derivados e exemplo | B5: Conta os pets da ONG com Situação do pet Disponível na emissão (estoque atual). Dentro do intervalo informado, conta registros de Matches pela Data do match, excluindo Status Recusado; conta solicitações pela Data/hora de envio; e conta solicitações com Situação da solicitação Concluída pela Data/hora de conclusão. Os limites são inclusivos e, no último dia, não ultrapassam a emissão. Conversão do fluxo = 100 × concluídas no período ÷ enviadas no período. Exemplo Projeto Patinhas: de 01/10/2026 00:00 até 14/10/2026 10:00, emissão no mesmo instante final, disponíveis atuais 3, matches positivos 6, enviadas 10 e concluídas 1; conversão = 10%.
A6: Interpretação e classificação | B6: A conversão compara fluxos do período, sem afirmar que a conclusão veio dos mesmos envios. O estoque atual é separado desses fluxos. Contagens vazias valem zero; sem envios, conversão não aplicável. É SE porque agrega registros e calcula percentual, em vez de apenas recuperar dados.
A7: Arquivos referenciados | B7: ALI-03 Perfil da ONG; ALI-04 Perfil do pet; ALI-06 Matches; ALI-08 Solicitação de adoção
A9: Arquivo / origem | B9: Dado que cruza a fronteira | C9: Uso no processo | D9: DER contado
A10: ALI-03 | B10: Nome da ONG | C10: Entrada e saída | D10: 1
A11: ALI-03 / ALI-04 / ALI-06 / ALI-08 | B11: Data inicial | C11: Critério recebido | D11: 1
A12: ALI-03 / ALI-04 / ALI-06 / ALI-08 | B12: Data final | C12: Critério recebido | D12: 1
A13: ALI-03 / ALI-04 / ALI-06 / ALI-08 | B13: Período do fluxo | C13: Datas já contadas | D13: 0
A14: ALI-03 / ALI-04 / ALI-06 / ALI-08 | B14: Data/hora de emissão | C14: Saída da SE | D14: 1
A15: ALI-03 / ALI-04 / ALI-06 / ALI-08 | B15: Pets disponíveis atuais | C15: Saída da SE | D15: 1
A16: ALI-03 / ALI-04 / ALI-06 / ALI-08 | B16: Matches positivos gerados no período | C16: Saída da SE | D16: 1
A17: ALI-03 / ALI-04 / ALI-06 / ALI-08 | B17: Solicitações enviadas no período | C17: Saída da SE | D17: 1
A18: ALI-03 / ALI-04 / ALI-06 / ALI-08 | B18: Adoções concluídas no período | C18: Saída da SE | D18: 1
A19: ALI-03 / ALI-04 / ALI-06 / ALI-08 | B19: Conversão do fluxo | C19: Saída da SE | D19: 1
A20: Interface / processamento | B20: Conjunto de ações de emissão | C20: Comando | D20: 1
A21: Interface / processamento | B21: Mensagem de validação / ausência de resultado | C21: Resposta | D21: 1
A23: Arquivos referenciados | B23: Nome do grupo lógico | C23: Uso
A24: ALI-03 | B24: Perfil da ONG | C24: Ver finalidade e dados descritos
A25: ALI-04 | B25: Perfil do pet | C25: Ver finalidade e dados descritos
A26: ALI-06 | B26: Matches | C26: Ver finalidade e dados descritos
A27: ALI-08 | B27: Solicitação de adoção | C27: Ver finalidade e dados descritos
A29: Contagem para PF | B29: Arquivos referenciados | C29: =COUNTA(A24:A27) -> 4
A30: Contagem para PF | B30: Itens de dados (DER) | C30: =IF(COUNT(D10:D21)<>ROWS(D10:D21),"Dados pendentes",IF(COUNTIF(D10:D21,0)+COUNTIF(D10:D21,1)<>ROWS(D10:D21),"Revisar DER",SUM(D10:D21))) -> 11
A31: Complexidade | B31: =IF(OR(NOT(ISNUMBER(C29)),NOT(ISNUMBER(C30)),C29<=0,C30<=0),"Dados pendentes",IF(C30<=5,IF(C29<=3,"Simples","Moderado"),IF(C30<=19,IF(C29<=1,"Simples",IF(C29<=3,"Moderado","Complexo")),IF(C29<=1,"Moderado","Complexo")))) -> Complexo
A32: Tamanho estimado (PF) | B32: =IF(B31="Simples",4,IF(B31="Moderado",5,IF(B31="Complexo",7,"Dados pendentes"))) -> 7

Sheet SE-06 Saída
A1: SE-06 - Pets mais favoritados
A2: Tipo e finalidade | B2: SE - A ONG solicita o ranking de seus pets pelos favoritos registrados. A saída apresenta posição, nome, raça, quantidade de favoritos e data do favorito mais recente, permitindo observar o interesse recebido por cada animal.
A3: Origem e complemento | B3: SE preservada do material anterior de saídas externas, com atribuição a Gustavo Yuri. Agrupamento, contagem de pares únicos, data máxima, desempate e ilustração foram explicitados nesta adaptação. Nesta atualização de 22/10/2026, a imagem foi substituída por captura real da execução local do Laço, com cobertura parcial identificada na legenda. A identificação, os dados e a classificação continuam referentes ao MatchEngine especificado; a captura não comprova implementação integral da função.
A4: ALIs e itens referenciados | B4: Lê Adotante, Animal favorito, Instituição e Data em que foi salvo no ALI-05 Favoritos; lê Nome e Raça no ALI-04 Perfil do pet. Instituição delimita os favoritos. Posição, Quantidade de favoritos únicos e Data do favorito mais recente são resultados calculados, sem acrescentar atributos aos arquivos de origem.
A5: Dados derivados e exemplo | B5: Agrupa favoritos por animal e conta pares únicos adotante-animal. Obtém a maior data salva de cada grupo. Ordena quantidade decrescente; em empate, usa data mais recente decrescente, nome e identificação. A posição é atribuída após ordenar. Exemplo: Luna tem 3 favoritos únicos, Mel 2 e Nino 1; aparecem nas posições 1, 2 e 3.
A6: Vazios e classificação | B6: Sem favoritos na instituição, apresenta lista vazia e mensagem informativa, sem inventar posições. É SE porque conta, agrupa, seleciona a data máxima e produz posições. A consulta simples dos favoritos individuais permanece separada na CE-06, sem ranking ou agregações.
A7: Arquivos referenciados | B7: ALI-05 Favoritos; ALI-04 Perfil do pet
A9: Arquivo / origem | B9: Dado que cruza a fronteira | C9: Uso no processo | D9: DER contado
A10: ALI-05 | B10: Instituição | C10: Critério recebido | D10: 1
A11: ALI-05 / ALI-04 | B11: Posição calculada | C11: Saída da SE | D11: 1
A12: ALI-04 | B12: Nome | C12: Saída da SE | D12: 1
A13: ALI-04 | B13: Raça | C13: Saída da SE | D13: 1
A14: ALI-05 / ALI-04 | B14: Quantidade de favoritos únicos | C14: Saída da SE | D14: 1
A15: ALI-05 / ALI-04 | B15: Data do favorito mais recente | C15: Saída da SE | D15: 1
A16: Interface / processamento | B16: Conjunto de ações de emissão | C16: Comando | D16: 1
A17: Interface / processamento | B17: Mensagem de validação / ausência de resultado | C17: Resposta | D17: 1
A19: Arquivos referenciados | B19: Nome do grupo lógico | C19: Uso
A20: ALI-05 | B20: Favoritos | C20: Ver finalidade e dados descritos
A21: ALI-04 | B21: Perfil do pet | C21: Ver finalidade e dados descritos
A23: Contagem para PF | B23: Arquivos referenciados | C23: =COUNTA(A20:A21) -> 2
A24: Contagem para PF | B24: Itens de dados (DER) | C24: =IF(COUNT(D10:D17)<>ROWS(D10:D17),"Dados pendentes",IF(COUNTIF(D10:D17,0)+COUNTIF(D10:D17,1)<>ROWS(D10:D17),"Revisar DER",SUM(D10:D17))) -> 8
A25: Complexidade | B25: =IF(OR(NOT(ISNUMBER(C23)),NOT(ISNUMBER(C24)),C23<=0,C24<=0),"Dados pendentes",IF(C24<=5,IF(C23<=3,"Simples","Moderado"),IF(C24<=19,IF(C23<=1,"Simples",IF(C23<=3,"Moderado","Complexo")),IF(C23<=1,"Moderado","Complexo")))) -> Moderado
A26: Tamanho estimado (PF) | B26: =IF(B25="Simples",4,IF(B25="Moderado",5,IF(B25="Complexo",7,"Dados pendentes"))) -> 5

Sheet CE-05 Consulta
A1: CE-05 - Consultar acervo de pets
A2: Tipo e finalidade | B2: CE - A ONG localiza pets de seu acervo para consultar o cadastro, sem alterá-lo. O contexto da instituição limita a consulta aos animais sob sua tutela.
A3: Origem e complemento | B3: Consulta organizada no material anterior a partir do ALI-04 Perfil do pet. Nesta adaptação, critérios e resultado continuam sendo etapas de uma única consulta sem derivação ou manutenção. Nesta atualização de 22/10/2026, a imagem foi substituída por captura real da execução local do Laço, com cobertura parcial identificada na legenda. A identificação, os dados e a classificação continuam referentes ao MatchEngine especificado; a captura não comprova implementação integral da função.
A4: Entrada e critérios | B4: A tela de entrada oferece Nome, Raça e Situação do pet. Nome e raça aceitam trecho do texto; situação aceita um valor armazenado ou qualquer situação. Campos preenchidos são combinados por E. No exemplo, Nome = Luna e Situação = Disponível; Raça fica em branco.
A5: Arquivos e resultado | B5: Consulta o ALI-04, usando nome, raça, situação e ONG responsável para selecionar os registros. Recupera nome, espécie, idade, raça, residência e situação para a tabela de resultado. A idade exibida é o valor cadastrado, sem cálculo a partir de nascimento. Não consulta AIE nesta operação.
A6: Classificação e vazios | B6: É CE porque o processo recebe critérios e devolve dados armazenados, sem calcular compatibilidade, totais ou indicadores e sem manter ALIs. As duas telas representam um único processo elementar. Se não houver correspondência, informa que nenhum pet foi encontrado. Ações de inclusão, alteração e exclusão pertencem às EEs próprias.
A7: Arquivos referenciados | B7: ALI-04 Perfil do pet
A9: Arquivo / origem | B9: Dado que cruza a fronteira | C9: Uso no processo | D9: DER contado
A10: ALI-04 | B10: ONG responsável | C10: Critério recebido | D10: 1
A11: ALI-04 | B11: Nome | C11: Entrada e saída | D11: 1
A12: ALI-04 | B12: Raça | C12: Entrada e saída | D12: 1
A13: ALI-04 | B13: Situação do pet | C13: Entrada e saída | D13: 1
A14: ALI-04 | B14: Espécie | C14: Saída da CE | D14: 1
A15: ALI-04 | B15: Idade | C15: Saída da CE | D15: 1
A16: ALI-04 | B16: Onde reside | C16: Saída da CE | D16: 1
A17: Interface / processamento | B17: Conjunto de ações de consulta | C17: Comando | D17: 1
A18: Interface / processamento | B18: Mensagem de validação / ausência de resultado | C18: Resposta | D18: 1
A20: Arquivos referenciados | B20: Nome do grupo lógico | C20: Uso
A21: ALI-04 | B21: Perfil do pet | C21: Ver finalidade e dados descritos
A23: Contagem para PF | B23: Arquivos referenciados | C23: =COUNTA(A21:A21) -> 1
A24: Contagem para PF | B24: Itens de dados (DER) | C24: =IF(COUNT(D10:D18)<>ROWS(D10:D18),"Dados pendentes",IF(COUNTIF(D10:D18,0)+COUNTIF(D10:D18,1)<>ROWS(D10:D18),"Revisar DER",SUM(D10:D18))) -> 9
A25: Complexidade | B25: =IF(OR(NOT(ISNUMBER(C23)),NOT(ISNUMBER(C24)),C23<=0,C24<=0),"Dados pendentes",IF(C24<=5,IF(C23<=3,"Simples","Moderado"),IF(C24<=19,IF(C23<=1,"Simples",IF(C23<=3,"Moderado","Complexo")),IF(C23<=1,"Moderado","Complexo")))) -> Simples
A26: Tamanho estimado (PF) | B26: =IF(B25="Simples",3,IF(B25="Moderado",4,IF(B25="Complexo",6,"Dados pendentes"))) -> 3

Sheet CE-06 Consulta
A1: CE-06 - Consultar favoritos
A2: Tipo e finalidade | B2: CE - O adotante consulta os pets que salvou e as observações registradas. O processo exibe favoritos individuais, sem ordenar por popularidade ou produzir um ranking.
A3: Origem e complemento | B3: Consulta organizada no material anterior a partir do ALI-05 Favoritos. Nesta adaptação, o resultado individual permanece sem ranking, score, contagem ou manutenção. Nesta atualização de 22/10/2026, a imagem foi substituída por captura real da execução local do Laço, com cobertura parcial identificada na legenda. A identificação, os dados e a classificação continuam referentes ao MatchEngine especificado; a captura não comprova implementação integral da função.
A4: Entrada e critérios | B4: A entrada usa Adotante, identificado pelo e-mail da sessão, e Instituição. O vínculo com o adotante é obrigatório; a instituição pode ser informada para restringir a lista ou deixada sem filtro. No exemplo, adotante ana@example.com e instituição Projeto Patinhas são combinados por E.
A5: Arquivos e resultado | B5: Lê Adotante, Animal favorito, Instituição, Data em que foi salvo e Observação no ALI-05 Favoritos e recupera Nome no ALI-04 Perfil do pet para identificar Animal favorito. Apresenta Animal favorito, Instituição, Data em que foi salvo e Observação exatamente como armazenados. Não calcula prazo, compatibilidade, quantidade ou posição. Não referencia AIE.
A6: Classificação e vazios | B6: É CE porque recebe critérios e retorna dados armazenados sem derivação ou manutenção. Entrada e resultado integram um único processo. Se a seleção estiver vazia, informa que não há favoritos para os critérios. Registrar interesse corresponde à EE-10; gerar o ranking agregado corresponde à SE-06.
A7: Arquivos referenciados | B7: ALI-05 Favoritos; ALI-04 Perfil do pet
A9: Arquivo / origem | B9: Dado que cruza a fronteira | C9: Uso no processo | D9: DER contado
A10: ALI-05 | B10: Adotante | C10: Critério recebido | D10: 1
A11: ALI-05 | B11: Instituição | C11: Entrada e saída | D11: 1
A12: ALI-05 | B12: Animal favorito | C12: Saída da CE | D12: 1
A13: ALI-05 | B13: Data em que foi salvo | C13: Saída da CE | D13: 1
A14: ALI-05 | B14: Observação | C14: Saída da CE | D14: 1
A15: Interface / processamento | B15: Conjunto de ações de consulta | C15: Comando | D15: 1
A16: Interface / processamento | B16: Mensagem de validação / ausência de resultado | C16: Resposta | D16: 1
A18: Arquivos referenciados | B18: Nome do grupo lógico | C18: Uso
A19: ALI-05 | B19: Favoritos | C19: Ver finalidade e dados descritos
A20: ALI-04 | B20: Perfil do pet | C20: Ver finalidade e dados descritos
A22: Contagem para PF | B22: Arquivos referenciados | C22: =COUNTA(A19:A20) -> 2
A23: Contagem para PF | B23: Itens de dados (DER) | C23: =IF(COUNT(D10:D16)<>ROWS(D10:D16),"Dados pendentes",IF(COUNTIF(D10:D16,0)+COUNTIF(D10:D16,1)<>ROWS(D10:D16),"Revisar DER",SUM(D10:D16))) -> 7
A24: Complexidade | B24: =IF(OR(NOT(ISNUMBER(C22)),NOT(ISNUMBER(C23)),C22<=0,C23<=0),"Dados pendentes",IF(C23<=5,IF(C22<=3,"Simples","Moderado"),IF(C23<=19,IF(C22<=1,"Simples",IF(C22<=3,"Moderado","Complexo")),IF(C22<=1,"Moderado","Complexo")))) -> Moderado
A25: Tamanho estimado (PF) | B25: =IF(B24="Simples",3,IF(B24="Moderado",4,IF(B24="Complexo",6,"Dados pendentes"))) -> 4

Sheet Critérios e fontes
A1: Critérios de classificação e estimativa didática
A2: Fronteira | B2: Aplicação de adoção animal especificada no trabalho. Adotantes, ONGs e sistemas externos estão fora da fronteira. As funções e contagens correspondem ao MatchEngine especificado. As imagens são capturas reais do Laço em execução local, com cobertura parcial; a existência de uma tela relacionada não comprova a implementação integral da função.
A3: Convenção de contagem | B3: ALI/AIE: um DER por dado reconhecido pelo usuário; o grupo biológico do pet foi detalhado em campos independentes. EE: dados que cruzam a fronteira, um conjunto de comandos e duas respostas possíveis, conforme os exemplos da disciplina.
A4: SE e CE | B4: Os dados recebidos e apresentados são listados por processo. Um mesmo dado de consulta e resultado é contado uma vez. As regras internas de filtro não são entradas adicionais. SE produz dado derivado; CE apenas recupera dados armazenados, sem atualização ou cálculo novo.
A6: ALI - faixas de DER nas colunas
A7: RL / arquivos | B7: 1 a 19 | C7: 20 a 50 | D7: 51 ou mais
A8: 1 RL | B8: Simples | C8: Simples | D8: Moderado
A9: 2 a 5 RL | B9: Simples | C9: Moderado | D9: Complexo
A10: 6 ou mais RL | B10: Moderado | C10: Complexo | D10: Complexo
A11: Pesos em PF | B11: 7 | C11: 10 | D11: 15
A14: AIE - faixas de DER nas colunas
A15: RL / arquivos | B15: 1 a 19 | C15: 20 a 50 | D15: 51 ou mais
A16: 1 RL | B16: Simples | C16: Simples | D16: Moderado
A17: 2 a 5 RL | B17: Simples | C17: Moderado | D17: Complexo
A18: 6 ou mais RL | B18: Moderado | C18: Complexo | D18: Complexo
A19: Pesos em PF | B19: 5 | C19: 7 | D19: 10
A22: EE - faixas de DER nas colunas
A23: RL / arquivos | B23: 1 a 4 | C23: 5 a 15 | D23: 16 ou mais
A24: 0 ou 1 arquivo | B24: Simples | C24: Simples | D24: Moderado
A25: 2 arquivos | B25: Simples | C25: Moderado | D25: Complexo
A26: 3 ou mais arquivos | B26: Moderado | C26: Complexo | D26: Complexo
A27: Pesos em PF | B27: 3 | C27: 4 | D27: 6
A30: SE - faixas de DER nas colunas
A31: RL / arquivos | B31: 1 a 5 | C31: 6 a 19 | D31: 20 ou mais
A32: 0 ou 1 arquivo | B32: Simples | C32: Simples | D32: Moderado
A33: 2 a 3 arquivos | B33: Simples | C33: Moderado | D33: Complexo
A34: 4 ou mais arquivos | B34: Moderado | C34: Complexo | D34: Complexo
A35: Pesos em PF | B35: 4 | C35: 5 | D35: 7
A38: CE - faixas de DER nas colunas
A39: RL / arquivos | B39: 1 a 5 | C39: 6 a 19 | D39: 20 ou mais
A40: 0 ou 1 arquivo | B40: Simples | C40: Simples | D40: Moderado
A41: 2 a 3 arquivos | B41: Simples | C41: Moderado | D41: Complexo
A42: 4 ou mais arquivos | B42: Moderado | C42: Complexo | D42: Complexo
A43: Pesos em PF | B43: 3 | C43: 4 | D43: 6

Sheet NI e estimativas
A2: PFB (PF) | B2: =Contribuição!D17 -> 65 | C2: Vínculo à soma das funções individuais em Contribuição!D21; não corresponde ao tamanho total do sistema.
A3: NI total (0 a 70) | B3: =IF(COUNT(B9:B22)<>ROWS(B9:B22),"Notas pendentes",IF(SUM(COUNTIF(B9:B22,0),COUNTIF(B9:B22,1),COUNTIF(B9:B22,2),COUNTIF(B9:B22,3),COUNTIF(B9:B22,4),COUNTIF(B9:B22,5))<>ROWS(B9:B22),"Notas inválidas",SUM(B9:B22))) -> 25 | C3: Soma das 14 notas de B12:B25. Cada nota deve ser um número inteiro de 0 a 5; justifique qualquer alteração.
A4: Fator de ajuste (FA) | B4: =IF(ISNUMBER(B3),0.65+0.01*B3,"Revisar NI") -> 0.9 | C4: FA = 0,65 + 0,01 × NI total. Intervalo possível: 0,65 a 1,35.
A5: PFA (PF ajustados) | B5: =IF(AND(ISNUMBER(B2),ISNUMBER(B4)),B2*B4,"Revisar dados") -> 58.5 | C5: PFA = PFB × FA. O ajuste pode reduzir ou aumentar o tamanho: NI abaixo de 35 produz FA menor que 1.
A7: Características gerais da aplicação: notas propostas e justificativas
A8: Característica | B8: NI (0 a 5) | C8: Justificativa da nota | D8: Enquadramento e referência
A9: 1. Comunicação de dados | B9: 4 | C9: Premissa da aplicação especificada: acesso web com envio de dados e atualização de ALIs por HTTP. Enquadra comunicação on-line além de uma consulta; não se pressupõem vários protocolos. | D9: Hipótese de arquitetura. UC 01–06 e abas EE/CE. IFPUG 8-6 a 8-8.
A10: 2. Processamento distribuído | B10: 4 | C10: Premissa de arquitetura para a solução completa: cliente web envia operações e servidor processa, mantém dados e devolve resultados on-line. Fluxo bidirecional; sem seleção dinâmica de processadores. O protótipo local não comprova essa implantação. | D10: Hipótese cliente/servidor. IFPUG 8-9 e 8-10.
A11: 3. Desempenho | B11: 1 | C11: A apresentação interativa dos cards exige resposta percebida como rápida. Considera-se essa preocupação no projeto, sem SLA numérico, análise especial de desempenho ou ferramentas de carga comprovadas. | D11: Interação descrita no UC 04. Julgamento conservador. IFPUG 8-11.
A12: 4. Configuração intensamente utilizada | B12: 0 | C12: O escopo não impõe limites específicos de memória, CPU, hardware compartilhado ou utilização de equipamentos saturados. Não se acrescenta influência sem requisito de restrição operacional. | D12: Ausência de requisito específico no escopo analisado. IFPUG 8-13.
A13: 5. Volume de transações | B13: 1 | C13: Adota-se volume inicial baixo para o projeto acadêmico, com impacto pequeno no desenho. Não há volumetria, pico de concorrência ou necessidade documentada de análise especial de capacidade. | D13: Premissa de baixa carga, sujeita a revisão com volumetria. IFPUG 8-15.
A14: 6. Entrada de dados on-line | B14: 5 | C14: As quatro EEs, as duas CEs e a emissão das duas SEs do recorte são acionadas por interação com a aplicação. Mais de 30% dos tipos de transação são interativos, faixa correspondente à nota 5. | D14: Abas EE - Gustavo, SE-05/06 e CE-05/06. IFPUG 8-16.
A15: 7. Eficiência do usuário final | B15: 3 | C15: As telas especificam navegação, menus, rolagem, valores padrão, interação por mouse e janelas/modais: seis recursos considerados no modelo. São hipóteses da interface pretendida. Não se assume estudo de ergonomia nem ferramentas especiais de usabilidade. | D15: Fluxos de interface especificados e capturas reais parciais da execução local do Laço em 22/10/2026. IFPUG 8-17 e 8-18.
A16: 8. Atualização on-line | B16: 3 | C16: A especificação prevê manter os pets da ONG e registrar interesses/favoritos pelas EEs 07, 08, 09 e 10 durante a interação. São ALIs de negócio. Não há projeto comprovado de recuperação automática contra perda de dados. | D16: ALI-04 e ALI-05 e EE - Gustavo. Avalia a especificação. IFPUG 8-19.
A17: 9. Processamento complexo | B17: 1 | C17: Conta-se um componente: controle de acesso por titular/papel, delimitando os pets da ONG e os favoritos do adotante. Scores, contagens, médias, percentuais e intervalos de datas usam aritmética básica; não fundamentam matemática extensa nem os demais componentes. | D17: CE-05/06 e SE-05/06; fronteira por usuário. IFPUG 8-20 e 8-21.
A18: 10. Reutilização | B18: 1 | C18: Adota-se reaproveitamento interno de formulários, validações e componentes de interface no MatchEngine. O recorte não exige empacotar componentes para outras aplicações, portanto a nota fica no reuso interno. | D18: Premissa de implementação interna; sem transferir o escopo de outros produtos Laço. IFPUG 8-22.
A19: 11. Facilidade de instalação | B19: 1 | C19: Para realizar as funções especificadas, pressupõe-se configuração do ambiente web e do armazenamento. Não se prevê migração de base legada, instalador especial ou conversão automatizada exigida pelo usuário. | D19: Premissa de implantação da solução completa. IFPUG 8-23 e 8-24.
A20: 12. Facilidade de operação | B20: 1 | C20: O acervo de pets e os favoritos são consultados em tela, reduzindo o manuseio de papel: um item do critério. Não se atribuem pontos a backup, recuperação automática ou operação sem intervenção não especificados. | D20: CE-05/06; critério de saída por meio eletrônico. IFPUG 8-25 e 8-26.
... A22: 14. Facilidade de mudanças | B22: 0 | C22: Os critérios de Nome, Raça, Situação e E-mail do adotante mantêm formato fixo. Não há editor de consultas/relatórios nem manutenção pelo usuário de tabelas de regras com vigência definida. As regras propostas das SEs não comprovam esse mecanismo. | D22: CE-05/06 e regras propostas de SE-05/06. IFPUG 8-29 e 8-30.
A26: Premissas editáveis para a estimativa individual
A27: Premissa | B27: Valor | C27: Explicação e alcance | D27: Unidade / origem
A28: Índice de esforço | B28: 10 | C28: Horas por PFA para análise, prototipação, implementação, testes e documentação. Não há histórico medido em PF; substituir a hipótese quando houver dados. Não é o índice de 20 h/UCP dos documentos de casos de uso. | D28: h/PFA. Hipótese didática; não é coeficiente do IFPUG.
A29: Pessoas equivalentes | B29: 1 | C29: Quantidade de pessoas equivalentes dedicada ao recorte de Gustavo; valor inicial: uma. Não se usa automaticamente o total de quatro integrantes para reduzir o prazo desta contribuição. | D29: pessoa. Premissa de capacidade individual.
A30: Jornada por dia | B30: 8 | C30: Jornada de referência antes de descontar reuniões, pausas e outras atividades. A produtividade efetiva é calculada pela alocação da linha seguinte. | D30: h/dia por pessoa. Hipótese de planejamento.
A31: Alocação produtiva | B31: 0.75 | C31: Parcela da jornada disponível para as atividades incluídas no esforço. O restante fica fora dessa capacidade. Horas produtivas por pessoa/dia = jornada × alocação, calculadas em B43. | D31: proporção de 0 a 1. Hipótese de disponibilidade.
A32: Dias úteis por semana | B32: 5 | C32: Usado para converter o prazo em dias úteis em semanas. Não define data inicial, calendário de feriados ou compromisso de entrega. | D32: dias/semana. Hipótese de calendário.
A33: Valor da hora | B33: 50 | C33: Valor orçamentário adotado para cada hora do esforço incluído. Não é pesquisa de mercado, salário comprovado nem custo efetivamente incorrido. | D33: R$/h. Premissa didática editável.
A34: Reserva de esforço | B34: 0.2 | C34: Aplica o percentual informado às horas base para incerteza de requisitos, integrações propostas e retrabalho. A reserva afeta esforço, prazo e custo uma única vez. | D34: proporção de 0 a 1. Reserva de planejamento.
A35: Custos adicionais | B35: 0 | C35: Campo para hospedagem, licenças, equipamentos e encargos adicionais documentados. O valor inicial zero indica que nenhum desses desembolsos foi orçado; itens não informados ficam fora da estimativa. | D35: R$. Valor inicial zero; não representa cotação.
A37: Estimativas para desenvolver as funções individuais especificadas
A38: Resultado | B38: Valor calculado | C38: Fórmula de planejamento e interpretação | D38: Unidade
A39: Horas produtivas por pessoa/dia | B39: =IF(AND(ISNUMBER(B30),B30>0,ISNUMBER(B31),B31>0,B31<=1),B30*B31,"Revisar jornada") -> 6 | C39: Jornada × alocação produtiva. | D39: h/pessoa/dia
A40: Esforço base | B40: =IF(AND(ISNUMBER(B5),ISNUMBER(B28),B28>0),B5*B28,"Revisar dados") -> 585 | C40: PFA × índice de esforço. Mede trabalho total, sem reserva. | D40: h
A41: Reserva em horas | B41: =IF(AND(ISNUMBER(B40),ISNUMBER(B34),B34>=0,B34<=1),B40*B34,"Revisar reserva") -> 117 | C41: Esforço base × percentual de reserva. Reserva zero é permitida. | D41: h
A42: Esforço total com reserva | B42: =IF(AND(ISNUMBER(B40),ISNUMBER(B41)),SUM(B40:B41),"Revisar dados") -> 702 | C42: Esforço base + reserva; base usada no prazo e no custo total. | D42: h
A43: Capacidade diária da equipe | B43: =IF(AND(ISNUMBER(B29),B29>0,ISNUMBER(B39)),B29*B39,"Revisar equipe") -> 6 | C43: Pessoas equivalentes × horas produtivas por pessoa/dia. | D43: h/dia
A44: Prazo calculado | B44: =IF(AND(ISNUMBER(B42),ISNUMBER(B43)),B42/B43,"Revisar dados") -> 117 | C44: Esforço total ÷ capacidade diária. Valor fracionário antes do arredondamento. | D44: dias úteis
A45: Prazo planejado | B45: =IF(ISNUMBER(B44),ROUNDUP(ROUND(B44,10),0),"Revisar dados") -> 117 | C45: Prazo calculado arredondado para o próximo dia útil inteiro. Arredondamento técnico prévio a 10 casas evita um dia extra causado apenas pela representação decimal. | D45: dias úteis
A46: Prazo em semanas | B46: =IF(AND(ISNUMBER(B45),ISNUMBER(B32),B32>0,B32<=7),B45/B32,"Revisar calendário") -> 23.4 | C46: Prazo planejado ÷ dias úteis por semana. Não é duração em dias corridos. | D46: semanas
A47: Custo base de mão de obra | B47: =IF(AND(ISNUMBER(B40),ISNUMBER(B33),B33>=0),B40*B33,"Revisar valor/hora") -> 29250 | C47: Esforço base × valor da hora. | D47: R$
...
