Workbook

Sheet Contribuição
A1: Medição de Software — Lucas Andriani Theiss
A2: Integrante / recorte | B2: Lucas Andriani Theiss — movimentacoes e usuarios
A4: Item | B4: Função / grupo lógico | C4: Tipo | D4: PF estimados
A5: A05 | B5: Movimentações | C5: ALI | D5: ='A05 ALI'!B30 -> 7
A6: A06 | B6: Usuários | C6: ALI | D6: ='A06 ALI'!B18 -> 7
A7: X01 | B7: Fornecedores externos | C7: AIE | D7: ='X01 AIE'!B19 -> 5
A8: X02 | B8: Ofertas externas | C8: AIE | D8: ='X02 AIE'!B19 -> 5
A9: EE21 | B9: Registrar entrada | C9: EE | D9: ='Entradas externas'!B39 -> 6
A10: EE13 | B10: Incluir usuário | C10: EE | D10: ='Entradas externas'!B81 -> 6
A11: EE21 | B11: Detalhamento já contado | C11: Continuação | D11: ='Entradas externas'!B106 -> 0
A12: EE13 | B12: Detalhamento já contado | C12: Continuação | D12: ='Entradas externas'!B135 -> 0
A13: SE04 | B13: Fluxo de movimentações | C13: SE | D13: ='SE04 SE'!B32 -> 5
A14: SE13 | B14: Comparar preços internos e ofertas externas | C14: SE | D14: ='SE13 SE'!B26 -> 5
A15: CE04 | B15: Consultar fornecedores externos | C15: CE | D15: ='CE04 Consulta'!B26 -> 3
A16: CE12 | B16: Consultar ofertas externas | C16: CE | D16: ='CE12 Consulta'!B25 -> 3
A17: Total individual estimado | D17: =IF(COUNT(D5:D16)=ROWS(D5:D16),SUM(D5:D16),"Dados pendentes") -> 52
A19: Cálculos de ajuste e estimativa individual
A20: NI total | B20: ='NI e estimativas'!B3 -> 41 | C20: NI: 14 notas. Contribuição real nas EEs: confirmar.
A21: Fator de ajuste (FA) | B21: ='NI e estimativas'!B4 -> 1.06 | C21: FA = 0,65 + 0,01 × NI.
A22: PFA individual | B22: ='NI e estimativas'!B5 -> 55.12 | C22: PFB individual × FA.
A23: Esforço com reserva (h) | B23: ='NI e estimativas'!B42 -> 551.2 | C23: Inclui a reserva de esforço de planejamento.
A24: Prazo planejado (dias úteis) | B24: ='NI e estimativas'!B45 -> 92 | C24: Prazo calculado pela capacidade diária definida nas premissas.
A25: Custo com reserva (R$) | B25: ='NI e estimativas'!B49 -> 13780 | C25: Valor da hora e custos adicionais são premissas editáveis.

Sheet A05 ALI
A1: A05 — Movimentações
A2: Sistema | B2: Estoque Inteligente
A3: Tipo | B3: ALI - Arquivo Lógico Interno
A4: Justificativa | B4: Grupo mantido pelo Estoque Inteligente.
A5: Requisito relacionado | B5: Manter Movimentações
A6: Caso de uso relacionado | B6: Função implementada: /movimentar e /historico. Um grupo lógico reconhecido pelo usuário.
A8: Registro lógico | B8: Item de dado referenciado | C8: Tipo | D8: Quantidade de TD na linha
A9: Movimentações | B9: loja | C9: String | D9: 1
A10: Movimentações | B10: número | C10: String | D10: 1
A11: Movimentações | B11: produto | C11: String | D11: 1
A12: Movimentações | B12: posição | C12: String | D12: 1
A13: Movimentações | B13: responsável | C13: String | D13: 1
A14: Movimentações | B14: tipo | C14: String | D14: 1
A15: Movimentações | B15: variação | C15: Decimal | D15: 1
A16: Movimentações | B16: saldo anterior | C16: Decimal | D16: 1
A17: Movimentações | B17: saldo posterior | C17: Decimal | D17: 1
A18: Movimentações | B18: motivo | C18: String | D18: 1
A19: Movimentações | B19: data | C19: Date | D19: 1
A20: Movimentações | B20: movimento original | C20: String | D20: 1
D21: 0
D22: 0
D23: 0
D24: 0
D25: 0
A27: Contagem para PF | B27: Registros lógicos (RL) | C27: =ROUND(SUMPRODUCT((A9:A25<>"")/COUNTIF(A9:A25,A9:A25&"")),0) -> 1
A28: Contagem para PF | B28: Itens de dados (DER) | C28: =SUM(D9:D25) -> 12
A29: Complexidade | B29: =IF(OR(NOT(ISNUMBER(C27)),NOT(ISNUMBER(C28)),C27<=0,C28<=0),"Dados pendentes",IF(C28<=19,IF(C27<=5,"Simples","Moderado"),IF(C28<=50,IF(C27=1,"Simples",IF(C27<=5,"Moderado","Complexo")),IF(C27=1,"Moderado","Complexo")))) -> Simples
A30: Tamanho estimado (PF) | B30: =IF(B29="Simples",7,IF(B29="Moderado",10,IF(B29="Complexo",15,"Dados pendentes"))) -> 7
A32: Origem e complemento | B32: 1 RL: Registro de movimentações. Campos separados por ponto e vírgula são distintos; D informa quantos TD há em cada linha.
A33: Relação com a tela | B33: Captura real de /historico no sistema local, loja Calçados Aurora. Dados de demonstração. Campos internos/contextuais não precisam aparecer como entradas editáveis.

Sheet A06 ALI
A1: A06 — Usuários
A2: Sistema | B2: Estoque Inteligente
A3: Tipo | B3: ALI - Arquivo Lógico Interno
A4: Justificativa | B4: Grupo mantido pelo Estoque Inteligente.
A5: Requisito relacionado | B5: Manter Usuários
A6: Caso de uso relacionado | B6: Função implementada: /usuarios. Um grupo lógico reconhecido pelo usuário.
A8: Registro lógico | B8: Item de dado referenciado | C8: Tipo | D8: Quantidade de TD na linha
A9: Usuários | B9: loja; código | C9: String; String | D9: 2
A10: Usuários | B10: nome de usuário | C10: String | D10: 1
A11: Usuários | B11: senha | C11: String | D11: 1
A12: Usuários | B12: perfil | C12: String | D12: 1
A13: Usuários | B13: ativo | C13: Boolean | D13: 1
A15: Contagem para PF | B15: Registros lógicos (RL) | C15: =ROUND(SUMPRODUCT((A9:A13<>"")/COUNTIF(A9:A13,A9:A13&"")),0) -> 1
A16: Contagem para PF | B16: Itens de dados (DER) | C16: =SUM(D9:D13) -> 6
A17: Complexidade | B17: =IF(OR(NOT(ISNUMBER(C15)),NOT(ISNUMBER(C16)),C15<=0,C16<=0),"Dados pendentes",IF(C16<=19,IF(C15<=5,"Simples","Moderado"),IF(C16<=50,IF(C15=1,"Simples",IF(C15<=5,"Moderado","Complexo")),IF(C15=1,"Moderado","Complexo")))) -> Simples
A18: Tamanho estimado (PF) | B18: =IF(B17="Simples",7,IF(B17="Moderado",10,IF(B17="Complexo",15,"Dados pendentes"))) -> 7
A20: Origem e complemento | B20: 1 RL: Registro de usuários. Campos separados por ponto e vírgula são distintos; D informa quantos TD há em cada linha.
A21: Relação com a tela | B21: Captura real de /usuarios no sistema local, loja Calçados Aurora. Dados de demonstração. Campos internos/contextuais não precisam aparecer como entradas editáveis.

Sheet X01 AIE
A1: X01 — Fornecedores externos
A2: Sistema | B2: Estoque Inteligente
A3: Tipo | B3: AIE - Arquivo de Interface Externa
A4: Justificativa | B4: Dados mantidos pelo provedor externo; o Estoque Inteligente apenas consulta.
A5: Requisito relacionado | B5: Consultar Fornecedores externos
A6: Caso de uso relacionado | B6: Função implementada: /fornecedores. Um grupo lógico reconhecido pelo usuário.
A7: Sistema externo | B7: external/fornecedores — provedor independente, integração HTTP.
A9: Registro lógico | B9: Item de dado referenciado | C9: Tipo | D9: Quantidade de TD na linha
A10: Fornecedores externos | B10: código | C10: String | D10: 1
A11: Fornecedores externos | B11: nome | C11: String | D11: 1
A12: Fornecedores externos | B12: documento | C12: String | D12: 1
A13: Fornecedores externos | B13: e-mail | C13: String | D13: 1
A14: Fornecedores externos | B14: telefone | C14: String | D14: 1
A16: Contagem para PF | B16: Registros lógicos (RL) | C16: =ROUND(SUMPRODUCT((A10:A14<>"")/COUNTIF(A10:A14,A10:A14&"")),0) -> 1
A17: Contagem para PF | B17: Itens de dados (DER) | C17: =SUM(D10:D14) -> 5
A18: Complexidade | B18: =IF(OR(NOT(ISNUMBER(C16)),NOT(ISNUMBER(C17)),C16<=0,C17<=0),"Dados pendentes",IF(C17<=19,IF(C16<=5,"Simples","Moderado"),IF(C17<=50,IF(C16=1,"Simples",IF(C16<=5,"Moderado","Complexo")),IF(C16=1,"Moderado","Complexo")))) -> Simples
A19: Tamanho estimado (PF) | B19: =IF(B18="Simples",5,IF(B18="Moderado",7,IF(B18="Complexo",10,"Dados pendentes"))) -> 5
A21: Origem e complemento | B21: 1 RL: Registro de fornecedores externos. Campos separados por ponto e vírgula são distintos; D informa quantos TD há em cada linha.
A22: Relação com a tela | B22: Captura real de /fornecedores no sistema local, loja Calçados Aurora. Dados de demonstração. Campos internos/contextuais não precisam aparecer como entradas editáveis.

Sheet X02 AIE
A1: X02 — Ofertas externas
A2: Sistema | B2: Estoque Inteligente
A3: Tipo | B3: AIE - Arquivo de Interface Externa
A4: Justificativa | B4: Dados mantidos pelo provedor externo; o Estoque Inteligente apenas consulta.
A5: Requisito relacionado | B5: Consultar Ofertas externas
A6: Caso de uso relacionado | B6: Função implementada: /ofertas. Um grupo lógico reconhecido pelo usuário.
A7: Sistema externo | B7: external/ofertas — provedor independente, integração HTTP.
A9: Registro lógico | B9: Item de dado referenciado | C9: Tipo | D9: Quantidade de TD na linha
A10: Ofertas externas | B10: GTIN; código do fornecedor | C10: String; String | D10: 2
A11: Ofertas externas | B11: SKU externo; descrição | C11: String; String | D11: 2
A12: Ofertas externas | B12: marca; unidade | C12: String; String | D12: 2
A13: Ofertas externas | B13: preço cotado; disponibilidade | C13: Decimal; String | D13: 2
A14: Ofertas externas | B14: data de atualização | C14: Date | D14: 1
A16: Contagem para PF | B16: Registros lógicos (RL) | C16: =ROUND(SUMPRODUCT((A10:A14<>"")/COUNTIF(A10:A14,A10:A14&"")),0) -> 1
A17: Contagem para PF | B17: Itens de dados (DER) | C17: =SUM(D10:D14) -> 9
A18: Complexidade | B18: =IF(OR(NOT(ISNUMBER(C16)),NOT(ISNUMBER(C17)),C16<=0,C17<=0),"Dados pendentes",IF(C17<=19,IF(C16<=5,"Simples","Moderado"),IF(C17<=50,IF(C16=1,"Simples",IF(C16<=5,"Moderado","Complexo")),IF(C16=1,"Moderado","Complexo")))) -> Simples
A19: Tamanho estimado (PF) | B19: =IF(B18="Simples",5,IF(B18="Moderado",7,IF(B18="Complexo",10,"Dados pendentes"))) -> 5
A21: Origem e complemento | B21: 1 RL: Oferta comercial externa. Campos separados por ponto e vírgula são distintos; D informa quantos TD há em cada linha.
A22: Relação com a tela | B22: Captura real de /ofertas no sistema local, loja Calçados Aurora. Dados de demonstração. Campos internos/contextuais não precisam aparecer como entradas editáveis.

Sheet Entradas externas
A1: EE21 — Registrar entrada
A2: Tipo e finalidade | B2: EE: Registrar entrada. Entrada: produto, posição, tipo, quantidade, motivo.
A3: Origem e complemento | B3: A identificação desta EE considerou produto, posição, tipo, quantidade e motivo como dados recebidos e A02 (Produtos), A03 (Posições), A04 (Vínculos), A05 (Movimentações) e A09 (Auditoria) como arquivos referenciados. A operação registra a entrada e atualiza o saldo. A imagem mostra o formulário real, sem enviar uma movimentação para obtê-la.
A4: Arquivos e itens | B4: A02: identificação, unidade e ativo do produto. A03: identificação, unidade e ativo da posição. A04: loja, produto, posição e quantidade anterior/posterior. A05: produto, posição, responsável, tipo, variação, saldo anterior, saldo posterior, motivo e data; número gerado e movimento original vazio na entrada normal. A09: loja, responsável, ação, detalhe e data. Chave técnica de idempotência excluída dos TD.
A5: Resultado e classificação | B5: Mantém dados internos e retorna mensagem de resultado. Intenção principal de manutenção: classificada como EE.
A6: Campos complementados | B6: TD = campos distintos da interface + acionamento + mensagem de resultado. Dados internos não são TD adicionais. Linhas não utilizadas valem zero.
A7: Arquivos referenciados | B7: A02 Produtos; A03 Posições; A04 Estoque por posição / vínculos; A05 Movimentações; A09 Auditoria consultável
A9: Arquivo / origem | B9: Dado que cruza a fronteira | C9: Uso no processo | D9: DER contado
A10: Interface | B10: produto | C10: Entrada | D10: 1
A11: Interface | B11: posição | C11: Entrada | D11: 1
A12: Interface | B12: tipo | C12: Entrada | D12: 1
A13: Interface | B13: quantidade | C13: Entrada | D13: 1
A14: Interface | B14: motivo | C14: Entrada | D14: 1
A15: Interface | B15: mensagem de resultado | C15: Saída | D15: 1
A16: Interface | B16: acionamento | C16: Controle | D16: 1
D17: 0
D18: 0
D19: 0
D20: 0
D21: 0
D22: 0
D23: 0
D24: 0
D25: 0
D26: 0
D27: 0
D28: 0
D29: 0
A31: Arquivos referenciados | B31: Nome do grupo lógico | C31: Uso
A32: A02; A03 | B32: Produtos; Posições | C32: Lido / mantido conforme descrição
A33: A04; A05 | B33: Estoque por posição / vínculos; Movimentações | C33: Lido / mantido conforme descrição
A34: A09 | B34: Auditoria consultável | C34: Lido / mantido conforme descrição
A36: Contagem para PF | B36: Arquivos referenciados | C36: =SUM(IF(A32="",0,LEN(A32)-LEN(SUBSTITUTE(A32,";",""))+1),IF(A33="",0,LEN(A33)-LEN(SUBSTITUTE(A33,";",""))+1),IF(A34="",0,LEN(A34)-LEN(SUBSTITUTE(A34,";",""))+1)) -> 5
A37: Contagem para PF | B37: Itens de dados (DER) | C37: =IF(COUNT(D10:D29)<>ROWS(D10:D29),"Dados pendentes",IF(COUNTIF(D10:D29,0)+COUNTIF(D10:D29,1)<>ROWS(D10:D29),"Revisar DER",SUM(D10:D29))) -> 7
A38: Complexidade | B38: =IF(OR(NOT(ISNUMBER(C36)),NOT(ISNUMBER(C37)),C36<=0,C37<=0),"Dados pendentes",IF(C37<=4,IF(C36<=2,"Simples","Moderado"),IF(C37<=15,IF(C36<=1,"Simples",IF(C36=2,"Moderado","Complexo")),IF(C36<=1,"Moderado","Complexo")))) -> Complexo
A39: Tamanho estimado (PF) | B39: =IF(B38="Simples",3,IF(B38="Moderado",4,IF(B38="Complexo",6,"Dados pendentes"))) -> 6
A42: EE13 — Incluir usuário
A43: Tipo e finalidade | B43: EE: Incluir usuário. Entrada: nome de usuário, perfil, senha.
A44: Origem e complemento | B44: A identificação desta EE considerou nome de usuário, perfil e senha como dados recebidos, além da loja como contexto. A operação mantém A06 (Usuários) e registra a ação em A09 (Auditoria). A senha é persistida como hash. A imagem é uma captura real do formulário; nenhum cadastro foi enviado para obtê-la.
A45: Arquivos e itens | B45: A08: identificação da loja e ativo. A06: loja, nome de usuário, senha (persistida como hash), perfil e ativo; identificação gerada. A09: loja, responsável, ação usuario.salvar, detalhe nome/perfil e data gerada. Hash é representação técnica da senha, não um segundo TD.
...

Sheet SE04 SE
A1: SE04 — Fluxo de movimentações
A2: Tipo e finalidade | B2: SE — Fluxo de movimentações.
A3: Origem e complemento | B3: Captura real da saída na aplicação local, com dados de demonstração. Campos separados por ponto e vírgula são distintos; D registra a quantidade por linha. Outros canais do mesmo processo não duplicam a contagem.
A4: ALIs e itens referenciados | B4: A02: SKU e unidade; A05: produto, tipo, data e variação. Loja delimita os registros. COUNT e SUM por produto/tipo no período inclusivo de Brasília; estornos têm categoria e sinal próprios.
A5: Dados derivados e exemplo | B5: COUNT(*) e SUM(delta) por produto/tipo. Período inclusivo em America/Sao_Paulo; estornos em categoria própria.
A6: Interpretação e classificação | B6: SE: produz dados derivados, não apenas dados recuperados. Entrada: início, fim.
A7: Arquivos referenciados | B7: A02 Produtos; A05 Movimentações
A9: Arquivo / origem | B9: Dado que cruza a fronteira | C9: Uso no processo | D9: DER contado
A10: Interface | B10: início | C10: Entrada | D10: 1
A11: Interface | B11: fim | C11: Entrada | D11: 1
A12: Interface | B12: SKU | C12: Saída | D12: 1
A13: Interface | B13: unidade | C13: Saída | D13: 1
A14: Interface | B14: tipo | C14: Saída | D14: 1
A15: Interface | B15: número de operações | C15: Saída | D15: 1
A16: Interface | B16: variação líquida | C16: Saída | D16: 1
A17: Interface | B17: acionamento | C17: Controle | D17: 1
A18: Interface | B18: mensagem de resultado | C18: Controle | D18: 1
D19: 0
D20: 0
D21: 0
A23: Arquivos referenciados | B23: Nome do grupo lógico | C23: Uso
A24: A02 | B24: Produtos | C24: Lido / mantido conforme descrição
A25: A05 | B25: Movimentações | C25: Lido / mantido conforme descrição
A29: Contagem para PF | B29: Arquivos referenciados | C29: =COUNTA(A24:A27) -> 2
A30: Contagem para PF | B30: Itens de dados (DER) | C30: =SUM(D10:D21) -> 9
A31: Complexidade | B31: =IF(OR(NOT(ISNUMBER(C29)),NOT(ISNUMBER(C30)),C29<=0,C30<=0),"Dados pendentes",IF(C30<=5,IF(C29<=3,"Simples","Moderado"),IF(C30<=19,IF(C29<=1,"Simples",IF(C29<=3,"Moderado","Complexo")),IF(C29<=1,"Moderado","Complexo")))) -> Moderado
A32: Tamanho estimado (PF) | B32: =IF(B31="Simples",4,IF(B31="Moderado",5,IF(B31="Complexo",7,"Dados pendentes"))) -> 5

Sheet SE13 SE
A1: SE13 — Comparar preços internos e ofertas externas
A2: Tipo e finalidade | B2: SE — Comparar preços internos e ofertas externas.
A3: Origem e complemento | B3: Captura real da saída na aplicação local, com dados de demonstração. Campos separados por ponto e vírgula são distintos; D registra a quantidade por linha. Outros canais do mesmo processo não duplicam a contagem.
A4: ALIs e itens referenciados | B4: A02: loja, ativo, código de barras, SKU, unidade e preço. X02: GTIN, fornecedor, SKU externo, unidade, preço cotado e atualização; demais campos recebidos são validados pelo cliente.
A5: Dados derivados e exemplo | B5: Diferença = cotação - preço interno. Percentual = diferença / preço interno x 100, arredondado a duas casas. Preço interno zero: percentual não aplicável. Cruza GTIN e unidade dos produtos ativos da loja, sem gravar dados.
A6: Vazios e classificação | B6: SE: produz dados derivados, não apenas dados recuperados. Entrada: GTIN, código do fornecedor.
A7: Arquivos referenciados | B7: A02 Produtos; X02 Ofertas externas
A9: Arquivo / origem | B9: Dado que cruza a fronteira | C9: Uso no processo | D9: DER contado
A10: Interface | B10: GTIN; código do fornecedor | C10: Entrada e saída | D10: 2
A11: Interface | B11: SKU interno; SKU externo | C11: Saída | D11: 2
A12: Interface | B12: unidade; preço interno | C12: Saída | D12: 2
A13: Interface | B13: preço cotado; diferença monetária | C13: Saída | D13: 2
A14: Interface | B14: diferença percentual | C14: Saída | D14: 1
A15: Interface | B15: data de atualização | C15: Saída | D15: 1
A16: Interface | B16: acionamento | C16: Controle | D16: 1
A17: Interface | B17: mensagem de resultado | C17: Controle | D17: 1
A19: Arquivos referenciados | B19: Nome do grupo lógico | C19: Uso
A20: A02 | B20: Produtos | C20: Lido / mantido conforme descrição
A21: X02 | B21: Ofertas externas | C21: Lido / mantido conforme descrição
A23: Contagem para PF | B23: Arquivos referenciados | C23: =COUNTA(A20:A21) -> 2
A24: Contagem para PF | B24: Itens de dados (DER) | C24: =SUM(D10:D17) -> 12
A25: Complexidade | B25: =IF(OR(NOT(ISNUMBER(C23)),NOT(ISNUMBER(C24)),C23<=0,C24<=0),"Dados pendentes",IF(C24<=5,IF(C23<=3,"Simples","Moderado"),IF(C24<=19,IF(C23<=1,"Simples",IF(C23<=3,"Moderado","Complexo")),IF(C23<=1,"Moderado","Complexo")))) -> Moderado
A26: Tamanho estimado (PF) | B26: =IF(B25="Simples",4,IF(B25="Moderado",5,IF(B25="Complexo",7,"Dados pendentes"))) -> 5

Sheet CE04 Consulta
A1: CE04 — Consultar fornecedores externos
A2: Tipo e finalidade | B2: CE — Consultar fornecedores externos.
A3: Origem e complemento | B3: Capturas reais: filtros preenchidos antes de consultar e resultado após enviar a consulta. Na imagem de entrada, a tabela ainda corresponde à consulta anterior. Mesmo processo, sem derivação ou manutenção. Dados de demonstração.
A4: Entrada e critérios | B4: Entrada: filtro código, nome ou documento. Filtros opcionais. Entrada e resultado pertencem à mesma consulta.
A5: Arquivos e resultado | B5: X01 Fornecedores externos. Saída: código, nome, documento, e-mail, telefone.
A6: Classificação e vazios | B6: CE sem cálculo nem manutenção. Entrada: 3 TD; saída sem repetição: 5 TD. Classificar separadamente e usar a maior complexidade: simples, 3 PF. Vazio: mensagem de resultado.
A7: Arquivos referenciados | B7: X01 Fornecedores externos
A9: Arquivo / origem | B9: Dado que cruza a fronteira | C9: Uso no processo | D9: DER contado
A10: Interface | B10: filtro código, nome ou documento | C10: Entrada | D10: 1
A11: Interface | B11: código | C11: Saída | D11: 1
A12: Interface | B12: nome | C12: Saída | D12: 1
A13: Interface | B13: documento | C13: Saída | D13: 1
A14: Interface | B14: e-mail | C14: Saída | D14: 1
A15: Interface | B15: telefone | C15: Saída | D15: 1
A16: Interface | B16: acionamento | C16: Controle | D16: 1
A17: Interface | B17: mensagem de resultado | C17: Controle | D17: 1
D18: 0
A20: Arquivos referenciados | B20: Nome do grupo lógico | C20: Uso
A21: X01 | B21: Fornecedores externos | C21: Lido / mantido conforme descrição
A23: Contagem para PF | B23: Arquivos referenciados | C23: =COUNTA(A21:A21) -> 1
A24: Contagem para PF | B24: Itens de dados (DER) | C24: =SUM(D10:D18) -> 8
A25: Complexidade | B25: =IF(OR(IF(OR(NOT(ISNUMBER(C23)),NOT(ISNUMBER(3)),C23<=0,3<=0),"Dados pendentes",IF(3<=4,IF(C23<=2,"Simples","Moderado"),IF(3<=15,IF(C23<=1,"Simples",IF(C23=2,"Moderado","Complexo")),IF(C23<=1,"Moderado","Complexo"))))="Complexo",IF(OR(NOT(ISNUMBER(C23)),NOT(ISNUMBER(5)),C23<=0,5<=0),"Dados pendentes",IF(5<=5,IF(C23<=3,"Simples","Moderado"),IF(5<=19,IF(C23<=1,"Simples",IF(C23<=3,"Moderado","Complexo")),IF(C23<=1,"Moderado","Complexo"))))="Complexo"),"Complexo",IF(OR(IF(OR(NOT(ISNUMBER(C23)),NOT(ISNUMBER(3)),C23<=0,3<=0),"Dados pendentes",IF(3<=4,IF(C23<=2,"Simples","Moderado"),IF(3<=15,IF(C23<=1,"Simples",IF(C23=2,"Moderado","Complexo")),IF(C23<=1,"Moderado","Complexo"))))="Moderado",IF(OR(NOT(ISNUMBER(C23)),NOT(ISNUMBER(5)),C23<=0,5<=0),"Dados pendentes",IF(5<=5,IF(C23<=3,"Simples","Moderado"),IF(5<=19,IF(C23<=1,"Simples",IF(C23<=3,"Moderado","Complexo")),IF(C23<=1,"Moderado","Complexo"))))="Moderado"),"Moderado","Simples")) -> Simples
A26: Tamanho estimado (PF) | B26: =IF(B25="Simples",3,IF(B25="Moderado",4,IF(B25="Complexo",6,"Dados pendentes"))) -> 3

Sheet CE12 Consulta
A1: CE12 — Consultar ofertas externas
A2: Tipo e finalidade | B2: CE — Consultar ofertas externas.
A3: Origem e complemento | B3: Capturas reais: filtros preenchidos antes de consultar e resultado após enviar a consulta. Na imagem de entrada, a tabela ainda corresponde à consulta anterior. Mesmo processo, sem derivação ou manutenção. Dados de demonstração.
A4: Entrada e critérios | B4: Entrada: GTIN, código do fornecedor. Filtros opcionais. Entrada e resultado pertencem à mesma consulta.
A5: Arquivos e resultado | B5: X02 Ofertas externas. Saída: GTIN, código do fornecedor, SKU externo, descrição, marca, unidade, preço cotado, disponibilidade, data de atualização.
A6: Classificação e vazios | B6: CE sem cálculo nem manutenção. Entrada: 4 TD; saída sem repetição: 7 TD. Classificar separadamente e usar a maior complexidade: simples, 3 PF. Vazio: mensagem de resultado.
A7: Arquivos referenciados | B7: X02 Ofertas externas
A9: Arquivo / origem | B9: Dado que cruza a fronteira | C9: Uso no processo | D9: DER contado
A10: Interface | B10: GTIN; código do fornecedor | C10: Entrada e saída | D10: 2
A11: Interface | B11: SKU externo; descrição | C11: Saída | D11: 2
A12: Interface | B12: marca; unidade | C12: Saída | D12: 2
A13: Interface | B13: preço cotado; disponibilidade | C13: Saída | D13: 2
A14: Interface | B14: data de atualização | C14: Saída | D14: 1
A15: Interface | B15: acionamento | C15: Controle | D15: 1
A16: Interface | B16: mensagem de resultado | C16: Controle | D16: 1
A18: Arquivos referenciados | B18: Nome do grupo lógico | C18: Uso
A19: X02 | B19: Ofertas externas | C19: Lido / mantido conforme descrição
A22: Contagem para PF | B22: Arquivos referenciados | C22: =COUNTA(A19:A20) -> 1
A23: Contagem para PF | B23: Itens de dados (DER) | C23: =SUM(D10:D16) -> 11
A24: Complexidade | B24: =IF(OR(IF(OR(NOT(ISNUMBER(C22)),NOT(ISNUMBER(4)),C22<=0,4<=0),"Dados pendentes",IF(4<=4,IF(C22<=2,"Simples","Moderado"),IF(4<=15,IF(C22<=1,"Simples",IF(C22=2,"Moderado","Complexo")),IF(C22<=1,"Moderado","Complexo"))))="Complexo",IF(OR(NOT(ISNUMBER(C22)),NOT(ISNUMBER(7)),C22<=0,7<=0),"Dados pendentes",IF(7<=5,IF(C22<=3,"Simples","Moderado"),IF(7<=19,IF(C22<=1,"Simples",IF(C22<=3,"Moderado","Complexo")),IF(C22<=1,"Moderado","Complexo"))))="Complexo"),"Complexo",IF(OR(IF(OR(NOT(ISNUMBER(C22)),NOT(ISNUMBER(4)),C22<=0,4<=0),"Dados pendentes",IF(4<=4,IF(C22<=2,"Simples","Moderado"),IF(4<=15,IF(C22<=1,"Simples",IF(C22=2,"Moderado","Complexo")),IF(C22<=1,"Moderado","Complexo"))))="Moderado",IF(OR(NOT(ISNUMBER(C22)),NOT(ISNUMBER(7)),C22<=0,7<=0),"Dados pendentes",IF(7<=5,IF(C22<=3,"Simples","Moderado"),IF(7<=19,IF(C22<=1,"Simples",IF(C22<=3,"Moderado","Complexo")),IF(C22<=1,"Moderado","Complexo"))))="Moderado"),"Moderado","Simples")) -> Simples
A25: Tamanho estimado (PF) | B25: =IF(B24="Simples",3,IF(B24="Moderado",4,IF(B24="Complexo",6,"Dados pendentes"))) -> 3

Sheet Critérios e fontes
A1: Critérios de classificação e estimativa didática
A2: Fronteira | B2: Estoque Inteligente: aplicação de controle de estoque. Provedores de fornecedores e ofertas fora da fronteira; manutenção externa. Os recortes individuais se sobrepõem e não devem ser somados.
A3: Convenção de contagem | B3: RL: subgrupo lógico. TD: cada campo distinto; ponto e vírgula separa campos na mesma linha. D informa quantos. EE: inclui acionamento e mensagem. CEs: entrada e saída classificadas separadamente, maior complexidade; pesos 3/4/6.
A4: SE e CE | B4: SE deriva dados; CE recupera sem cálculo ou manutenção. Material: docs/pdfs, Partes I–IV. FA = 0,65 + 0,01 × NI (Parte IV p. 11); p. 15 contém 0,35 inconsistente. Imagens: capturas reais do sistema local com dados de demonstração.
A6: ALI - faixas de DER nas colunas
A7: RL / arquivos | B7: 1 a 19 | C7: 20 a 50 | D7: 51 ou mais
A8: 1 RL | B8: Simples | C8: Simples | D8: Moderado
A9: 2 a 5 RL | B9: Simples | C9: Moderado | D9: Complexo
A10: 6 ou mais RL | B10: Moderado | C10: Complexo | D10: Complexo
A11: Pesos em PF | B11: 7 | C11: 10 | D11: 15
A14: AIE - faixas de DER nas colunas
A15: RL / arquivos | B15: 1 a 19 | C15: 20 a 50 | D15: 51 ou mais
A16: 1 RL | B16: Simples | C16: Simples | D16: Moderado
A17: 2 a 5 RL | B17: Simples | C17: Moderado | D17: Complexo
A18: 6 ou mais RL | B18: Moderado | C18: Complexo | D18: Complexo
A19: Pesos em PF | B19: 5 | C19: 7 | D19: 10
A22: EE - faixas de DER nas colunas
A23: RL / arquivos | B23: 1 a 4 | C23: 5 a 15 | D23: 16 ou mais
A24: 0 ou 1 arquivo | B24: Simples | C24: Simples | D24: Moderado
A25: 2 arquivos | B25: Simples | C25: Moderado | D25: Complexo
A26: 3 ou mais arquivos | B26: Moderado | C26: Complexo | D26: Complexo
A27: Pesos em PF | B27: 3 | C27: 4 | D27: 6
A30: SE - faixas de DER nas colunas
A31: RL / arquivos | B31: 1 a 5 | C31: 6 a 19 | D31: 20 ou mais
A32: 0 ou 1 arquivo | B32: Simples | C32: Simples | D32: Moderado
A33: 2 a 3 arquivos | B33: Simples | C33: Moderado | D33: Complexo
A34: 4 ou mais arquivos | B34: Moderado | C34: Complexo | D34: Complexo
A35: Pesos em PF | B35: 4 | C35: 5 | D35: 7
A38: CE - faixas de DER nas colunas
A39: RL / arquivos | B39: 1 a 5 | C39: 6 a 19 | D39: 20 ou mais
A40: 0 ou 1 arquivo | B40: Simples | C40: Simples | D40: Moderado
A41: 2 a 3 arquivos | B41: Simples | C41: Moderado | D41: Complexo
A42: 4 ou mais arquivos | B42: Moderado | C42: Complexo | D42: Complexo
A43: Pesos em PF | B43: 3 | C43: 4 | D43: 6

Sheet NI e estimativas
A2: PFB (PF) | B2: =Contribuição!D17 -> 52 | C2: PFB do recorte: Contribuição!D17; não é o tamanho completo do sistema.
A3: NI total (0 a 70) | B3: =IF(COUNT(B9:B22)<>ROWS(B9:B22),"Notas pendentes",IF(SUM(COUNTIF(B9:B22,0),COUNTIF(B9:B22,1),COUNTIF(B9:B22,2),COUNTIF(B9:B22,3),COUNTIF(B9:B22,4),COUNTIF(B9:B22,5))<>ROWS(B9:B22),"Notas inválidas",SUM(B9:B22))) -> 41 | C3: Soma das 14 notas de B9:B22; valores inteiros de 0 a 5.
A4: Fator de ajuste (FA) | B4: =IF(ISNUMBER(B3),0.65+0.01*B3,"Revisar NI") -> 1.06 | C4: FA = 0,65 + 0,01 × NI total. Intervalo possível: 0,65 a 1,35.
A5: PFA (PF ajustados) | B5: =IF(AND(ISNUMBER(B2),ISNUMBER(B4)),B2*B4,"Revisar dados") -> 55.12 | C5: PFA = PFB × FA. O ajuste pode reduzir ou aumentar o tamanho: NI abaixo de 35 produz FA menor que 1.
A7: Características gerais da aplicação: notas propostas e justificativas
A8: Característica | B8: NI (0 a 5) | C8: Justificativa da nota | D8: Enquadramento e referência
A9: Comunicação de dados | B9: 5 | C9: Aplicação on-line com HTTP e MQTT; novo cliente HTTP de fornecedores. Mais de um protocolo. | D9: MqttGateway, controllers e FornecedorGateway
A10: Processamento distribuído | B10: 3 | C10: Envia comandos para processamento no controlador IoT. Retorno de telemetria não demonstra transferência de processamento nas duas direções nem escolha dinâmica de CPU. | D10: IoTService.sinalizar
A11: Desempenho | B11: 1 | C11: Há limites de conexão, paginação e timeouts, mas não foi fornecido SLA crítico nem evidência de análise de desempenho rigorosa. | D11: application.properties, ProdutoRepository
A12: Utilização de equipamento | B12: 2 | C12: Compose define limites de memória e pools; há considerações de recursos e segurança. Não exige CPU exclusiva. | D12: compose.yaml
A13: Volume de transações | B13: 1 | C13: Premissa acadêmica: picos mensais de inventário. Volume real não medido; revisar se houver histórico operacional. | D13: Premissa de estimativa
A14: Entrada on-line | B14: 5 | C14: Mais de 30% dos processos de entrada são interativos: cadastros, movimentos e configurações. | D14: Controllers web
A15: Eficiência do usuário final | B15: 4 | C15: Menus, mouse, paginação, navegação, ajuda contextual e poucas telas; redução de digitação por código de barras, voz e balança. Sem medição formal de eficiência. | D15: templates, speech.js, baixa rápida
A16: Atualização on-line | B16: 4 | C16: Maioria dos ALIs atualizada on-line, com transações, bloqueios e idempotência contra perda/duplicação. Não se assume recuperação de volumes extremos. | D16: EstoqueService, repositories
A17: Processamento complexo | B17: 2 | C17: Dois critérios: auditoria/segurança específica e lógica de negócio de estorno, saldo e permissões. Não se considera matemática extensiva nem reprocessamento batch complexo. | D17: Acesso, EstoqueService, AuditoriaRepository
A18: Reutilização de código | B18: 4 | C18: Biblioteca de regras empacotável, documentada e com consumidor externo. Extensões exigem código; não se atribui customização geral por parâmetros. | D18: docs/reuso/README.md, scripts/empacotar-reuso.ps1
A19: Facilidade de implantação | B19: 2 | C19: Roteiros de execução e migrações preparados. Não há evidência de conversão automatizada de dados legados para justificar 4/5. | D19: README, Flyway, Compose
A20: Facilidade operacional | B20: 2 | C20: Inicialização por scripts com intervenção (1); consultas e relatórios minimizam papel (1). Não se presume backup/recuperação automática. | D20: scripts/demo.ps1, relatórios
... A22: Facilidade de mudanças | B22: 4 | C22: Consulta flexível sobre vários ALIs (2) e controles em tabelas alteráveis on-line com efeito imediato, como permissões/recursos (2). | D22: ProdutoRepository.pesquisar, PermissaoService, LojaService
A26: Premissas editáveis para a estimativa individual
A27: Premissa | B27: Valor | C27: Explicação e alcance | D27: Unidade / origem
A28: Índice de esforço | B28: 10 | C28: Hipótese didática de 10 horas/PFA para análise, prototipação, implementação, testes e documentação. | D28: h/PFA. Hipótese didática; não é coeficiente do IFPUG.
A29: Pessoas equivalentes | B29: 1 | C29: Uma pessoa equivalente dedicada ao recorte de Lucas Andriani Theiss. | D29: pessoa. Premissa de capacidade individual.
A30: Jornada por dia | B30: 8 | C30: Jornada de referência antes de descontar reuniões, pausas e outras atividades. A produtividade efetiva é calculada pela alocação da linha seguinte. | D30: h/dia por pessoa. Hipótese de planejamento.
A31: Alocação produtiva | B31: 0.75 | C31: 8 h/dia × 75% = 6 horas produtivas por pessoa/dia. | D31: proporção de 0 a 1. Hipótese de disponibilidade.
A32: Dias úteis por semana | B32: 5 | C32: Usado para converter o prazo em dias úteis em semanas. Não define data inicial, calendário de feriados ou compromisso de entrega. | D32: dias/semana. Hipótese de calendário.
A33: Valor da hora | B33: 25 | C33: Valor orçamentário adotado para cada hora do esforço incluído. Não é pesquisa de mercado, salário comprovado nem custo efetivamente incorrido. | D33: R$/h. Premissa didática editável.
A34: Reserva de esforço | B34: 0 | C34: Reserva zero conforme premissas acadêmicas; a fórmula de reserva é preservada. | D34: proporção de 0 a 1. Reserva de planejamento.
A35: Custos adicionais | B35: 0 | C35: Campo para hospedagem, licenças, equipamentos e encargos adicionais documentados. O valor inicial zero indica que nenhum desses desembolsos foi orçado; itens não informados ficam fora da estimativa. | D35: R$. Valor inicial zero; não representa cotação.
A37: Estimativas para desenvolver as funções individuais especificadas
A38: Resultado | B38: Valor calculado | C38: Fórmula de planejamento e interpretação | D38: Unidade
A39: Horas produtivas por pessoa/dia | B39: =IF(AND(ISNUMBER(B30),B30>0,ISNUMBER(B31),B31>0,B31<=1),B30*B31,"Revisar jornada") -> 6 | C39: Jornada × alocação produtiva. | D39: h/pessoa/dia
A40: Esforço base | B40: =IF(AND(ISNUMBER(B5),ISNUMBER(B28),B28>0),B5*B28,"Revisar dados") -> 551.2 | C40: PFA × índice de esforço. Mede trabalho total, sem reserva. | D40: h
A41: Reserva em horas | B41: =IF(AND(ISNUMBER(B40),ISNUMBER(B34),B34>=0,B34<=1),B40*B34,"Revisar reserva") -> 0 | C41: Esforço base × percentual de reserva. Reserva zero é permitida. | D41: h
A42: Esforço total com reserva | B42: =IF(AND(ISNUMBER(B40),ISNUMBER(B41)),SUM(B40:B41),"Revisar dados") -> 551.2 | C42: Esforço base + reserva; base usada no prazo e no custo total. | D42: h
A43: Capacidade diária da equipe | B43: =IF(AND(ISNUMBER(B29),B29>0,ISNUMBER(B39)),B29*B39,"Revisar equipe") -> 6 | C43: Pessoas equivalentes × horas produtivas por pessoa/dia. | D43: h/dia
A44: Prazo calculado | B44: =IF(AND(ISNUMBER(B42),ISNUMBER(B43)),B42/B43,"Revisar dados") -> 91.866667 | C44: Esforço total ÷ capacidade diária. Valor fracionário antes do arredondamento. | D44: dias úteis
A45: Prazo planejado | B45: =IF(ISNUMBER(B44),ROUNDUP(ROUND(B44,10),0),"Revisar dados") -> 92 | C45: Prazo calculado arredondado para o próximo dia útil inteiro. Arredondamento técnico prévio a 10 casas evita um dia extra causado apenas pela representação decimal. | D45: dias úteis
A46: Prazo em semanas | B46: =IF(AND(ISNUMBER(B45),ISNUMBER(B32),B32>0,B32<=7),B45/B32,"Revisar calendário") -> 18.4 | C46: Prazo planejado ÷ dias úteis por semana. Não é duração em dias corridos. | D46: semanas
A47: Custo base de mão de obra | B47: =IF(AND(ISNUMBER(B40),ISNUMBER(B33),B33>=0),B40*B33,"Revisar valor/hora") -> 13780 | C47: Esforço base × valor da hora. | D47: R$
...
